/cluster/rs_lab/dbarton/usb_twitching/pili/src/analysis/mdl.py:193: RuntimeWarning: invalid value encountered in arccos
  theta = np.arccos(np.sum(norm_dx * norm_dy,axis=1))
Process Process-3:
Traceback (most recent call last):
  File "/cluster/rs_lab/dbarton/env/lib/python3.8/multiprocessing/process.py", line 315, in _bootstrap
    self.run()
  File "/cluster/rs_lab/dbarton/env/lib/python3.8/multiprocessing/process.py", line 108, in run
    self._target(*self._args, **self._kwargs)
  File "run_pwl.py", line 157, in pwl_solve
    'solver_iter' : solver.get_iter_count()
AttributeError: 'Solver' object has no attribute 'get_iter_count'
Process Process-5:
Traceback (most recent call last):
  File "/cluster/rs_lab/dbarton/env/lib/python3.8/multiprocessing/process.py", line 315, in _bootstrap
    self.run()
  File "/cluster/rs_lab/dbarton/env/lib/python3.8/multiprocessing/process.py", line 108, in run
    self._target(*self._args, **self._kwargs)
  File "run_pwl.py", line 157, in pwl_solve
    'solver_iter' : solver.get_iter_count()
AttributeError: 'Solver' object has no attribute 'get_iter_count'
Process Process-7:
Traceback (most recent call last):
  File "/cluster/rs_lab/dbarton/env/lib/python3.8/multiprocessing/process.py", line 315, in _bootstrap
    self.run()
  File "/cluster/rs_lab/dbarton/env/lib/python3.8/multiprocessing/process.py", line 108, in run
    self._target(*self._args, **self._kwargs)
  File "run_pwl.py", line 157, in pwl_solve
    'solver_iter' : solver.get_iter_count()
AttributeError: 'Solver' object has no attribute 'get_iter_count'
Process Process-2:
Traceback (most recent call last):
  File "/cluster/rs_lab/dbarton/env/lib/python3.8/multiprocessing/process.py", line 315, in _bootstrap
    self.run()
  File "/cluster/rs_lab/dbarton/env/lib/python3.8/multiprocessing/process.py", line 108, in run
    self._target(*self._args, **self._kwargs)
  File "run_pwl.py", line 157, in pwl_solve
    'solver_iter' : solver.get_iter_count()
AttributeError: 'Solver' object has no attribute 'get_iter_count'
Process Process-8:
Traceback (most recent call last):
  File "/cluster/rs_lab/dbarton/env/lib/python3.8/multiprocessing/process.py", line 315, in _bootstrap
    self.run()
  File "/cluster/rs_lab/dbarton/env/lib/python3.8/multiprocessing/process.py", line 108, in run
    self._target(*self._args, **self._kwargs)
  File "run_pwl.py", line 157, in pwl_solve
    'solver_iter' : solver.get_iter_count()
AttributeError: 'Solver' object has no attribute 'get_iter_count'
/cluster/rs_lab/dbarton/usb_twitching/pili/src/analysis/mdl.py:193: RuntimeWarning: invalid value encountered in arccos
  theta = np.arccos(np.sum(norm_dx * norm_dy,axis=1))
/cluster/rs_lab/dbarton/usb_twitching/pili/support.py:52: RuntimeWarning: invalid value encountered in true_divide
  d_hat = np.divide(d_ba, d)
/cluster/rs_lab/dbarton/usb_twitching/pili/src/analysis/pwlpartition.py:102: RuntimeWarning: invalid value encountered in true_divide
  u = vector/length[:,np.newaxis]
Process Process-52:
Traceback (most recent call last):
  File "/cluster/rs_lab/dbarton/env/lib/python3.8/multiprocessing/process.py", line 315, in _bootstrap
    self.run()
  File "/cluster/rs_lab/dbarton/env/lib/python3.8/multiprocessing/process.py", line 108, in run
    self._target(*self._args, **self._kwargs)
  File "run_pwl.py", line 142, in pwl_solve
    solver.priority_solve(control, output=output)
  File "/cluster/rs_lab/dbarton/usb_twitching/pili/src/analysis/pwlpartition.py", line 823, in priority_solve
    accepted = self.destroy_at(index)
  File "/cluster/rs_lab/dbarton/usb_twitching/pili/src/analysis/pwlpartition.py", line 1036, in destroy_at
    clone.delete_at(index)
  File "/cluster/rs_lab/dbarton/usb_twitching/pili/src/analysis/pwlpartition.py", line 407, in delete_at
    self.update_residuals()
  File "/cluster/rs_lab/dbarton/usb_twitching/pili/src/analysis/pwlpartition.py", line 175, in update_residuals
    self.residual_at(0, self.model.M)
  File "/cluster/rs_lab/dbarton/usb_twitching/pili/src/analysis/pwlpartition.py", line 250, in residual_at
    residual = np.concatenate(distance_list)
  File "<__array_function__ internals>", line 5, in concatenate
ValueError: need at least one array to concatenate
Process Process-19:
Traceback (most recent call last):
  File "/cluster/rs_lab/dbarton/env/lib/python3.8/multiprocessing/process.py", line 315, in _bootstrap
    self.run()
  File "/cluster/rs_lab/dbarton/env/lib/python3.8/multiprocessing/process.py", line 108, in run
    self._target(*self._args, **self._kwargs)
  File "run_pwl.py", line 157, in pwl_solve
    'solver_iter' : solver.get_iter_count()
AttributeError: 'Solver' object has no attribute 'get_iter_count'
/cluster/rs_lab/dbarton/usb_twitching/pili/src/analysis/mdl.py:193: RuntimeWarning: invalid value encountered in arccos
  theta = np.arccos(np.sum(norm_dx * norm_dy,axis=1))
Process Process-31:
Traceback (most recent call last):
  File "/cluster/rs_lab/dbarton/env/lib/python3.8/multiprocessing/process.py", line 315, in _bootstrap
    self.run()
  File "/cluster/rs_lab/dbarton/env/lib/python3.8/multiprocessing/process.py", line 108, in run
    self._target(*self._args, **self._kwargs)
  File "run_pwl.py", line 157, in pwl_solve
    'solver_iter' : solver.get_iter_count()
AttributeError: 'Solver' object has no attribute 'get_iter_count'
Process Process-62:
Traceback (most recent call last):
  File "/cluster/rs_lab/dbarton/env/lib/python3.8/multiprocessing/process.py", line 315, in _bootstrap
    self.run()
  File "/cluster/rs_lab/dbarton/env/lib/python3.8/multiprocessing/process.py", line 108, in run
    self._target(*self._args, **self._kwargs)
  File "run_pwl.py", line 157, in pwl_solve
    'solver_iter' : solver.get_iter_count()
AttributeError: 'Solver' object has no attribute 'get_iter_count'
/cluster/rs_lab/dbarton/usb_twitching/pili/src/analysis/mdl.py:193: RuntimeWarning: invalid value encountered in arccos
  theta = np.arccos(np.sum(norm_dx * norm_dy,axis=1))
Process Process-6:
Traceback (most recent call last):
  File "/cluster/rs_lab/dbarton/env/lib/python3.8/multiprocessing/process.py", line 315, in _bootstrap
    self.run()
  File "/cluster/rs_lab/dbarton/env/lib/python3.8/multiprocessing/process.py", line 108, in run
    self._target(*self._args, **self._kwargs)
  File "run_pwl.py", line 157, in pwl_solve
    'solver_iter' : solver.get_iter_count()
AttributeError: 'Solver' object has no attribute 'get_iter_count'
Process Process-60:
Traceback (most recent call last):
  File "/cluster/rs_lab/dbarton/env/lib/python3.8/multiprocessing/process.py", line 315, in _bootstrap
    self.run()
  File "/cluster/rs_lab/dbarton/env/lib/python3.8/multiprocessing/process.py", line 108, in run
    self._target(*self._args, **self._kwargs)
  File "run_pwl.py", line 157, in pwl_solve
    'solver_iter' : solver.get_iter_count()
AttributeError: 'Solver' object has no attribute 'get_iter_count'
Process Process-46:
Traceback (most recent call last):
  File "/cluster/rs_lab/dbarton/env/lib/python3.8/multiprocessing/process.py", line 315, in _bootstrap
    self.run()
  File "/cluster/rs_lab/dbarton/env/lib/python3.8/multiprocessing/process.py", line 108, in run
    self._target(*self._args, **self._kwargs)
  File "run_pwl.py", line 157, in pwl_solve
    'solver_iter' : solver.get_iter_count()
AttributeError: 'Solver' object has no attribute 'get_iter_count'
/cluster/rs_lab/dbarton/usb_twitching/pili/src/analysis/mdl.py:193: RuntimeWarning: invalid value encountered in arccos
  theta = np.arccos(np.sum(norm_dx * norm_dy,axis=1))
Process Process-49:
Traceback (most recent call last):
  File "/cluster/rs_lab/dbarton/env/lib/python3.8/multiprocessing/process.py", line 315, in _bootstrap
    self.run()
  File "/cluster/rs_lab/dbarton/env/lib/python3.8/multiprocessing/process.py", line 108, in run
    self._target(*self._args, **self._kwargs)
  File "run_pwl.py", line 157, in pwl_solve
    'solver_iter' : solver.get_iter_count()
AttributeError: 'Solver' object has no attribute 'get_iter_count'
Process Process-12:
Traceback (most recent call last):
  File "/cluster/rs_lab/dbarton/env/lib/python3.8/multiprocessing/process.py", line 315, in _bootstrap
    self.run()
  File "/cluster/rs_lab/dbarton/env/lib/python3.8/multiprocessing/process.py", line 108, in run
    self._target(*self._args, **self._kwargs)
  File "run_pwl.py", line 157, in pwl_solve
    'solver_iter' : solver.get_iter_count()
AttributeError: 'Solver' object has no attribute 'get_iter_count'
Process Process-33:
Traceback (most recent call last):
  File "/cluster/rs_lab/dbarton/env/lib/python3.8/multiprocessing/process.py", line 315, in _bootstrap
    self.run()
  File "/cluster/rs_lab/dbarton/env/lib/python3.8/multiprocessing/process.py", line 108, in run
    self._target(*self._args, **self._kwargs)
  File "run_pwl.py", line 157, in pwl_solve
    'solver_iter' : solver.get_iter_count()
AttributeError: 'Solver' object has no attribute 'get_iter_count'
Process Process-22:
Traceback (most recent call last):
  File "/cluster/rs_lab/dbarton/env/lib/python3.8/multiprocessing/process.py", line 315, in _bootstrap
    self.run()
  File "/cluster/rs_lab/dbarton/env/lib/python3.8/multiprocessing/process.py", line 108, in run
    self._target(*self._args, **self._kwargs)
  File "run_pwl.py", line 157, in pwl_solve
    'solver_iter' : solver.get_iter_count()
AttributeError: 'Solver' object has no attribute 'get_iter_count'
Process Process-40:
Traceback (most recent call last):
  File "/cluster/rs_lab/dbarton/env/lib/python3.8/multiprocessing/process.py", line 315, in _bootstrap
    self.run()
  File "/cluster/rs_lab/dbarton/env/lib/python3.8/multiprocessing/process.py", line 108, in run
    self._target(*self._args, **self._kwargs)
  File "run_pwl.py", line 157, in pwl_solve
    'solver_iter' : solver.get_iter_count()
AttributeError: 'Solver' object has no attribute 'get_iter_count'
Process Process-10:
Traceback (most recent call last):
  File "/cluster/rs_lab/dbarton/env/lib/python3.8/multiprocessing/process.py", line 315, in _bootstrap
    self.run()
  File "/cluster/rs_lab/dbarton/env/lib/python3.8/multiprocessing/process.py", line 108, in run
    self._target(*self._args, **self._kwargs)
  File "run_pwl.py", line 157, in pwl_solve
    'solver_iter' : solver.get_iter_count()
AttributeError: 'Solver' object has no attribute 'get_iter_count'
Process Process-14:
Traceback (most recent call last):
  File "/cluster/rs_lab/dbarton/env/lib/python3.8/multiprocessing/process.py", line 315, in _bootstrap
    self.run()
  File "/cluster/rs_lab/dbarton/env/lib/python3.8/multiprocessing/process.py", line 108, in run
    self._target(*self._args, **self._kwargs)
  File "run_pwl.py", line 157, in pwl_solve
    'solver_iter' : solver.get_iter_count()
AttributeError: 'Solver' object has no attribute 'get_iter_count'
Process Process-51:
Traceback (most recent call last):
  File "/cluster/rs_lab/dbarton/env/lib/python3.8/multiprocessing/process.py", line 315, in _bootstrap
    self.run()
  File "/cluster/rs_lab/dbarton/env/lib/python3.8/multiprocessing/process.py", line 108, in run
    self._target(*self._args, **self._kwargs)
  File "run_pwl.py", line 157, in pwl_solve
    'solver_iter' : solver.get_iter_count()
AttributeError: 'Solver' object has no attribute 'get_iter_count'
Process Process-30:
Traceback (most recent call last):
  File "/cluster/rs_lab/dbarton/env/lib/python3.8/multiprocessing/process.py", line 315, in _bootstrap
    self.run()
  File "/cluster/rs_lab/dbarton/env/lib/python3.8/multiprocessing/process.py", line 108, in run
    self._target(*self._args, **self._kwargs)
  File "run_pwl.py", line 157, in pwl_solve
    'solver_iter' : solver.get_iter_count()
AttributeError: 'Solver' object has no attribute 'get_iter_count'
Process Process-63:
Traceback (most recent call last):
  File "/cluster/rs_lab/dbarton/env/lib/python3.8/multiprocessing/process.py", line 315, in _bootstrap
    self.run()
  File "/cluster/rs_lab/dbarton/env/lib/python3.8/multiprocessing/process.py", line 108, in run
    self._target(*self._args, **self._kwargs)
  File "run_pwl.py", line 157, in pwl_solve
    'solver_iter' : solver.get_iter_count()
AttributeError: 'Solver' object has no attribute 'get_iter_count'
Process Process-67:
Traceback (most recent call last):
  File "/cluster/rs_lab/dbarton/env/lib/python3.8/multiprocessing/process.py", line 315, in _bootstrap
    self.run()
  File "/cluster/rs_lab/dbarton/env/lib/python3.8/multiprocessing/process.py", line 108, in run
    self._target(*self._args, **self._kwargs)
  File "run_pwl.py", line 157, in pwl_solve
    'solver_iter' : solver.get_iter_count()
AttributeError: 'Solver' object has no attribute 'get_iter_count'
Process Process-35:
Traceback (most recent call last):
  File "/cluster/rs_lab/dbarton/env/lib/python3.8/multiprocessing/process.py", line 315, in _bootstrap
    self.run()
  File "/cluster/rs_lab/dbarton/env/lib/python3.8/multiprocessing/process.py", line 108, in run
    self._target(*self._args, **self._kwargs)
  File "run_pwl.py", line 157, in pwl_solve
    'solver_iter' : solver.get_iter_count()
AttributeError: 'Solver' object has no attribute 'get_iter_count'
Process Process-23:
Traceback (most recent call last):
  File "/cluster/rs_lab/dbarton/env/lib/python3.8/multiprocessing/process.py", line 315, in _bootstrap
    self.run()
  File "/cluster/rs_lab/dbarton/env/lib/python3.8/multiprocessing/process.py", line 108, in run
    self._target(*self._args, **self._kwargs)
  File "run_pwl.py", line 157, in pwl_solve
    'solver_iter' : solver.get_iter_count()
AttributeError: 'Solver' object has no attribute 'get_iter_count'
Process Process-37:
Traceback (most recent call last):
  File "/cluster/rs_lab/dbarton/env/lib/python3.8/multiprocessing/process.py", line 315, in _bootstrap
    self.run()
  File "/cluster/rs_lab/dbarton/env/lib/python3.8/multiprocessing/process.py", line 108, in run
    self._target(*self._args, **self._kwargs)
  File "run_pwl.py", line 157, in pwl_solve
    'solver_iter' : solver.get_iter_count()
AttributeError: 'Solver' object has no attribute 'get_iter_count'
Process Process-18:
Traceback (most recent call last):
  File "/cluster/rs_lab/dbarton/env/lib/python3.8/multiprocessing/process.py", line 315, in _bootstrap
    self.run()
  File "/cluster/rs_lab/dbarton/env/lib/python3.8/multiprocessing/process.py", line 108, in run
    self._target(*self._args, **self._kwargs)
  File "run_pwl.py", line 157, in pwl_solve
    'solver_iter' : solver.get_iter_count()
AttributeError: 'Solver' object has no attribute 'get_iter_count'
Process Process-15:
Traceback (most recent call last):
  File "/cluster/rs_lab/dbarton/env/lib/python3.8/multiprocessing/process.py", line 315, in _bootstrap
    self.run()
  File "/cluster/rs_lab/dbarton/env/lib/python3.8/multiprocessing/process.py", line 108, in run
    self._target(*self._args, **self._kwargs)
  File "run_pwl.py", line 157, in pwl_solve
    'solver_iter' : solver.get_iter_count()
AttributeError: 'Solver' object has no attribute 'get_iter_count'
Process Process-71:
Traceback (most recent call last):
  File "/cluster/rs_lab/dbarton/env/lib/python3.8/multiprocessing/process.py", line 315, in _bootstrap
    self.run()
  File "/cluster/rs_lab/dbarton/env/lib/python3.8/multiprocessing/process.py", line 108, in run
    self._target(*self._args, **self._kwargs)
  File "run_pwl.py", line 157, in pwl_solve
    'solver_iter' : solver.get_iter_count()
AttributeError: 'Solver' object has no attribute 'get_iter_count'
Process Process-64:
Traceback (most recent call last):
  File "/cluster/rs_lab/dbarton/env/lib/python3.8/multiprocessing/process.py", line 315, in _bootstrap
    self.run()
  File "/cluster/rs_lab/dbarton/env/lib/python3.8/multiprocessing/process.py", line 108, in run
    self._target(*self._args, **self._kwargs)
  File "run_pwl.py", line 157, in pwl_solve
    'solver_iter' : solver.get_iter_count()
AttributeError: 'Solver' object has no attribute 'get_iter_count'
Process Process-29:
Traceback (most recent call last):
  File "/cluster/rs_lab/dbarton/env/lib/python3.8/multiprocessing/process.py", line 315, in _bootstrap
    self.run()
  File "/cluster/rs_lab/dbarton/env/lib/python3.8/multiprocessing/process.py", line 108, in run
    self._target(*self._args, **self._kwargs)
  File "run_pwl.py", line 157, in pwl_solve
    'solver_iter' : solver.get_iter_count()
AttributeError: 'Solver' object has no attribute 'get_iter_count'
Process Process-57:
Traceback (most recent call last):
  File "/cluster/rs_lab/dbarton/env/lib/python3.8/multiprocessing/process.py", line 315, in _bootstrap
    self.run()
  File "/cluster/rs_lab/dbarton/env/lib/python3.8/multiprocessing/process.py", line 108, in run
    self._target(*self._args, **self._kwargs)
  File "run_pwl.py", line 157, in pwl_solve
    'solver_iter' : solver.get_iter_count()
AttributeError: 'Solver' object has no attribute 'get_iter_count'
Process Process-50:
Traceback (most recent call last):
  File "/cluster/rs_lab/dbarton/env/lib/python3.8/multiprocessing/process.py", line 315, in _bootstrap
    self.run()
  File "/cluster/rs_lab/dbarton/env/lib/python3.8/multiprocessing/process.py", line 108, in run
    self._target(*self._args, **self._kwargs)
  File "run_pwl.py", line 157, in pwl_solve
    'solver_iter' : solver.get_iter_count()
AttributeError: 'Solver' object has no attribute 'get_iter_count'
Process Process-39:
Traceback (most recent call last):
  File "/cluster/rs_lab/dbarton/env/lib/python3.8/multiprocessing/process.py", line 315, in _bootstrap
    self.run()
  File "/cluster/rs_lab/dbarton/env/lib/python3.8/multiprocessing/process.py", line 108, in run
    self._target(*self._args, **self._kwargs)
  File "run_pwl.py", line 157, in pwl_solve
    'solver_iter' : solver.get_iter_count()
AttributeError: 'Solver' object has no attribute 'get_iter_count'
Process Process-54:
Traceback (most recent call last):
  File "/cluster/rs_lab/dbarton/env/lib/python3.8/multiprocessing/process.py", line 315, in _bootstrap
    self.run()
  File "/cluster/rs_lab/dbarton/env/lib/python3.8/multiprocessing/process.py", line 108, in run
    self._target(*self._args, **self._kwargs)
  File "run_pwl.py", line 157, in pwl_solve
    'solver_iter' : solver.get_iter_count()
AttributeError: 'Solver' object has no attribute 'get_iter_count'
Process Process-20:
Traceback (most recent call last):
  File "/cluster/rs_lab/dbarton/env/lib/python3.8/multiprocessing/process.py", line 315, in _bootstrap
    self.run()
  File "/cluster/rs_lab/dbarton/env/lib/python3.8/multiprocessing/process.py", line 108, in run
    self._target(*self._args, **self._kwargs)
  File "run_pwl.py", line 157, in pwl_solve
    'solver_iter' : solver.get_iter_count()
AttributeError: 'Solver' object has no attribute 'get_iter_count'
Process Process-38:
Traceback (most recent call last):
  File "/cluster/rs_lab/dbarton/env/lib/python3.8/multiprocessing/process.py", line 315, in _bootstrap
    self.run()
  File "/cluster/rs_lab/dbarton/env/lib/python3.8/multiprocessing/process.py", line 108, in run
    self._target(*self._args, **self._kwargs)
  File "run_pwl.py", line 157, in pwl_solve
    'solver_iter' : solver.get_iter_count()
AttributeError: 'Solver' object has no attribute 'get_iter_count'
Process Process-27:
Traceback (most recent call last):
  File "/cluster/rs_lab/dbarton/env/lib/python3.8/multiprocessing/process.py", line 315, in _bootstrap
    self.run()
  File "/cluster/rs_lab/dbarton/env/lib/python3.8/multiprocessing/process.py", line 108, in run
    self._target(*self._args, **self._kwargs)
  File "run_pwl.py", line 157, in pwl_solve
    'solver_iter' : solver.get_iter_count()
AttributeError: 'Solver' object has no attribute 'get_iter_count'
Process Process-36:
Traceback (most recent call last):
  File "/cluster/rs_lab/dbarton/env/lib/python3.8/multiprocessing/process.py", line 315, in _bootstrap
    self.run()
  File "/cluster/rs_lab/dbarton/env/lib/python3.8/multiprocessing/process.py", line 108, in run
    self._target(*self._args, **self._kwargs)
  File "run_pwl.py", line 157, in pwl_solve
    'solver_iter' : solver.get_iter_count()
AttributeError: 'Solver' object has no attribute 'get_iter_count'
/cluster/rs_lab/dbarton/usb_twitching/pili/src/analysis/mdl.py:193: RuntimeWarning: invalid value encountered in arccos
  theta = np.arccos(np.sum(norm_dx * norm_dy,axis=1))
/cluster/rs_lab/dbarton/usb_twitching/pili/support.py:52: RuntimeWarning: invalid value encountered in true_divide
  d_hat = np.divide(d_ba, d)
/cluster/rs_lab/dbarton/usb_twitching/pili/support.py:52: RuntimeWarning: invalid value encountered in true_divide
  d_hat = np.divide(d_ba, d)
Process Process-1:
Traceback (most recent call last):
  File "/cluster/rs_lab/dbarton/env/lib/python3.8/multiprocessing/process.py", line 315, in _bootstrap
    self.run()
  File "/cluster/rs_lab/dbarton/env/lib/python3.8/multiprocessing/process.py", line 108, in run
    self._target(*self._args, **self._kwargs)
  File "run_pwl.py", line 157, in pwl_solve
    'solver_iter' : solver.get_iter_count()
AttributeError: 'Solver' object has no attribute 'get_iter_count'
Process Process-25:
Traceback (most recent call last):
  File "/cluster/rs_lab/dbarton/env/lib/python3.8/multiprocessing/process.py", line 315, in _bootstrap
    self.run()
  File "/cluster/rs_lab/dbarton/env/lib/python3.8/multiprocessing/process.py", line 108, in run
    self._target(*self._args, **self._kwargs)
  File "run_pwl.py", line 157, in pwl_solve
    'solver_iter' : solver.get_iter_count()
AttributeError: 'Solver' object has no attribute 'get_iter_count'
Process Process-11:
Traceback (most recent call last):
  File "/cluster/rs_lab/dbarton/env/lib/python3.8/multiprocessing/process.py", line 315, in _bootstrap
    self.run()
  File "/cluster/rs_lab/dbarton/env/lib/python3.8/multiprocessing/process.py", line 108, in run
    self._target(*self._args, **self._kwargs)
  File "run_pwl.py", line 157, in pwl_solve
    'solver_iter' : solver.get_iter_count()
AttributeError: 'Solver' object has no attribute 'get_iter_count'
/cluster/rs_lab/dbarton/usb_twitching/pili/support.py:52: RuntimeWarning: invalid value encountered in true_divide
  d_hat = np.divide(d_ba, d)
/cluster/rs_lab/dbarton/usb_twitching/pili/src/analysis/pwlpartition.py:102: RuntimeWarning: invalid value encountered in true_divide
  u = vector/length[:,np.newaxis]
Process Process-61:
Traceback (most recent call last):
  File "/cluster/rs_lab/dbarton/env/lib/python3.8/multiprocessing/process.py", line 315, in _bootstrap
    self.run()
  File "/cluster/rs_lab/dbarton/env/lib/python3.8/multiprocessing/process.py", line 108, in run
    self._target(*self._args, **self._kwargs)
  File "run_pwl.py", line 142, in pwl_solve
    solver.priority_solve(control, output=output)
  File "/cluster/rs_lab/dbarton/usb_twitching/pili/src/analysis/pwlpartition.py", line 823, in priority_solve
    accepted = self.destroy_at(index)
  File "/cluster/rs_lab/dbarton/usb_twitching/pili/src/analysis/pwlpartition.py", line 1036, in destroy_at
    clone.delete_at(index)
  File "/cluster/rs_lab/dbarton/usb_twitching/pili/src/analysis/pwlpartition.py", line 407, in delete_at
    self.update_residuals()
  File "/cluster/rs_lab/dbarton/usb_twitching/pili/src/analysis/pwlpartition.py", line 175, in update_residuals
    self.residual_at(0, self.model.M)
  File "/cluster/rs_lab/dbarton/usb_twitching/pili/src/analysis/pwlpartition.py", line 250, in residual_at
    residual = np.concatenate(distance_list)
  File "<__array_function__ internals>", line 5, in concatenate
ValueError: need at least one array to concatenate
Process Process-72:
Traceback (most recent call last):
  File "/cluster/rs_lab/dbarton/env/lib/python3.8/multiprocessing/process.py", line 315, in _bootstrap
    self.run()
  File "/cluster/rs_lab/dbarton/env/lib/python3.8/multiprocessing/process.py", line 108, in run
    self._target(*self._args, **self._kwargs)
  File "run_pwl.py", line 157, in pwl_solve
    'solver_iter' : solver.get_iter_count()
AttributeError: 'Solver' object has no attribute 'get_iter_count'
/cluster/rs_lab/dbarton/usb_twitching/pili/src/analysis/mdl.py:193: RuntimeWarning: invalid value encountered in arccos
  theta = np.arccos(np.sum(norm_dx * norm_dy,axis=1))
/cluster/rs_lab/dbarton/usb_twitching/pili/support.py:52: RuntimeWarning: invalid value encountered in true_divide
  d_hat = np.divide(d_ba, d)
/cluster/rs_lab/dbarton/usb_twitching/pili/src/analysis/pwlpartition.py:102: RuntimeWarning: invalid value encountered in true_divide
  u = vector/length[:,np.newaxis]
Process Process-13:
Traceback (most recent call last):
  File "/cluster/rs_lab/dbarton/env/lib/python3.8/multiprocessing/process.py", line 315, in _bootstrap
    self.run()
  File "/cluster/rs_lab/dbarton/env/lib/python3.8/multiprocessing/process.py", line 108, in run
    self._target(*self._args, **self._kwargs)
  File "run_pwl.py", line 142, in pwl_solve
    solver.priority_solve(control, output=output)
  File "/cluster/rs_lab/dbarton/usb_twitching/pili/src/analysis/pwlpartition.py", line 823, in priority_solve
    accepted = self.destroy_at(index)
  File "/cluster/rs_lab/dbarton/usb_twitching/pili/src/analysis/pwlpartition.py", line 1036, in destroy_at
    clone.delete_at(index)
  File "/cluster/rs_lab/dbarton/usb_twitching/pili/src/analysis/pwlpartition.py", line 407, in delete_at
    self.update_residuals()
  File "/cluster/rs_lab/dbarton/usb_twitching/pili/src/analysis/pwlpartition.py", line 175, in update_residuals
    self.residual_at(0, self.model.M)
  File "/cluster/rs_lab/dbarton/usb_twitching/pili/src/analysis/pwlpartition.py", line 250, in residual_at
    residual = np.concatenate(distance_list)
  File "<__array_function__ internals>", line 5, in concatenate
ValueError: need at least one array to concatenate
Process Process-68:
Traceback (most recent call last):
  File "/cluster/rs_lab/dbarton/env/lib/python3.8/multiprocessing/process.py", line 315, in _bootstrap
    self.run()
  File "/cluster/rs_lab/dbarton/env/lib/python3.8/multiprocessing/process.py", line 108, in run
    self._target(*self._args, **self._kwargs)
  File "run_pwl.py", line 157, in pwl_solve
    'solver_iter' : solver.get_iter_count()
AttributeError: 'Solver' object has no attribute 'get_iter_count'
Process Process-43:
Traceback (most recent call last):
  File "/cluster/rs_lab/dbarton/env/lib/python3.8/multiprocessing/process.py", line 315, in _bootstrap
    self.run()
  File "/cluster/rs_lab/dbarton/env/lib/python3.8/multiprocessing/process.py", line 108, in run
    self._target(*self._args, **self._kwargs)
  File "run_pwl.py", line 157, in pwl_solve
    'solver_iter' : solver.get_iter_count()
AttributeError: 'Solver' object has no attribute 'get_iter_count'
Process Process-32:
Traceback (most recent call last):
  File "/cluster/rs_lab/dbarton/env/lib/python3.8/multiprocessing/process.py", line 315, in _bootstrap
    self.run()
  File "/cluster/rs_lab/dbarton/env/lib/python3.8/multiprocessing/process.py", line 108, in run
    self._target(*self._args, **self._kwargs)
  File "run_pwl.py", line 157, in pwl_solve
    'solver_iter' : solver.get_iter_count()
AttributeError: 'Solver' object has no attribute 'get_iter_count'
/cluster/rs_lab/dbarton/usb_twitching/pili/src/analysis/mdl.py:193: RuntimeWarning: invalid value encountered in arccos
  theta = np.arccos(np.sum(norm_dx * norm_dy,axis=1))
Process Process-41:
Traceback (most recent call last):
  File "/cluster/rs_lab/dbarton/env/lib/python3.8/multiprocessing/process.py", line 315, in _bootstrap
    self.run()
  File "/cluster/rs_lab/dbarton/env/lib/python3.8/multiprocessing/process.py", line 108, in run
    self._target(*self._args, **self._kwargs)
  File "run_pwl.py", line 157, in pwl_solve
    'solver_iter' : solver.get_iter_count()
AttributeError: 'Solver' object has no attribute 'get_iter_count'
Process Process-59:
Traceback (most recent call last):
  File "/cluster/rs_lab/dbarton/env/lib/python3.8/multiprocessing/process.py", line 315, in _bootstrap
    self.run()
  File "/cluster/rs_lab/dbarton/env/lib/python3.8/multiprocessing/process.py", line 108, in run
    self._target(*self._args, **self._kwargs)
  File "run_pwl.py", line 157, in pwl_solve
    'solver_iter' : solver.get_iter_count()
AttributeError: 'Solver' object has no attribute 'get_iter_count'
Process Process-92:
Traceback (most recent call last):
  File "/cluster/rs_lab/dbarton/env/lib/python3.8/multiprocessing/process.py", line 315, in _bootstrap
    self.run()
  File "/cluster/rs_lab/dbarton/env/lib/python3.8/multiprocessing/process.py", line 108, in run
    self._target(*self._args, **self._kwargs)
  File "run_pwl.py", line 157, in pwl_solve
    'solver_iter' : solver.get_iter_count()
AttributeError: 'Solver' object has no attribute 'get_iter_count'
Process Process-24:
Traceback (most recent call last):
  File "/cluster/rs_lab/dbarton/env/lib/python3.8/multiprocessing/process.py", line 315, in _bootstrap
    self.run()
  File "/cluster/rs_lab/dbarton/env/lib/python3.8/multiprocessing/process.py", line 108, in run
    self._target(*self._args, **self._kwargs)
  File "run_pwl.py", line 157, in pwl_solve
    'solver_iter' : solver.get_iter_count()
AttributeError: 'Solver' object has no attribute 'get_iter_count'
Process Process-21:
Traceback (most recent call last):
  File "/cluster/rs_lab/dbarton/env/lib/python3.8/multiprocessing/process.py", line 315, in _bootstrap
    self.run()
  File "/cluster/rs_lab/dbarton/env/lib/python3.8/multiprocessing/process.py", line 108, in run
    self._target(*self._args, **self._kwargs)
  File "run_pwl.py", line 157, in pwl_solve
    'solver_iter' : solver.get_iter_count()
AttributeError: 'Solver' object has no attribute 'get_iter_count'
/cluster/rs_lab/dbarton/usb_twitching/pili/src/analysis/mdl.py:193: RuntimeWarning: invalid value encountered in arccos
  theta = np.arccos(np.sum(norm_dx * norm_dy,axis=1))
Process Process-53:
Traceback (most recent call last):
  File "/cluster/rs_lab/dbarton/env/lib/python3.8/multiprocessing/process.py", line 315, in _bootstrap
    self.run()
  File "/cluster/rs_lab/dbarton/env/lib/python3.8/multiprocessing/process.py", line 108, in run
    self._target(*self._args, **self._kwargs)
  File "run_pwl.py", line 157, in pwl_solve
    'solver_iter' : solver.get_iter_count()
AttributeError: 'Solver' object has no attribute 'get_iter_count'
Process Process-66:
Traceback (most recent call last):
  File "/cluster/rs_lab/dbarton/env/lib/python3.8/multiprocessing/process.py", line 315, in _bootstrap
    self.run()
  File "/cluster/rs_lab/dbarton/env/lib/python3.8/multiprocessing/process.py", line 108, in run
    self._target(*self._args, **self._kwargs)
  File "run_pwl.py", line 157, in pwl_solve
    'solver_iter' : solver.get_iter_count()
AttributeError: 'Solver' object has no attribute 'get_iter_count'
Process Process-80:
Traceback (most recent call last):
  File "/cluster/rs_lab/dbarton/env/lib/python3.8/multiprocessing/process.py", line 315, in _bootstrap
    self.run()
  File "/cluster/rs_lab/dbarton/env/lib/python3.8/multiprocessing/process.py", line 108, in run
    self._target(*self._args, **self._kwargs)
  File "run_pwl.py", line 157, in pwl_solve
    'solver_iter' : solver.get_iter_count()
AttributeError: 'Solver' object has no attribute 'get_iter_count'
Process Process-17:
Traceback (most recent call last):
  File "/cluster/rs_lab/dbarton/env/lib/python3.8/multiprocessing/process.py", line 315, in _bootstrap
    self.run()
  File "/cluster/rs_lab/dbarton/env/lib/python3.8/multiprocessing/process.py", line 108, in run
    self._target(*self._args, **self._kwargs)
  File "run_pwl.py", line 157, in pwl_solve
    'solver_iter' : solver.get_iter_count()
AttributeError: 'Solver' object has no attribute 'get_iter_count'
Process Process-34:
Traceback (most recent call last):
  File "/cluster/rs_lab/dbarton/env/lib/python3.8/multiprocessing/process.py", line 315, in _bootstrap
    self.run()
  File "/cluster/rs_lab/dbarton/env/lib/python3.8/multiprocessing/process.py", line 108, in run
    self._target(*self._args, **self._kwargs)
  File "run_pwl.py", line 157, in pwl_solve
    'solver_iter' : solver.get_iter_count()
AttributeError: 'Solver' object has no attribute 'get_iter_count'
/cluster/rs_lab/dbarton/usb_twitching/pili/src/analysis/mdl.py:193: RuntimeWarning: invalid value encountered in arccos
  theta = np.arccos(np.sum(norm_dx * norm_dy,axis=1))
Process Process-87:
Traceback (most recent call last):
  File "/cluster/rs_lab/dbarton/env/lib/python3.8/multiprocessing/process.py", line 315, in _bootstrap
    self.run()
  File "/cluster/rs_lab/dbarton/env/lib/python3.8/multiprocessing/process.py", line 108, in run
    self._target(*self._args, **self._kwargs)
  File "run_pwl.py", line 157, in pwl_solve
    'solver_iter' : solver.get_iter_count()
AttributeError: 'Solver' object has no attribute 'get_iter_count'
Process Process-100:
Traceback (most recent call last):
  File "/cluster/rs_lab/dbarton/env/lib/python3.8/multiprocessing/process.py", line 315, in _bootstrap
    self.run()
  File "/cluster/rs_lab/dbarton/env/lib/python3.8/multiprocessing/process.py", line 108, in run
    self._target(*self._args, **self._kwargs)
  File "run_pwl.py", line 157, in pwl_solve
    'solver_iter' : solver.get_iter_count()
AttributeError: 'Solver' object has no attribute 'get_iter_count'
/cluster/rs_lab/dbarton/usb_twitching/pili/src/analysis/mdl.py:193: RuntimeWarning: invalid value encountered in arccos
  theta = np.arccos(np.sum(norm_dx * norm_dy,axis=1))
Process Process-16:
Traceback (most recent call last):
  File "/cluster/rs_lab/dbarton/env/lib/python3.8/multiprocessing/process.py", line 315, in _bootstrap
    self.run()
  File "/cluster/rs_lab/dbarton/env/lib/python3.8/multiprocessing/process.py", line 108, in run
    self._target(*self._args, **self._kwargs)
  File "run_pwl.py", line 157, in pwl_solve
    'solver_iter' : solver.get_iter_count()
AttributeError: 'Solver' object has no attribute 'get_iter_count'
Process Process-47:
Traceback (most recent call last):
  File "/cluster/rs_lab/dbarton/env/lib/python3.8/multiprocessing/process.py", line 315, in _bootstrap
    self.run()
  File "/cluster/rs_lab/dbarton/env/lib/python3.8/multiprocessing/process.py", line 108, in run
    self._target(*self._args, **self._kwargs)
  File "run_pwl.py", line 157, in pwl_solve
    'solver_iter' : solver.get_iter_count()
AttributeError: 'Solver' object has no attribute 'get_iter_count'
Process Process-45:
Traceback (most recent call last):
  File "/cluster/rs_lab/dbarton/env/lib/python3.8/multiprocessing/process.py", line 315, in _bootstrap
    self.run()
  File "/cluster/rs_lab/dbarton/env/lib/python3.8/multiprocessing/process.py", line 108, in run
    self._target(*self._args, **self._kwargs)
  File "run_pwl.py", line 157, in pwl_solve
    'solver_iter' : solver.get_iter_count()
AttributeError: 'Solver' object has no attribute 'get_iter_count'
Process Process-79:
Traceback (most recent call last):
  File "/cluster/rs_lab/dbarton/env/lib/python3.8/multiprocessing/process.py", line 315, in _bootstrap
    self.run()
  File "/cluster/rs_lab/dbarton/env/lib/python3.8/multiprocessing/process.py", line 108, in run
    self._target(*self._args, **self._kwargs)
  File "run_pwl.py", line 157, in pwl_solve
    'solver_iter' : solver.get_iter_count()
AttributeError: 'Solver' object has no attribute 'get_iter_count'
Process Process-56:
Traceback (most recent call last):
  File "/cluster/rs_lab/dbarton/env/lib/python3.8/multiprocessing/process.py", line 315, in _bootstrap
    self.run()
  File "/cluster/rs_lab/dbarton/env/lib/python3.8/multiprocessing/process.py", line 108, in run
    self._target(*self._args, **self._kwargs)
  File "run_pwl.py", line 157, in pwl_solve
    'solver_iter' : solver.get_iter_count()
AttributeError: 'Solver' object has no attribute 'get_iter_count'
Process Process-93:
Traceback (most recent call last):
  File "/cluster/rs_lab/dbarton/env/lib/python3.8/multiprocessing/process.py", line 315, in _bootstrap
    self.run()
  File "/cluster/rs_lab/dbarton/env/lib/python3.8/multiprocessing/process.py", line 108, in run
    self._target(*self._args, **self._kwargs)
  File "run_pwl.py", line 157, in pwl_solve
    'solver_iter' : solver.get_iter_count()
AttributeError: 'Solver' object has no attribute 'get_iter_count'
Process Process-48:
Traceback (most recent call last):
  File "/cluster/rs_lab/dbarton/env/lib/python3.8/multiprocessing/process.py", line 315, in _bootstrap
    self.run()
  File "/cluster/rs_lab/dbarton/env/lib/python3.8/multiprocessing/process.py", line 108, in run
    self._target(*self._args, **self._kwargs)
  File "run_pwl.py", line 157, in pwl_solve
    'solver_iter' : solver.get_iter_count()
AttributeError: 'Solver' object has no attribute 'get_iter_count'
Process Process-74:
Traceback (most recent call last):
  File "/cluster/rs_lab/dbarton/env/lib/python3.8/multiprocessing/process.py", line 315, in _bootstrap
    self.run()
  File "/cluster/rs_lab/dbarton/env/lib/python3.8/multiprocessing/process.py", line 108, in run
    self._target(*self._args, **self._kwargs)
  File "run_pwl.py", line 157, in pwl_solve
    'solver_iter' : solver.get_iter_count()
AttributeError: 'Solver' object has no attribute 'get_iter_count'
Process Process-81:
Traceback (most recent call last):
  File "/cluster/rs_lab/dbarton/env/lib/python3.8/multiprocessing/process.py", line 315, in _bootstrap
    self.run()
  File "/cluster/rs_lab/dbarton/env/lib/python3.8/multiprocessing/process.py", line 108, in run
    self._target(*self._args, **self._kwargs)
  File "run_pwl.py", line 157, in pwl_solve
    'solver_iter' : solver.get_iter_count()
AttributeError: 'Solver' object has no attribute 'get_iter_count'
Process Process-69:
Traceback (most recent call last):
  File "/cluster/rs_lab/dbarton/env/lib/python3.8/multiprocessing/process.py", line 315, in _bootstrap
    self.run()
  File "/cluster/rs_lab/dbarton/env/lib/python3.8/multiprocessing/process.py", line 108, in run
    self._target(*self._args, **self._kwargs)
  File "run_pwl.py", line 157, in pwl_solve
    'solver_iter' : solver.get_iter_count()
AttributeError: 'Solver' object has no attribute 'get_iter_count'
Process Process-84:
Traceback (most recent call last):
  File "/cluster/rs_lab/dbarton/env/lib/python3.8/multiprocessing/process.py", line 315, in _bootstrap
    self.run()
  File "/cluster/rs_lab/dbarton/env/lib/python3.8/multiprocessing/process.py", line 108, in run
    self._target(*self._args, **self._kwargs)
  File "run_pwl.py", line 157, in pwl_solve
    'solver_iter' : solver.get_iter_count()
AttributeError: 'Solver' object has no attribute 'get_iter_count'
Process Process-65:
Traceback (most recent call last):
  File "/cluster/rs_lab/dbarton/env/lib/python3.8/multiprocessing/process.py", line 315, in _bootstrap
    self.run()
  File "/cluster/rs_lab/dbarton/env/lib/python3.8/multiprocessing/process.py", line 108, in run
    self._target(*self._args, **self._kwargs)
  File "run_pwl.py", line 157, in pwl_solve
    'solver_iter' : solver.get_iter_count()
AttributeError: 'Solver' object has no attribute 'get_iter_count'
Process Process-9:
Traceback (most recent call last):
  File "/cluster/rs_lab/dbarton/env/lib/python3.8/multiprocessing/process.py", line 315, in _bootstrap
    self.run()
  File "/cluster/rs_lab/dbarton/env/lib/python3.8/multiprocessing/process.py", line 108, in run
    self._target(*self._args, **self._kwargs)
  File "run_pwl.py", line 157, in pwl_solve
    'solver_iter' : solver.get_iter_count()
AttributeError: 'Solver' object has no attribute 'get_iter_count'
Process Process-83:
Traceback (most recent call last):
  File "/cluster/rs_lab/dbarton/env/lib/python3.8/multiprocessing/process.py", line 315, in _bootstrap
    self.run()
  File "/cluster/rs_lab/dbarton/env/lib/python3.8/multiprocessing/process.py", line 108, in run
    self._target(*self._args, **self._kwargs)
  File "run_pwl.py", line 157, in pwl_solve
    'solver_iter' : solver.get_iter_count()
AttributeError: 'Solver' object has no attribute 'get_iter_count'
Process Process-104:
Traceback (most recent call last):
  File "/cluster/rs_lab/dbarton/env/lib/python3.8/multiprocessing/process.py", line 315, in _bootstrap
    self.run()
  File "/cluster/rs_lab/dbarton/env/lib/python3.8/multiprocessing/process.py", line 108, in run
    self._target(*self._args, **self._kwargs)
  File "run_pwl.py", line 157, in pwl_solve
    'solver_iter' : solver.get_iter_count()
AttributeError: 'Solver' object has no attribute 'get_iter_count'
Process Process-42:
Traceback (most recent call last):
  File "/cluster/rs_lab/dbarton/env/lib/python3.8/multiprocessing/process.py", line 315, in _bootstrap
    self.run()
  File "/cluster/rs_lab/dbarton/env/lib/python3.8/multiprocessing/process.py", line 108, in run
    self._target(*self._args, **self._kwargs)
  File "run_pwl.py", line 157, in pwl_solve
    'solver_iter' : solver.get_iter_count()
AttributeError: 'Solver' object has no attribute 'get_iter_count'
Process Process-91:
Traceback (most recent call last):
  File "/cluster/rs_lab/dbarton/env/lib/python3.8/multiprocessing/process.py", line 315, in _bootstrap
    self.run()
  File "/cluster/rs_lab/dbarton/env/lib/python3.8/multiprocessing/process.py", line 108, in run
    self._target(*self._args, **self._kwargs)
  File "run_pwl.py", line 157, in pwl_solve
    'solver_iter' : solver.get_iter_count()
AttributeError: 'Solver' object has no attribute 'get_iter_count'
Process Process-111:
Traceback (most recent call last):
  File "/cluster/rs_lab/dbarton/env/lib/python3.8/multiprocessing/process.py", line 315, in _bootstrap
    self.run()
  File "/cluster/rs_lab/dbarton/env/lib/python3.8/multiprocessing/process.py", line 108, in run
    self._target(*self._args, **self._kwargs)
  File "run_pwl.py", line 157, in pwl_solve
    'solver_iter' : solver.get_iter_count()
AttributeError: 'Solver' object has no attribute 'get_iter_count'
/cluster/rs_lab/dbarton/usb_twitching/pili/support.py:52: RuntimeWarning: invalid value encountered in true_divide
  d_hat = np.divide(d_ba, d)
/cluster/rs_lab/dbarton/usb_twitching/pili/src/analysis/pwlpartition.py:102: RuntimeWarning: invalid value encountered in true_divide
  u = vector/length[:,np.newaxis]
Process Process-70:
Traceback (most recent call last):
  File "/cluster/rs_lab/dbarton/env/lib/python3.8/multiprocessing/process.py", line 315, in _bootstrap
    self.run()
  File "/cluster/rs_lab/dbarton/env/lib/python3.8/multiprocessing/process.py", line 108, in run
    self._target(*self._args, **self._kwargs)
  File "run_pwl.py", line 142, in pwl_solve
    solver.priority_solve(control, output=output)
  File "/cluster/rs_lab/dbarton/usb_twitching/pili/src/analysis/pwlpartition.py", line 823, in priority_solve
    accepted = self.destroy_at(index)
  File "/cluster/rs_lab/dbarton/usb_twitching/pili/src/analysis/pwlpartition.py", line 1036, in destroy_at
    clone.delete_at(index)
  File "/cluster/rs_lab/dbarton/usb_twitching/pili/src/analysis/pwlpartition.py", line 407, in delete_at
    self.update_residuals()
  File "/cluster/rs_lab/dbarton/usb_twitching/pili/src/analysis/pwlpartition.py", line 175, in update_residuals
    self.residual_at(0, self.model.M)
  File "/cluster/rs_lab/dbarton/usb_twitching/pili/src/analysis/pwlpartition.py", line 250, in residual_at
    residual = np.concatenate(distance_list)
  File "<__array_function__ internals>", line 5, in concatenate
ValueError: need at least one array to concatenate
Process Process-97:
Traceback (most recent call last):
  File "/cluster/rs_lab/dbarton/env/lib/python3.8/multiprocessing/process.py", line 315, in _bootstrap
    self.run()
  File "/cluster/rs_lab/dbarton/env/lib/python3.8/multiprocessing/process.py", line 108, in run
    self._target(*self._args, **self._kwargs)
  File "run_pwl.py", line 157, in pwl_solve
    'solver_iter' : solver.get_iter_count()
AttributeError: 'Solver' object has no attribute 'get_iter_count'
Process Process-110:
Traceback (most recent call last):
  File "/cluster/rs_lab/dbarton/env/lib/python3.8/multiprocessing/process.py", line 315, in _bootstrap
    self.run()
  File "/cluster/rs_lab/dbarton/env/lib/python3.8/multiprocessing/process.py", line 108, in run
    self._target(*self._args, **self._kwargs)
  File "run_pwl.py", line 157, in pwl_solve
    'solver_iter' : solver.get_iter_count()
AttributeError: 'Solver' object has no attribute 'get_iter_count'
Process Process-82:
Traceback (most recent call last):
  File "/cluster/rs_lab/dbarton/env/lib/python3.8/multiprocessing/process.py", line 315, in _bootstrap
    self.run()
  File "/cluster/rs_lab/dbarton/env/lib/python3.8/multiprocessing/process.py", line 108, in run
    self._target(*self._args, **self._kwargs)
  File "run_pwl.py", line 157, in pwl_solve
    'solver_iter' : solver.get_iter_count()
AttributeError: 'Solver' object has no attribute 'get_iter_count'
Process Process-118:
Traceback (most recent call last):
  File "/cluster/rs_lab/dbarton/env/lib/python3.8/multiprocessing/process.py", line 315, in _bootstrap
    self.run()
  File "/cluster/rs_lab/dbarton/env/lib/python3.8/multiprocessing/process.py", line 108, in run
    self._target(*self._args, **self._kwargs)
  File "run_pwl.py", line 157, in pwl_solve
    'solver_iter' : solver.get_iter_count()
AttributeError: 'Solver' object has no attribute 'get_iter_count'
Process Process-4:
Traceback (most recent call last):
  File "/cluster/rs_lab/dbarton/env/lib/python3.8/multiprocessing/process.py", line 315, in _bootstrap
    self.run()
  File "/cluster/rs_lab/dbarton/env/lib/python3.8/multiprocessing/process.py", line 108, in run
    self._target(*self._args, **self._kwargs)
  File "run_pwl.py", line 157, in pwl_solve
    'solver_iter' : solver.get_iter_count()
AttributeError: 'Solver' object has no attribute 'get_iter_count'
Process Process-96:
Traceback (most recent call last):
  File "/cluster/rs_lab/dbarton/env/lib/python3.8/multiprocessing/process.py", line 315, in _bootstrap
    self.run()
  File "/cluster/rs_lab/dbarton/env/lib/python3.8/multiprocessing/process.py", line 108, in run
    self._target(*self._args, **self._kwargs)
  File "run_pwl.py", line 157, in pwl_solve
    'solver_iter' : solver.get_iter_count()
AttributeError: 'Solver' object has no attribute 'get_iter_count'
/cluster/rs_lab/dbarton/usb_twitching/pili/support.py:52: RuntimeWarning: invalid value encountered in true_divide
  d_hat = np.divide(d_ba, d)
/cluster/rs_lab/dbarton/usb_twitching/pili/support.py:52: RuntimeWarning: invalid value encountered in true_divide
  d_hat = np.divide(d_ba, d)
Process Process-28:
Traceback (most recent call last):
  File "/cluster/rs_lab/dbarton/env/lib/python3.8/multiprocessing/process.py", line 315, in _bootstrap
    self.run()
  File "/cluster/rs_lab/dbarton/env/lib/python3.8/multiprocessing/process.py", line 108, in run
    self._target(*self._args, **self._kwargs)
  File "run_pwl.py", line 157, in pwl_solve
    'solver_iter' : solver.get_iter_count()
AttributeError: 'Solver' object has no attribute 'get_iter_count'
Process Process-107:
Traceback (most recent call last):
  File "/cluster/rs_lab/dbarton/env/lib/python3.8/multiprocessing/process.py", line 315, in _bootstrap
    self.run()
  File "/cluster/rs_lab/dbarton/env/lib/python3.8/multiprocessing/process.py", line 108, in run
    self._target(*self._args, **self._kwargs)
  File "run_pwl.py", line 157, in pwl_solve
    'solver_iter' : solver.get_iter_count()
AttributeError: 'Solver' object has no attribute 'get_iter_count'
Process Process-106:
Traceback (most recent call last):
  File "/cluster/rs_lab/dbarton/env/lib/python3.8/multiprocessing/process.py", line 315, in _bootstrap
    self.run()
  File "/cluster/rs_lab/dbarton/env/lib/python3.8/multiprocessing/process.py", line 108, in run
    self._target(*self._args, **self._kwargs)
  File "run_pwl.py", line 157, in pwl_solve
    'solver_iter' : solver.get_iter_count()
AttributeError: 'Solver' object has no attribute 'get_iter_count'
Process Process-98:
Traceback (most recent call last):
  File "/cluster/rs_lab/dbarton/env/lib/python3.8/multiprocessing/process.py", line 315, in _bootstrap
    self.run()
  File "/cluster/rs_lab/dbarton/env/lib/python3.8/multiprocessing/process.py", line 108, in run
    self._target(*self._args, **self._kwargs)
  File "run_pwl.py", line 157, in pwl_solve
    'solver_iter' : solver.get_iter_count()
AttributeError: 'Solver' object has no attribute 'get_iter_count'
Process Process-95:
Traceback (most recent call last):
  File "/cluster/rs_lab/dbarton/env/lib/python3.8/multiprocessing/process.py", line 315, in _bootstrap
    self.run()
  File "/cluster/rs_lab/dbarton/env/lib/python3.8/multiprocessing/process.py", line 108, in run
    self._target(*self._args, **self._kwargs)
  File "run_pwl.py", line 157, in pwl_solve
    'solver_iter' : solver.get_iter_count()
AttributeError: 'Solver' object has no attribute 'get_iter_count'
/cluster/rs_lab/dbarton/usb_twitching/pili/support.py:52: RuntimeWarning: invalid value encountered in true_divide
  d_hat = np.divide(d_ba, d)
/cluster/rs_lab/dbarton/usb_twitching/pili/src/analysis/pwlpartition.py:102: RuntimeWarning: invalid value encountered in true_divide
  u = vector/length[:,np.newaxis]
Process Process-131:
Traceback (most recent call last):
  File "/cluster/rs_lab/dbarton/env/lib/python3.8/multiprocessing/process.py", line 315, in _bootstrap
    self.run()
  File "/cluster/rs_lab/dbarton/env/lib/python3.8/multiprocessing/process.py", line 108, in run
    self._target(*self._args, **self._kwargs)
  File "run_pwl.py", line 142, in pwl_solve
    solver.priority_solve(control, output=output)
  File "/cluster/rs_lab/dbarton/usb_twitching/pili/src/analysis/pwlpartition.py", line 823, in priority_solve
    accepted = self.destroy_at(index)
  File "/cluster/rs_lab/dbarton/usb_twitching/pili/src/analysis/pwlpartition.py", line 1036, in destroy_at
    clone.delete_at(index)
  File "/cluster/rs_lab/dbarton/usb_twitching/pili/src/analysis/pwlpartition.py", line 407, in delete_at
    self.update_residuals()
  File "/cluster/rs_lab/dbarton/usb_twitching/pili/src/analysis/pwlpartition.py", line 175, in update_residuals
    self.residual_at(0, self.model.M)
  File "/cluster/rs_lab/dbarton/usb_twitching/pili/src/analysis/pwlpartition.py", line 250, in residual_at
    residual = np.concatenate(distance_list)
  File "<__array_function__ internals>", line 5, in concatenate
ValueError: need at least one array to concatenate
Process Process-76:
Traceback (most recent call last):
  File "/cluster/rs_lab/dbarton/env/lib/python3.8/multiprocessing/process.py", line 315, in _bootstrap
    self.run()
  File "/cluster/rs_lab/dbarton/env/lib/python3.8/multiprocessing/process.py", line 108, in run
    self._target(*self._args, **self._kwargs)
  File "run_pwl.py", line 157, in pwl_solve
    'solver_iter' : solver.get_iter_count()
AttributeError: 'Solver' object has no attribute 'get_iter_count'
Process Process-130:
Traceback (most recent call last):
  File "/cluster/rs_lab/dbarton/env/lib/python3.8/multiprocessing/process.py", line 315, in _bootstrap
    self.run()
  File "/cluster/rs_lab/dbarton/env/lib/python3.8/multiprocessing/process.py", line 108, in run
    self._target(*self._args, **self._kwargs)
  File "run_pwl.py", line 157, in pwl_solve
    'solver_iter' : solver.get_iter_count()
AttributeError: 'Solver' object has no attribute 'get_iter_count'
Process Process-58:
Traceback (most recent call last):
  File "/cluster/rs_lab/dbarton/env/lib/python3.8/multiprocessing/process.py", line 315, in _bootstrap
    self.run()
  File "/cluster/rs_lab/dbarton/env/lib/python3.8/multiprocessing/process.py", line 108, in run
    self._target(*self._args, **self._kwargs)
  File "run_pwl.py", line 157, in pwl_solve
    'solver_iter' : solver.get_iter_count()
AttributeError: 'Solver' object has no attribute 'get_iter_count'
Process Process-85:
Traceback (most recent call last):
  File "/cluster/rs_lab/dbarton/env/lib/python3.8/multiprocessing/process.py", line 315, in _bootstrap
    self.run()
  File "/cluster/rs_lab/dbarton/env/lib/python3.8/multiprocessing/process.py", line 108, in run
    self._target(*self._args, **self._kwargs)
  File "run_pwl.py", line 157, in pwl_solve
    'solver_iter' : solver.get_iter_count()
AttributeError: 'Solver' object has no attribute 'get_iter_count'
Process Process-137:
Traceback (most recent call last):
  File "/cluster/rs_lab/dbarton/env/lib/python3.8/multiprocessing/process.py", line 315, in _bootstrap
    self.run()
  File "/cluster/rs_lab/dbarton/env/lib/python3.8/multiprocessing/process.py", line 108, in run
    self._target(*self._args, **self._kwargs)
  File "run_pwl.py", line 157, in pwl_solve
    'solver_iter' : solver.get_iter_count()
AttributeError: 'Solver' object has no attribute 'get_iter_count'
Process Process-148:
Traceback (most recent call last):
  File "/cluster/rs_lab/dbarton/env/lib/python3.8/multiprocessing/process.py", line 315, in _bootstrap
    self.run()
  File "/cluster/rs_lab/dbarton/env/lib/python3.8/multiprocessing/process.py", line 108, in run
    self._target(*self._args, **self._kwargs)
  File "run_pwl.py", line 157, in pwl_solve
    'solver_iter' : solver.get_iter_count()
AttributeError: 'Solver' object has no attribute 'get_iter_count'
Process Process-44:
Traceback (most recent call last):
  File "/cluster/rs_lab/dbarton/env/lib/python3.8/multiprocessing/process.py", line 315, in _bootstrap
    self.run()
  File "/cluster/rs_lab/dbarton/env/lib/python3.8/multiprocessing/process.py", line 108, in run
    self._target(*self._args, **self._kwargs)
  File "run_pwl.py", line 157, in pwl_solve
    'solver_iter' : solver.get_iter_count()
AttributeError: 'Solver' object has no attribute 'get_iter_count'
Process Process-77:
Traceback (most recent call last):
  File "/cluster/rs_lab/dbarton/env/lib/python3.8/multiprocessing/process.py", line 315, in _bootstrap
    self.run()
  File "/cluster/rs_lab/dbarton/env/lib/python3.8/multiprocessing/process.py", line 108, in run
    self._target(*self._args, **self._kwargs)
  File "run_pwl.py", line 157, in pwl_solve
    'solver_iter' : solver.get_iter_count()
AttributeError: 'Solver' object has no attribute 'get_iter_count'
Process Process-101:
Traceback (most recent call last):
  File "/cluster/rs_lab/dbarton/env/lib/python3.8/multiprocessing/process.py", line 315, in _bootstrap
    self.run()
  File "/cluster/rs_lab/dbarton/env/lib/python3.8/multiprocessing/process.py", line 108, in run
    self._target(*self._args, **self._kwargs)
  File "run_pwl.py", line 157, in pwl_solve
    'solver_iter' : solver.get_iter_count()
AttributeError: 'Solver' object has no attribute 'get_iter_count'
Process Process-105:
Traceback (most recent call last):
  File "/cluster/rs_lab/dbarton/env/lib/python3.8/multiprocessing/process.py", line 315, in _bootstrap
    self.run()
  File "/cluster/rs_lab/dbarton/env/lib/python3.8/multiprocessing/process.py", line 108, in run
    self._target(*self._args, **self._kwargs)
  File "run_pwl.py", line 157, in pwl_solve
    'solver_iter' : solver.get_iter_count()
AttributeError: 'Solver' object has no attribute 'get_iter_count'
Process Process-117:
Traceback (most recent call last):
  File "/cluster/rs_lab/dbarton/env/lib/python3.8/multiprocessing/process.py", line 315, in _bootstrap
    self.run()
  File "/cluster/rs_lab/dbarton/env/lib/python3.8/multiprocessing/process.py", line 108, in run
    self._target(*self._args, **self._kwargs)
  File "run_pwl.py", line 157, in pwl_solve
    'solver_iter' : solver.get_iter_count()
AttributeError: 'Solver' object has no attribute 'get_iter_count'
Process Process-26:
Traceback (most recent call last):
  File "/cluster/rs_lab/dbarton/env/lib/python3.8/multiprocessing/process.py", line 315, in _bootstrap
    self.run()
  File "/cluster/rs_lab/dbarton/env/lib/python3.8/multiprocessing/process.py", line 108, in run
    self._target(*self._args, **self._kwargs)
  File "run_pwl.py", line 157, in pwl_solve
    'solver_iter' : solver.get_iter_count()
AttributeError: 'Solver' object has no attribute 'get_iter_count'
Process Process-78:
Traceback (most recent call last):
  File "/cluster/rs_lab/dbarton/env/lib/python3.8/multiprocessing/process.py", line 315, in _bootstrap
    self.run()
  File "/cluster/rs_lab/dbarton/env/lib/python3.8/multiprocessing/process.py", line 108, in run
    self._target(*self._args, **self._kwargs)
  File "run_pwl.py", line 157, in pwl_solve
    'solver_iter' : solver.get_iter_count()
AttributeError: 'Solver' object has no attribute 'get_iter_count'
Process Process-75:
Traceback (most recent call last):
  File "/cluster/rs_lab/dbarton/env/lib/python3.8/multiprocessing/process.py", line 315, in _bootstrap
    self.run()
  File "/cluster/rs_lab/dbarton/env/lib/python3.8/multiprocessing/process.py", line 108, in run
    self._target(*self._args, **self._kwargs)
  File "run_pwl.py", line 157, in pwl_solve
    'solver_iter' : solver.get_iter_count()
AttributeError: 'Solver' object has no attribute 'get_iter_count'
Process Process-90:
Traceback (most recent call last):
  File "/cluster/rs_lab/dbarton/env/lib/python3.8/multiprocessing/process.py", line 315, in _bootstrap
    self.run()
  File "/cluster/rs_lab/dbarton/env/lib/python3.8/multiprocessing/process.py", line 108, in run
    self._target(*self._args, **self._kwargs)
  File "run_pwl.py", line 157, in pwl_solve
    'solver_iter' : solver.get_iter_count()
AttributeError: 'Solver' object has no attribute 'get_iter_count'
Process Process-155:
Traceback (most recent call last):
  File "/cluster/rs_lab/dbarton/env/lib/python3.8/multiprocessing/process.py", line 315, in _bootstrap
    self.run()
  File "/cluster/rs_lab/dbarton/env/lib/python3.8/multiprocessing/process.py", line 108, in run
    self._target(*self._args, **self._kwargs)
  File "run_pwl.py", line 157, in pwl_solve
    'solver_iter' : solver.get_iter_count()
AttributeError: 'Solver' object has no attribute 'get_iter_count'
/cluster/rs_lab/dbarton/usb_twitching/pili/src/analysis/mdl.py:193: RuntimeWarning: invalid value encountered in arccos
  theta = np.arccos(np.sum(norm_dx * norm_dy,axis=1))
Process Process-140:
Traceback (most recent call last):
  File "/cluster/rs_lab/dbarton/env/lib/python3.8/multiprocessing/process.py", line 315, in _bootstrap
    self.run()
  File "/cluster/rs_lab/dbarton/env/lib/python3.8/multiprocessing/process.py", line 108, in run
    self._target(*self._args, **self._kwargs)
  File "run_pwl.py", line 157, in pwl_solve
    'solver_iter' : solver.get_iter_count()
AttributeError: 'Solver' object has no attribute 'get_iter_count'
Process Process-119:
Traceback (most recent call last):
  File "/cluster/rs_lab/dbarton/env/lib/python3.8/multiprocessing/process.py", line 315, in _bootstrap
    self.run()
  File "/cluster/rs_lab/dbarton/env/lib/python3.8/multiprocessing/process.py", line 108, in run
    self._target(*self._args, **self._kwargs)
  File "run_pwl.py", line 157, in pwl_solve
    'solver_iter' : solver.get_iter_count()
AttributeError: 'Solver' object has no attribute 'get_iter_count'
Process Process-88:
Traceback (most recent call last):
  File "/cluster/rs_lab/dbarton/env/lib/python3.8/multiprocessing/process.py", line 315, in _bootstrap
    self.run()
  File "/cluster/rs_lab/dbarton/env/lib/python3.8/multiprocessing/process.py", line 108, in run
    self._target(*self._args, **self._kwargs)
  File "run_pwl.py", line 157, in pwl_solve
    'solver_iter' : solver.get_iter_count()
AttributeError: 'Solver' object has no attribute 'get_iter_count'
Process Process-73:
Traceback (most recent call last):
  File "/cluster/rs_lab/dbarton/env/lib/python3.8/multiprocessing/process.py", line 315, in _bootstrap
    self.run()
  File "/cluster/rs_lab/dbarton/env/lib/python3.8/multiprocessing/process.py", line 108, in run
    self._target(*self._args, **self._kwargs)
  File "run_pwl.py", line 157, in pwl_solve
    'solver_iter' : solver.get_iter_count()
AttributeError: 'Solver' object has no attribute 'get_iter_count'
Process Process-99:
Traceback (most recent call last):
  File "/cluster/rs_lab/dbarton/env/lib/python3.8/multiprocessing/process.py", line 315, in _bootstrap
    self.run()
  File "/cluster/rs_lab/dbarton/env/lib/python3.8/multiprocessing/process.py", line 108, in run
    self._target(*self._args, **self._kwargs)
  File "run_pwl.py", line 157, in pwl_solve
    'solver_iter' : solver.get_iter_count()
AttributeError: 'Solver' object has no attribute 'get_iter_count'
Process Process-121:
Traceback (most recent call last):
  File "/cluster/rs_lab/dbarton/env/lib/python3.8/multiprocessing/process.py", line 315, in _bootstrap
    self.run()
  File "/cluster/rs_lab/dbarton/env/lib/python3.8/multiprocessing/process.py", line 108, in run
    self._target(*self._args, **self._kwargs)
  File "run_pwl.py", line 157, in pwl_solve
    'solver_iter' : solver.get_iter_count()
AttributeError: 'Solver' object has no attribute 'get_iter_count'
Process Process-55:
Traceback (most recent call last):
  File "/cluster/rs_lab/dbarton/env/lib/python3.8/multiprocessing/process.py", line 315, in _bootstrap
    self.run()
  File "/cluster/rs_lab/dbarton/env/lib/python3.8/multiprocessing/process.py", line 108, in run
    self._target(*self._args, **self._kwargs)
  File "run_pwl.py", line 157, in pwl_solve
    'solver_iter' : solver.get_iter_count()
AttributeError: 'Solver' object has no attribute 'get_iter_count'
/cluster/rs_lab/dbarton/usb_twitching/pili/support.py:52: RuntimeWarning: invalid value encountered in true_divide
  d_hat = np.divide(d_ba, d)
/cluster/rs_lab/dbarton/usb_twitching/pili/src/analysis/pwlpartition.py:102: RuntimeWarning: invalid value encountered in true_divide
  u = vector/length[:,np.newaxis]
Process Process-125:
Traceback (most recent call last):
  File "/cluster/rs_lab/dbarton/env/lib/python3.8/multiprocessing/process.py", line 315, in _bootstrap
    self.run()
  File "/cluster/rs_lab/dbarton/env/lib/python3.8/multiprocessing/process.py", line 108, in run
    self._target(*self._args, **self._kwargs)
  File "run_pwl.py", line 142, in pwl_solve
    solver.priority_solve(control, output=output)
  File "/cluster/rs_lab/dbarton/usb_twitching/pili/src/analysis/pwlpartition.py", line 823, in priority_solve
    accepted = self.destroy_at(index)
  File "/cluster/rs_lab/dbarton/usb_twitching/pili/src/analysis/pwlpartition.py", line 1036, in destroy_at
    clone.delete_at(index)
  File "/cluster/rs_lab/dbarton/usb_twitching/pili/src/analysis/pwlpartition.py", line 407, in delete_at
    self.update_residuals()
  File "/cluster/rs_lab/dbarton/usb_twitching/pili/src/analysis/pwlpartition.py", line 175, in update_residuals
    self.residual_at(0, self.model.M)
  File "/cluster/rs_lab/dbarton/usb_twitching/pili/src/analysis/pwlpartition.py", line 250, in residual_at
    residual = np.concatenate(distance_list)
  File "<__array_function__ internals>", line 5, in concatenate
ValueError: need at least one array to concatenate
Process Process-94:
Traceback (most recent call last):
  File "/cluster/rs_lab/dbarton/env/lib/python3.8/multiprocessing/process.py", line 315, in _bootstrap
    self.run()
  File "/cluster/rs_lab/dbarton/env/lib/python3.8/multiprocessing/process.py", line 108, in run
    self._target(*self._args, **self._kwargs)
  File "run_pwl.py", line 157, in pwl_solve
    'solver_iter' : solver.get_iter_count()
AttributeError: 'Solver' object has no attribute 'get_iter_count'
/cluster/rs_lab/dbarton/usb_twitching/pili/support.py:52: RuntimeWarning: invalid value encountered in true_divide
  d_hat = np.divide(d_ba, d)
/cluster/rs_lab/dbarton/usb_twitching/pili/support.py:52: RuntimeWarning: invalid value encountered in true_divide
  d_hat = np.divide(d_ba, d)
Process Process-116:
Traceback (most recent call last):
  File "/cluster/rs_lab/dbarton/env/lib/python3.8/multiprocessing/process.py", line 315, in _bootstrap
    self.run()
  File "/cluster/rs_lab/dbarton/env/lib/python3.8/multiprocessing/process.py", line 108, in run
    self._target(*self._args, **self._kwargs)
  File "run_pwl.py", line 157, in pwl_solve
    'solver_iter' : solver.get_iter_count()
AttributeError: 'Solver' object has no attribute 'get_iter_count'
/cluster/rs_lab/dbarton/usb_twitching/pili/src/analysis/mdl.py:193: RuntimeWarning: invalid value encountered in arccos
  theta = np.arccos(np.sum(norm_dx * norm_dy,axis=1))
Process Process-156:
Traceback (most recent call last):
  File "/cluster/rs_lab/dbarton/env/lib/python3.8/multiprocessing/process.py", line 315, in _bootstrap
    self.run()
  File "/cluster/rs_lab/dbarton/env/lib/python3.8/multiprocessing/process.py", line 108, in run
    self._target(*self._args, **self._kwargs)
  File "run_pwl.py", line 157, in pwl_solve
    'solver_iter' : solver.get_iter_count()
AttributeError: 'Solver' object has no attribute 'get_iter_count'
Process Process-138:
Traceback (most recent call last):
  File "/cluster/rs_lab/dbarton/env/lib/python3.8/multiprocessing/process.py", line 315, in _bootstrap
    self.run()
  File "/cluster/rs_lab/dbarton/env/lib/python3.8/multiprocessing/process.py", line 108, in run
    self._target(*self._args, **self._kwargs)
  File "run_pwl.py", line 157, in pwl_solve
    'solver_iter' : solver.get_iter_count()
AttributeError: 'Solver' object has no attribute 'get_iter_count'
Process Process-112:
Traceback (most recent call last):
  File "/cluster/rs_lab/dbarton/env/lib/python3.8/multiprocessing/process.py", line 315, in _bootstrap
    self.run()
  File "/cluster/rs_lab/dbarton/env/lib/python3.8/multiprocessing/process.py", line 108, in run
    self._target(*self._args, **self._kwargs)
  File "run_pwl.py", line 157, in pwl_solve
    'solver_iter' : solver.get_iter_count()
AttributeError: 'Solver' object has no attribute 'get_iter_count'
Process Process-120:
Traceback (most recent call last):
  File "/cluster/rs_lab/dbarton/env/lib/python3.8/multiprocessing/process.py", line 315, in _bootstrap
    self.run()
  File "/cluster/rs_lab/dbarton/env/lib/python3.8/multiprocessing/process.py", line 108, in run
    self._target(*self._args, **self._kwargs)
  File "run_pwl.py", line 157, in pwl_solve
    'solver_iter' : solver.get_iter_count()
AttributeError: 'Solver' object has no attribute 'get_iter_count'
Process Process-141:
Traceback (most recent call last):
  File "/cluster/rs_lab/dbarton/env/lib/python3.8/multiprocessing/process.py", line 315, in _bootstrap
    self.run()
  File "/cluster/rs_lab/dbarton/env/lib/python3.8/multiprocessing/process.py", line 108, in run
    self._target(*self._args, **self._kwargs)
  File "run_pwl.py", line 157, in pwl_solve
    'solver_iter' : solver.get_iter_count()
AttributeError: 'Solver' object has no attribute 'get_iter_count'
Process Process-144:
Traceback (most recent call last):
  File "/cluster/rs_lab/dbarton/env/lib/python3.8/multiprocessing/process.py", line 315, in _bootstrap
    self.run()
  File "/cluster/rs_lab/dbarton/env/lib/python3.8/multiprocessing/process.py", line 108, in run
    self._target(*self._args, **self._kwargs)
  File "run_pwl.py", line 157, in pwl_solve
    'solver_iter' : solver.get_iter_count()
AttributeError: 'Solver' object has no attribute 'get_iter_count'
Process Process-122:
Traceback (most recent call last):
  File "/cluster/rs_lab/dbarton/env/lib/python3.8/multiprocessing/process.py", line 315, in _bootstrap
    self.run()
  File "/cluster/rs_lab/dbarton/env/lib/python3.8/multiprocessing/process.py", line 108, in run
    self._target(*self._args, **self._kwargs)
  File "run_pwl.py", line 157, in pwl_solve
    'solver_iter' : solver.get_iter_count()
AttributeError: 'Solver' object has no attribute 'get_iter_count'
Process Process-124:
Traceback (most recent call last):
  File "/cluster/rs_lab/dbarton/env/lib/python3.8/multiprocessing/process.py", line 315, in _bootstrap
    self.run()
  File "/cluster/rs_lab/dbarton/env/lib/python3.8/multiprocessing/process.py", line 108, in run
    self._target(*self._args, **self._kwargs)
  File "run_pwl.py", line 157, in pwl_solve
    'solver_iter' : solver.get_iter_count()
AttributeError: 'Solver' object has no attribute 'get_iter_count'
Process Process-89:
Traceback (most recent call last):
  File "/cluster/rs_lab/dbarton/env/lib/python3.8/multiprocessing/process.py", line 315, in _bootstrap
    self.run()
  File "/cluster/rs_lab/dbarton/env/lib/python3.8/multiprocessing/process.py", line 108, in run
    self._target(*self._args, **self._kwargs)
  File "run_pwl.py", line 157, in pwl_solve
    'solver_iter' : solver.get_iter_count()
AttributeError: 'Solver' object has no attribute 'get_iter_count'
Process Process-133:
Traceback (most recent call last):
  File "/cluster/rs_lab/dbarton/env/lib/python3.8/multiprocessing/process.py", line 315, in _bootstrap
    self.run()
  File "/cluster/rs_lab/dbarton/env/lib/python3.8/multiprocessing/process.py", line 108, in run
    self._target(*self._args, **self._kwargs)
  File "run_pwl.py", line 157, in pwl_solve
    'solver_iter' : solver.get_iter_count()
AttributeError: 'Solver' object has no attribute 'get_iter_count'
Process Process-171:
Traceback (most recent call last):
  File "/cluster/rs_lab/dbarton/env/lib/python3.8/multiprocessing/process.py", line 315, in _bootstrap
    self.run()
  File "/cluster/rs_lab/dbarton/env/lib/python3.8/multiprocessing/process.py", line 108, in run
    self._target(*self._args, **self._kwargs)
  File "run_pwl.py", line 157, in pwl_solve
    'solver_iter' : solver.get_iter_count()
AttributeError: 'Solver' object has no attribute 'get_iter_count'
Process Process-136:
Traceback (most recent call last):
  File "/cluster/rs_lab/dbarton/env/lib/python3.8/multiprocessing/process.py", line 315, in _bootstrap
    self.run()
  File "/cluster/rs_lab/dbarton/env/lib/python3.8/multiprocessing/process.py", line 108, in run
    self._target(*self._args, **self._kwargs)
  File "run_pwl.py", line 157, in pwl_solve
    'solver_iter' : solver.get_iter_count()
AttributeError: 'Solver' object has no attribute 'get_iter_count'
Process Process-150:
Traceback (most recent call last):
  File "/cluster/rs_lab/dbarton/env/lib/python3.8/multiprocessing/process.py", line 315, in _bootstrap
    self.run()
  File "/cluster/rs_lab/dbarton/env/lib/python3.8/multiprocessing/process.py", line 108, in run
    self._target(*self._args, **self._kwargs)
  File "run_pwl.py", line 157, in pwl_solve
    'solver_iter' : solver.get_iter_count()
AttributeError: 'Solver' object has no attribute 'get_iter_count'
Process Process-154:
Traceback (most recent call last):
  File "/cluster/rs_lab/dbarton/env/lib/python3.8/multiprocessing/process.py", line 315, in _bootstrap
    self.run()
  File "/cluster/rs_lab/dbarton/env/lib/python3.8/multiprocessing/process.py", line 108, in run
    self._target(*self._args, **self._kwargs)
  File "run_pwl.py", line 157, in pwl_solve
    'solver_iter' : solver.get_iter_count()
AttributeError: 'Solver' object has no attribute 'get_iter_count'
Process Process-109:
Traceback (most recent call last):
  File "/cluster/rs_lab/dbarton/env/lib/python3.8/multiprocessing/process.py", line 315, in _bootstrap
    self.run()
  File "/cluster/rs_lab/dbarton/env/lib/python3.8/multiprocessing/process.py", line 108, in run
    self._target(*self._args, **self._kwargs)
  File "run_pwl.py", line 157, in pwl_solve
    'solver_iter' : solver.get_iter_count()
AttributeError: 'Solver' object has no attribute 'get_iter_count'
Process Process-159:
Traceback (most recent call last):
  File "/cluster/rs_lab/dbarton/env/lib/python3.8/multiprocessing/process.py", line 315, in _bootstrap
    self.run()
  File "/cluster/rs_lab/dbarton/env/lib/python3.8/multiprocessing/process.py", line 108, in run
    self._target(*self._args, **self._kwargs)
  File "run_pwl.py", line 157, in pwl_solve
    'solver_iter' : solver.get_iter_count()
AttributeError: 'Solver' object has no attribute 'get_iter_count'
Process Process-128:
Traceback (most recent call last):
  File "/cluster/rs_lab/dbarton/env/lib/python3.8/multiprocessing/process.py", line 315, in _bootstrap
    self.run()
  File "/cluster/rs_lab/dbarton/env/lib/python3.8/multiprocessing/process.py", line 108, in run
    self._target(*self._args, **self._kwargs)
  File "run_pwl.py", line 157, in pwl_solve
    'solver_iter' : solver.get_iter_count()
AttributeError: 'Solver' object has no attribute 'get_iter_count'
Process Process-123:
Traceback (most recent call last):
  File "/cluster/rs_lab/dbarton/env/lib/python3.8/multiprocessing/process.py", line 315, in _bootstrap
    self.run()
  File "/cluster/rs_lab/dbarton/env/lib/python3.8/multiprocessing/process.py", line 108, in run
    self._target(*self._args, **self._kwargs)
  File "run_pwl.py", line 157, in pwl_solve
    'solver_iter' : solver.get_iter_count()
AttributeError: 'Solver' object has no attribute 'get_iter_count'
Process Process-132:
Traceback (most recent call last):
  File "/cluster/rs_lab/dbarton/env/lib/python3.8/multiprocessing/process.py", line 315, in _bootstrap
    self.run()
  File "/cluster/rs_lab/dbarton/env/lib/python3.8/multiprocessing/process.py", line 108, in run
    self._target(*self._args, **self._kwargs)
  File "run_pwl.py", line 157, in pwl_solve
    'solver_iter' : solver.get_iter_count()
AttributeError: 'Solver' object has no attribute 'get_iter_count'
Process Process-146:
Traceback (most recent call last):
  File "/cluster/rs_lab/dbarton/env/lib/python3.8/multiprocessing/process.py", line 315, in _bootstrap
    self.run()
  File "/cluster/rs_lab/dbarton/env/lib/python3.8/multiprocessing/process.py", line 108, in run
    self._target(*self._args, **self._kwargs)
  File "run_pwl.py", line 157, in pwl_solve
    'solver_iter' : solver.get_iter_count()
AttributeError: 'Solver' object has no attribute 'get_iter_count'
/cluster/rs_lab/dbarton/usb_twitching/pili/support.py:52: RuntimeWarning: invalid value encountered in true_divide
  d_hat = np.divide(d_ba, d)
/cluster/rs_lab/dbarton/usb_twitching/pili/src/analysis/pwlpartition.py:102: RuntimeWarning: invalid value encountered in true_divide
  u = vector/length[:,np.newaxis]
Process Process-151:
Traceback (most recent call last):
  File "/cluster/rs_lab/dbarton/env/lib/python3.8/multiprocessing/process.py", line 315, in _bootstrap
    self.run()
  File "/cluster/rs_lab/dbarton/env/lib/python3.8/multiprocessing/process.py", line 108, in run
    self._target(*self._args, **self._kwargs)
  File "run_pwl.py", line 142, in pwl_solve
    solver.priority_solve(control, output=output)
  File "/cluster/rs_lab/dbarton/usb_twitching/pili/src/analysis/pwlpartition.py", line 823, in priority_solve
    accepted = self.destroy_at(index)
  File "/cluster/rs_lab/dbarton/usb_twitching/pili/src/analysis/pwlpartition.py", line 1036, in destroy_at
    clone.delete_at(index)
  File "/cluster/rs_lab/dbarton/usb_twitching/pili/src/analysis/pwlpartition.py", line 407, in delete_at
    self.update_residuals()
  File "/cluster/rs_lab/dbarton/usb_twitching/pili/src/analysis/pwlpartition.py", line 175, in update_residuals
    self.residual_at(0, self.model.M)
  File "/cluster/rs_lab/dbarton/usb_twitching/pili/src/analysis/pwlpartition.py", line 250, in residual_at
    residual = np.concatenate(distance_list)
  File "<__array_function__ internals>", line 5, in concatenate
ValueError: need at least one array to concatenate
/cluster/rs_lab/dbarton/usb_twitching/pili/support.py:52: RuntimeWarning: invalid value encountered in true_divide
  d_hat = np.divide(d_ba, d)
/cluster/rs_lab/dbarton/usb_twitching/pili/support.py:52: RuntimeWarning: invalid value encountered in true_divide
  d_hat = np.divide(d_ba, d)
/cluster/rs_lab/dbarton/usb_twitching/pili/src/analysis/pwlpartition.py:102: RuntimeWarning: invalid value encountered in true_divide
  u = vector/length[:,np.newaxis]
Process Process-167:
Traceback (most recent call last):
  File "/cluster/rs_lab/dbarton/env/lib/python3.8/multiprocessing/process.py", line 315, in _bootstrap
    self.run()
  File "/cluster/rs_lab/dbarton/env/lib/python3.8/multiprocessing/process.py", line 108, in run
    self._target(*self._args, **self._kwargs)
  File "run_pwl.py", line 142, in pwl_solve
    solver.priority_solve(control, output=output)
  File "/cluster/rs_lab/dbarton/usb_twitching/pili/src/analysis/pwlpartition.py", line 823, in priority_solve
    accepted = self.destroy_at(index)
  File "/cluster/rs_lab/dbarton/usb_twitching/pili/src/analysis/pwlpartition.py", line 1036, in destroy_at
    clone.delete_at(index)
  File "/cluster/rs_lab/dbarton/usb_twitching/pili/src/analysis/pwlpartition.py", line 407, in delete_at
    self.update_residuals()
  File "/cluster/rs_lab/dbarton/usb_twitching/pili/src/analysis/pwlpartition.py", line 175, in update_residuals
    self.residual_at(0, self.model.M)
  File "/cluster/rs_lab/dbarton/usb_twitching/pili/src/analysis/pwlpartition.py", line 250, in residual_at
    residual = np.concatenate(distance_list)
  File "<__array_function__ internals>", line 5, in concatenate
ValueError: need at least one array to concatenate
Process Process-139:
Traceback (most recent call last):
  File "/cluster/rs_lab/dbarton/env/lib/python3.8/multiprocessing/process.py", line 315, in _bootstrap
    self.run()
  File "/cluster/rs_lab/dbarton/env/lib/python3.8/multiprocessing/process.py", line 108, in run
    self._target(*self._args, **self._kwargs)
  File "run_pwl.py", line 157, in pwl_solve
    'solver_iter' : solver.get_iter_count()
AttributeError: 'Solver' object has no attribute 'get_iter_count'
Process Process-147:
Traceback (most recent call last):
  File "/cluster/rs_lab/dbarton/env/lib/python3.8/multiprocessing/process.py", line 315, in _bootstrap
    self.run()
  File "/cluster/rs_lab/dbarton/env/lib/python3.8/multiprocessing/process.py", line 108, in run
    self._target(*self._args, **self._kwargs)
  File "run_pwl.py", line 157, in pwl_solve
    'solver_iter' : solver.get_iter_count()
AttributeError: 'Solver' object has no attribute 'get_iter_count'
Process Process-158:
Traceback (most recent call last):
  File "/cluster/rs_lab/dbarton/env/lib/python3.8/multiprocessing/process.py", line 315, in _bootstrap
    self.run()
  File "/cluster/rs_lab/dbarton/env/lib/python3.8/multiprocessing/process.py", line 108, in run
    self._target(*self._args, **self._kwargs)
  File "run_pwl.py", line 157, in pwl_solve
    'solver_iter' : solver.get_iter_count()
AttributeError: 'Solver' object has no attribute 'get_iter_count'
Process Process-108:
Traceback (most recent call last):
  File "/cluster/rs_lab/dbarton/env/lib/python3.8/multiprocessing/process.py", line 315, in _bootstrap
    self.run()
  File "/cluster/rs_lab/dbarton/env/lib/python3.8/multiprocessing/process.py", line 108, in run
    self._target(*self._args, **self._kwargs)
  File "run_pwl.py", line 157, in pwl_solve
    'solver_iter' : solver.get_iter_count()
AttributeError: 'Solver' object has no attribute 'get_iter_count'
/cluster/rs_lab/dbarton/usb_twitching/pili/src/analysis/mdl.py:193: RuntimeWarning: invalid value encountered in arccos
  theta = np.arccos(np.sum(norm_dx * norm_dy,axis=1))
Process Process-134:
Traceback (most recent call last):
  File "/cluster/rs_lab/dbarton/env/lib/python3.8/multiprocessing/process.py", line 315, in _bootstrap
    self.run()
  File "/cluster/rs_lab/dbarton/env/lib/python3.8/multiprocessing/process.py", line 108, in run
    self._target(*self._args, **self._kwargs)
  File "run_pwl.py", line 157, in pwl_solve
    'solver_iter' : solver.get_iter_count()
AttributeError: 'Solver' object has no attribute 'get_iter_count'
Process Process-164:
Traceback (most recent call last):
  File "/cluster/rs_lab/dbarton/env/lib/python3.8/multiprocessing/process.py", line 315, in _bootstrap
    self.run()
  File "/cluster/rs_lab/dbarton/env/lib/python3.8/multiprocessing/process.py", line 108, in run
    self._target(*self._args, **self._kwargs)
  File "run_pwl.py", line 157, in pwl_solve
    'solver_iter' : solver.get_iter_count()
AttributeError: 'Solver' object has no attribute 'get_iter_count'
Process Process-102:
Traceback (most recent call last):
  File "/cluster/rs_lab/dbarton/env/lib/python3.8/multiprocessing/process.py", line 315, in _bootstrap
    self.run()
  File "/cluster/rs_lab/dbarton/env/lib/python3.8/multiprocessing/process.py", line 108, in run
    self._target(*self._args, **self._kwargs)
  File "run_pwl.py", line 157, in pwl_solve
    'solver_iter' : solver.get_iter_count()
AttributeError: 'Solver' object has no attribute 'get_iter_count'
Process Process-174:
Traceback (most recent call last):
  File "/cluster/rs_lab/dbarton/env/lib/python3.8/multiprocessing/process.py", line 315, in _bootstrap
    self.run()
  File "/cluster/rs_lab/dbarton/env/lib/python3.8/multiprocessing/process.py", line 108, in run
    self._target(*self._args, **self._kwargs)
  File "run_pwl.py", line 157, in pwl_solve
    'solver_iter' : solver.get_iter_count()
AttributeError: 'Solver' object has no attribute 'get_iter_count'
Process Process-181:
Traceback (most recent call last):
  File "/cluster/rs_lab/dbarton/env/lib/python3.8/multiprocessing/process.py", line 315, in _bootstrap
    self.run()
  File "/cluster/rs_lab/dbarton/env/lib/python3.8/multiprocessing/process.py", line 108, in run
    self._target(*self._args, **self._kwargs)
  File "run_pwl.py", line 157, in pwl_solve
    'solver_iter' : solver.get_iter_count()
AttributeError: 'Solver' object has no attribute 'get_iter_count'
Process Process-168:
Traceback (most recent call last):
  File "/cluster/rs_lab/dbarton/env/lib/python3.8/multiprocessing/process.py", line 315, in _bootstrap
    self.run()
  File "/cluster/rs_lab/dbarton/env/lib/python3.8/multiprocessing/process.py", line 108, in run
    self._target(*self._args, **self._kwargs)
  File "run_pwl.py", line 157, in pwl_solve
    'solver_iter' : solver.get_iter_count()
AttributeError: 'Solver' object has no attribute 'get_iter_count'
Process Process-176:
Traceback (most recent call last):
  File "/cluster/rs_lab/dbarton/env/lib/python3.8/multiprocessing/process.py", line 315, in _bootstrap
    self.run()
  File "/cluster/rs_lab/dbarton/env/lib/python3.8/multiprocessing/process.py", line 108, in run
    self._target(*self._args, **self._kwargs)
  File "run_pwl.py", line 157, in pwl_solve
    'solver_iter' : solver.get_iter_count()
AttributeError: 'Solver' object has no attribute 'get_iter_count'
Process Process-183:
Traceback (most recent call last):
  File "/cluster/rs_lab/dbarton/env/lib/python3.8/multiprocessing/process.py", line 315, in _bootstrap
    self.run()
  File "/cluster/rs_lab/dbarton/env/lib/python3.8/multiprocessing/process.py", line 108, in run
    self._target(*self._args, **self._kwargs)
  File "run_pwl.py", line 157, in pwl_solve
    'solver_iter' : solver.get_iter_count()
AttributeError: 'Solver' object has no attribute 'get_iter_count'
Process Process-114:
Traceback (most recent call last):
  File "/cluster/rs_lab/dbarton/env/lib/python3.8/multiprocessing/process.py", line 315, in _bootstrap
    self.run()
  File "/cluster/rs_lab/dbarton/env/lib/python3.8/multiprocessing/process.py", line 108, in run
    self._target(*self._args, **self._kwargs)
  File "run_pwl.py", line 157, in pwl_solve
    'solver_iter' : solver.get_iter_count()
AttributeError: 'Solver' object has no attribute 'get_iter_count'
Process Process-182:
Traceback (most recent call last):
  File "/cluster/rs_lab/dbarton/env/lib/python3.8/multiprocessing/process.py", line 315, in _bootstrap
    self.run()
  File "/cluster/rs_lab/dbarton/env/lib/python3.8/multiprocessing/process.py", line 108, in run
    self._target(*self._args, **self._kwargs)
  File "run_pwl.py", line 157, in pwl_solve
    'solver_iter' : solver.get_iter_count()
AttributeError: 'Solver' object has no attribute 'get_iter_count'
Process Process-163:
Traceback (most recent call last):
  File "/cluster/rs_lab/dbarton/env/lib/python3.8/multiprocessing/process.py", line 315, in _bootstrap
    self.run()
  File "/cluster/rs_lab/dbarton/env/lib/python3.8/multiprocessing/process.py", line 108, in run
    self._target(*self._args, **self._kwargs)
  File "run_pwl.py", line 157, in pwl_solve
    'solver_iter' : solver.get_iter_count()
AttributeError: 'Solver' object has no attribute 'get_iter_count'
Process Process-152:
Traceback (most recent call last):
  File "/cluster/rs_lab/dbarton/env/lib/python3.8/multiprocessing/process.py", line 315, in _bootstrap
    self.run()
  File "/cluster/rs_lab/dbarton/env/lib/python3.8/multiprocessing/process.py", line 108, in run
    self._target(*self._args, **self._kwargs)
  File "run_pwl.py", line 157, in pwl_solve
    'solver_iter' : solver.get_iter_count()
AttributeError: 'Solver' object has no attribute 'get_iter_count'
/cluster/rs_lab/dbarton/usb_twitching/pili/support.py:52: RuntimeWarning: invalid value encountered in true_divide
  d_hat = np.divide(d_ba, d)
/cluster/rs_lab/dbarton/usb_twitching/pili/support.py:52: RuntimeWarning: invalid value encountered in true_divide
  d_hat = np.divide(d_ba, d)
/cluster/rs_lab/dbarton/usb_twitching/pili/src/analysis/pwlpartition.py:102: RuntimeWarning: invalid value encountered in true_divide
  u = vector/length[:,np.newaxis]
Process Process-153:
Traceback (most recent call last):
  File "/cluster/rs_lab/dbarton/env/lib/python3.8/multiprocessing/process.py", line 315, in _bootstrap
    self.run()
  File "/cluster/rs_lab/dbarton/env/lib/python3.8/multiprocessing/process.py", line 108, in run
    self._target(*self._args, **self._kwargs)
  File "run_pwl.py", line 142, in pwl_solve
    solver.priority_solve(control, output=output)
  File "/cluster/rs_lab/dbarton/usb_twitching/pili/src/analysis/pwlpartition.py", line 823, in priority_solve
    accepted = self.destroy_at(index)
  File "/cluster/rs_lab/dbarton/usb_twitching/pili/src/analysis/pwlpartition.py", line 1036, in destroy_at
    clone.delete_at(index)
  File "/cluster/rs_lab/dbarton/usb_twitching/pili/src/analysis/pwlpartition.py", line 407, in delete_at
    self.update_residuals()
  File "/cluster/rs_lab/dbarton/usb_twitching/pili/src/analysis/pwlpartition.py", line 175, in update_residuals
    self.residual_at(0, self.model.M)
  File "/cluster/rs_lab/dbarton/usb_twitching/pili/src/analysis/pwlpartition.py", line 250, in residual_at
    residual = np.concatenate(distance_list)
  File "<__array_function__ internals>", line 5, in concatenate
ValueError: need at least one array to concatenate
Process Process-166:
Traceback (most recent call last):
  File "/cluster/rs_lab/dbarton/env/lib/python3.8/multiprocessing/process.py", line 315, in _bootstrap
    self.run()
  File "/cluster/rs_lab/dbarton/env/lib/python3.8/multiprocessing/process.py", line 108, in run
    self._target(*self._args, **self._kwargs)
  File "run_pwl.py", line 157, in pwl_solve
    'solver_iter' : solver.get_iter_count()
AttributeError: 'Solver' object has no attribute 'get_iter_count'
Process Process-169:
Traceback (most recent call last):
  File "/cluster/rs_lab/dbarton/env/lib/python3.8/multiprocessing/process.py", line 315, in _bootstrap
    self.run()
  File "/cluster/rs_lab/dbarton/env/lib/python3.8/multiprocessing/process.py", line 108, in run
    self._target(*self._args, **self._kwargs)
  File "run_pwl.py", line 157, in pwl_solve
    'solver_iter' : solver.get_iter_count()
AttributeError: 'Solver' object has no attribute 'get_iter_count'
/cluster/rs_lab/dbarton/usb_twitching/pili/src/analysis/mdl.py:193: RuntimeWarning: invalid value encountered in arccos
  theta = np.arccos(np.sum(norm_dx * norm_dy,axis=1))
Process Process-145:
Traceback (most recent call last):
  File "/cluster/rs_lab/dbarton/env/lib/python3.8/multiprocessing/process.py", line 315, in _bootstrap
    self.run()
  File "/cluster/rs_lab/dbarton/env/lib/python3.8/multiprocessing/process.py", line 108, in run
    self._target(*self._args, **self._kwargs)
  File "run_pwl.py", line 157, in pwl_solve
    'solver_iter' : solver.get_iter_count()
AttributeError: 'Solver' object has no attribute 'get_iter_count'
Process Process-143:
Traceback (most recent call last):
  File "/cluster/rs_lab/dbarton/env/lib/python3.8/multiprocessing/process.py", line 315, in _bootstrap
    self.run()
  File "/cluster/rs_lab/dbarton/env/lib/python3.8/multiprocessing/process.py", line 108, in run
    self._target(*self._args, **self._kwargs)
  File "run_pwl.py", line 157, in pwl_solve
    'solver_iter' : solver.get_iter_count()
AttributeError: 'Solver' object has no attribute 'get_iter_count'
Process Process-113:
Traceback (most recent call last):
  File "/cluster/rs_lab/dbarton/env/lib/python3.8/multiprocessing/process.py", line 315, in _bootstrap
    self.run()
  File "/cluster/rs_lab/dbarton/env/lib/python3.8/multiprocessing/process.py", line 108, in run
    self._target(*self._args, **self._kwargs)
  File "run_pwl.py", line 157, in pwl_solve
    'solver_iter' : solver.get_iter_count()
AttributeError: 'Solver' object has no attribute 'get_iter_count'
/cluster/rs_lab/dbarton/usb_twitching/pili/support.py:52: RuntimeWarning: invalid value encountered in true_divide
  d_hat = np.divide(d_ba, d)
/cluster/rs_lab/dbarton/usb_twitching/pili/src/analysis/pwlpartition.py:102: RuntimeWarning: invalid value encountered in true_divide
  u = vector/length[:,np.newaxis]
Process Process-149:
Traceback (most recent call last):
  File "/cluster/rs_lab/dbarton/env/lib/python3.8/multiprocessing/process.py", line 315, in _bootstrap
    self.run()
  File "/cluster/rs_lab/dbarton/env/lib/python3.8/multiprocessing/process.py", line 108, in run
    self._target(*self._args, **self._kwargs)
  File "run_pwl.py", line 142, in pwl_solve
    solver.priority_solve(control, output=output)
  File "/cluster/rs_lab/dbarton/usb_twitching/pili/src/analysis/pwlpartition.py", line 823, in priority_solve
    accepted = self.destroy_at(index)
  File "/cluster/rs_lab/dbarton/usb_twitching/pili/src/analysis/pwlpartition.py", line 1036, in destroy_at
    clone.delete_at(index)
  File "/cluster/rs_lab/dbarton/usb_twitching/pili/src/analysis/pwlpartition.py", line 407, in delete_at
    self.update_residuals()
  File "/cluster/rs_lab/dbarton/usb_twitching/pili/src/analysis/pwlpartition.py", line 175, in update_residuals
    self.residual_at(0, self.model.M)
  File "/cluster/rs_lab/dbarton/usb_twitching/pili/src/analysis/pwlpartition.py", line 250, in residual_at
    residual = np.concatenate(distance_list)
  File "<__array_function__ internals>", line 5, in concatenate
ValueError: need at least one array to concatenate
Process Process-129:
Traceback (most recent call last):
  File "/cluster/rs_lab/dbarton/env/lib/python3.8/multiprocessing/process.py", line 315, in _bootstrap
    self.run()
  File "/cluster/rs_lab/dbarton/env/lib/python3.8/multiprocessing/process.py", line 108, in run
    self._target(*self._args, **self._kwargs)
  File "run_pwl.py", line 157, in pwl_solve
    'solver_iter' : solver.get_iter_count()
AttributeError: 'Solver' object has no attribute 'get_iter_count'
Process Process-189:
Traceback (most recent call last):
  File "/cluster/rs_lab/dbarton/env/lib/python3.8/multiprocessing/process.py", line 315, in _bootstrap
    self.run()
  File "/cluster/rs_lab/dbarton/env/lib/python3.8/multiprocessing/process.py", line 108, in run
    self._target(*self._args, **self._kwargs)
  File "run_pwl.py", line 157, in pwl_solve
    'solver_iter' : solver.get_iter_count()
AttributeError: 'Solver' object has no attribute 'get_iter_count'
Process Process-127:
Traceback (most recent call last):
  File "/cluster/rs_lab/dbarton/env/lib/python3.8/multiprocessing/process.py", line 315, in _bootstrap
    self.run()
  File "/cluster/rs_lab/dbarton/env/lib/python3.8/multiprocessing/process.py", line 108, in run
    self._target(*self._args, **self._kwargs)
  File "run_pwl.py", line 157, in pwl_solve
    'solver_iter' : solver.get_iter_count()
AttributeError: 'Solver' object has no attribute 'get_iter_count'
Process Process-195:
Traceback (most recent call last):
  File "/cluster/rs_lab/dbarton/env/lib/python3.8/multiprocessing/process.py", line 315, in _bootstrap
    self.run()
  File "/cluster/rs_lab/dbarton/env/lib/python3.8/multiprocessing/process.py", line 108, in run
    self._target(*self._args, **self._kwargs)
  File "run_pwl.py", line 157, in pwl_solve
    'solver_iter' : solver.get_iter_count()
AttributeError: 'Solver' object has no attribute 'get_iter_count'
Process Process-160:
Traceback (most recent call last):
  File "/cluster/rs_lab/dbarton/env/lib/python3.8/multiprocessing/process.py", line 315, in _bootstrap
    self.run()
  File "/cluster/rs_lab/dbarton/env/lib/python3.8/multiprocessing/process.py", line 108, in run
    self._target(*self._args, **self._kwargs)
  File "run_pwl.py", line 157, in pwl_solve
    'solver_iter' : solver.get_iter_count()
AttributeError: 'Solver' object has no attribute 'get_iter_count'
Process Process-103:
Traceback (most recent call last):
  File "/cluster/rs_lab/dbarton/env/lib/python3.8/multiprocessing/process.py", line 315, in _bootstrap
    self.run()
  File "/cluster/rs_lab/dbarton/env/lib/python3.8/multiprocessing/process.py", line 108, in run
    self._target(*self._args, **self._kwargs)
  File "run_pwl.py", line 157, in pwl_solve
    'solver_iter' : solver.get_iter_count()
AttributeError: 'Solver' object has no attribute 'get_iter_count'
Process Process-157:
Traceback (most recent call last):
  File "/cluster/rs_lab/dbarton/env/lib/python3.8/multiprocessing/process.py", line 315, in _bootstrap
    self.run()
  File "/cluster/rs_lab/dbarton/env/lib/python3.8/multiprocessing/process.py", line 108, in run
    self._target(*self._args, **self._kwargs)
  File "run_pwl.py", line 157, in pwl_solve
    'solver_iter' : solver.get_iter_count()
AttributeError: 'Solver' object has no attribute 'get_iter_count'
Process Process-126:
Traceback (most recent call last):
  File "/cluster/rs_lab/dbarton/env/lib/python3.8/multiprocessing/process.py", line 315, in _bootstrap
    self.run()
  File "/cluster/rs_lab/dbarton/env/lib/python3.8/multiprocessing/process.py", line 108, in run
    self._target(*self._args, **self._kwargs)
  File "run_pwl.py", line 157, in pwl_solve
    'solver_iter' : solver.get_iter_count()
AttributeError: 'Solver' object has no attribute 'get_iter_count'
/cluster/rs_lab/dbarton/usb_twitching/pili/src/analysis/mdl.py:193: RuntimeWarning: invalid value encountered in arccos
  theta = np.arccos(np.sum(norm_dx * norm_dy,axis=1))
Process Process-188:
Traceback (most recent call last):
  File "/cluster/rs_lab/dbarton/env/lib/python3.8/multiprocessing/process.py", line 315, in _bootstrap
    self.run()
  File "/cluster/rs_lab/dbarton/env/lib/python3.8/multiprocessing/process.py", line 108, in run
    self._target(*self._args, **self._kwargs)
  File "run_pwl.py", line 157, in pwl_solve
    'solver_iter' : solver.get_iter_count()
AttributeError: 'Solver' object has no attribute 'get_iter_count'
Process Process-161:
Traceback (most recent call last):
  File "/cluster/rs_lab/dbarton/env/lib/python3.8/multiprocessing/process.py", line 315, in _bootstrap
    self.run()
  File "/cluster/rs_lab/dbarton/env/lib/python3.8/multiprocessing/process.py", line 108, in run
    self._target(*self._args, **self._kwargs)
  File "run_pwl.py", line 157, in pwl_solve
    'solver_iter' : solver.get_iter_count()
AttributeError: 'Solver' object has no attribute 'get_iter_count'
Process Process-192:
Traceback (most recent call last):
  File "/cluster/rs_lab/dbarton/env/lib/python3.8/multiprocessing/process.py", line 315, in _bootstrap
    self.run()
  File "/cluster/rs_lab/dbarton/env/lib/python3.8/multiprocessing/process.py", line 108, in run
    self._target(*self._args, **self._kwargs)
  File "run_pwl.py", line 157, in pwl_solve
    'solver_iter' : solver.get_iter_count()
AttributeError: 'Solver' object has no attribute 'get_iter_count'
Process Process-170:
Traceback (most recent call last):
  File "/cluster/rs_lab/dbarton/env/lib/python3.8/multiprocessing/process.py", line 315, in _bootstrap
    self.run()
  File "/cluster/rs_lab/dbarton/env/lib/python3.8/multiprocessing/process.py", line 108, in run
    self._target(*self._args, **self._kwargs)
  File "run_pwl.py", line 157, in pwl_solve
    'solver_iter' : solver.get_iter_count()
AttributeError: 'Solver' object has no attribute 'get_iter_count'
Process Process-142:
Traceback (most recent call last):
  File "/cluster/rs_lab/dbarton/env/lib/python3.8/multiprocessing/process.py", line 315, in _bootstrap
    self.run()
  File "/cluster/rs_lab/dbarton/env/lib/python3.8/multiprocessing/process.py", line 108, in run
    self._target(*self._args, **self._kwargs)
  File "run_pwl.py", line 157, in pwl_solve
    'solver_iter' : solver.get_iter_count()
AttributeError: 'Solver' object has no attribute 'get_iter_count'
Process Process-180:
Traceback (most recent call last):
  File "/cluster/rs_lab/dbarton/env/lib/python3.8/multiprocessing/process.py", line 315, in _bootstrap
    self.run()
  File "/cluster/rs_lab/dbarton/env/lib/python3.8/multiprocessing/process.py", line 108, in run
    self._target(*self._args, **self._kwargs)
  File "run_pwl.py", line 157, in pwl_solve
    'solver_iter' : solver.get_iter_count()
AttributeError: 'Solver' object has no attribute 'get_iter_count'
Process Process-162:
Traceback (most recent call last):
  File "/cluster/rs_lab/dbarton/env/lib/python3.8/multiprocessing/process.py", line 315, in _bootstrap
    self.run()
  File "/cluster/rs_lab/dbarton/env/lib/python3.8/multiprocessing/process.py", line 108, in run
    self._target(*self._args, **self._kwargs)
  File "run_pwl.py", line 157, in pwl_solve
    'solver_iter' : solver.get_iter_count()
AttributeError: 'Solver' object has no attribute 'get_iter_count'
Process Process-115:
Traceback (most recent call last):
  File "/cluster/rs_lab/dbarton/env/lib/python3.8/multiprocessing/process.py", line 315, in _bootstrap
    self.run()
  File "/cluster/rs_lab/dbarton/env/lib/python3.8/multiprocessing/process.py", line 108, in run
    self._target(*self._args, **self._kwargs)
  File "run_pwl.py", line 157, in pwl_solve
    'solver_iter' : solver.get_iter_count()
AttributeError: 'Solver' object has no attribute 'get_iter_count'
Process Process-135:
Traceback (most recent call last):
  File "/cluster/rs_lab/dbarton/env/lib/python3.8/multiprocessing/process.py", line 315, in _bootstrap
    self.run()
  File "/cluster/rs_lab/dbarton/env/lib/python3.8/multiprocessing/process.py", line 108, in run
    self._target(*self._args, **self._kwargs)
  File "run_pwl.py", line 157, in pwl_solve
    'solver_iter' : solver.get_iter_count()
AttributeError: 'Solver' object has no attribute 'get_iter_count'
Process Process-190:
Traceback (most recent call last):
  File "/cluster/rs_lab/dbarton/env/lib/python3.8/multiprocessing/process.py", line 315, in _bootstrap
    self.run()
  File "/cluster/rs_lab/dbarton/env/lib/python3.8/multiprocessing/process.py", line 108, in run
    self._target(*self._args, **self._kwargs)
  File "run_pwl.py", line 157, in pwl_solve
    'solver_iter' : solver.get_iter_count()
AttributeError: 'Solver' object has no attribute 'get_iter_count'
Process Process-200:
Traceback (most recent call last):
  File "/cluster/rs_lab/dbarton/env/lib/python3.8/multiprocessing/process.py", line 315, in _bootstrap
    self.run()
  File "/cluster/rs_lab/dbarton/env/lib/python3.8/multiprocessing/process.py", line 108, in run
    self._target(*self._args, **self._kwargs)
  File "run_pwl.py", line 157, in pwl_solve
    'solver_iter' : solver.get_iter_count()
AttributeError: 'Solver' object has no attribute 'get_iter_count'
Process Process-165:
Traceback (most recent call last):
  File "/cluster/rs_lab/dbarton/env/lib/python3.8/multiprocessing/process.py", line 315, in _bootstrap
    self.run()
  File "/cluster/rs_lab/dbarton/env/lib/python3.8/multiprocessing/process.py", line 108, in run
    self._target(*self._args, **self._kwargs)
  File "run_pwl.py", line 157, in pwl_solve
    'solver_iter' : solver.get_iter_count()
AttributeError: 'Solver' object has no attribute 'get_iter_count'
/cluster/rs_lab/dbarton/usb_twitching/pili/support.py:52: RuntimeWarning: invalid value encountered in true_divide
  d_hat = np.divide(d_ba, d)
/cluster/rs_lab/dbarton/usb_twitching/pili/src/analysis/pwlpartition.py:102: RuntimeWarning: invalid value encountered in true_divide
  u = vector/length[:,np.newaxis]
Process Process-197:
Traceback (most recent call last):
  File "/cluster/rs_lab/dbarton/env/lib/python3.8/multiprocessing/process.py", line 315, in _bootstrap
    self.run()
  File "/cluster/rs_lab/dbarton/env/lib/python3.8/multiprocessing/process.py", line 108, in run
    self._target(*self._args, **self._kwargs)
  File "run_pwl.py", line 142, in pwl_solve
    solver.priority_solve(control, output=output)
  File "/cluster/rs_lab/dbarton/usb_twitching/pili/src/analysis/pwlpartition.py", line 823, in priority_solve
    accepted = self.destroy_at(index)
  File "/cluster/rs_lab/dbarton/usb_twitching/pili/src/analysis/pwlpartition.py", line 1036, in destroy_at
    clone.delete_at(index)
  File "/cluster/rs_lab/dbarton/usb_twitching/pili/src/analysis/pwlpartition.py", line 407, in delete_at
    self.update_residuals()
  File "/cluster/rs_lab/dbarton/usb_twitching/pili/src/analysis/pwlpartition.py", line 175, in update_residuals
    self.residual_at(0, self.model.M)
  File "/cluster/rs_lab/dbarton/usb_twitching/pili/src/analysis/pwlpartition.py", line 250, in residual_at
    residual = np.concatenate(distance_list)
  File "<__array_function__ internals>", line 5, in concatenate
ValueError: need at least one array to concatenate
/cluster/rs_lab/dbarton/usb_twitching/pili/support.py:52: RuntimeWarning: invalid value encountered in true_divide
  d_hat = np.divide(d_ba, d)
/cluster/rs_lab/dbarton/usb_twitching/pili/src/analysis/pwlpartition.py:102: RuntimeWarning: invalid value encountered in true_divide
  u = vector/length[:,np.newaxis]
Process Process-191:
Traceback (most recent call last):
  File "/cluster/rs_lab/dbarton/env/lib/python3.8/multiprocessing/process.py", line 315, in _bootstrap
    self.run()
  File "/cluster/rs_lab/dbarton/env/lib/python3.8/multiprocessing/process.py", line 108, in run
    self._target(*self._args, **self._kwargs)
  File "run_pwl.py", line 142, in pwl_solve
    solver.priority_solve(control, output=output)
  File "/cluster/rs_lab/dbarton/usb_twitching/pili/src/analysis/pwlpartition.py", line 823, in priority_solve
    accepted = self.destroy_at(index)
  File "/cluster/rs_lab/dbarton/usb_twitching/pili/src/analysis/pwlpartition.py", line 1036, in destroy_at
    clone.delete_at(index)
  File "/cluster/rs_lab/dbarton/usb_twitching/pili/src/analysis/pwlpartition.py", line 407, in delete_at
    self.update_residuals()
  File "/cluster/rs_lab/dbarton/usb_twitching/pili/src/analysis/pwlpartition.py", line 175, in update_residuals
    self.residual_at(0, self.model.M)
  File "/cluster/rs_lab/dbarton/usb_twitching/pili/src/analysis/pwlpartition.py", line 250, in residual_at
    residual = np.concatenate(distance_list)
  File "<__array_function__ internals>", line 5, in concatenate
ValueError: need at least one array to concatenate
/cluster/rs_lab/dbarton/usb_twitching/pili/support.py:52: RuntimeWarning: invalid value encountered in true_divide
  d_hat = np.divide(d_ba, d)
/cluster/rs_lab/dbarton/usb_twitching/pili/src/analysis/pwlpartition.py:102: RuntimeWarning: invalid value encountered in true_divide
  u = vector/length[:,np.newaxis]
Process Process-173:
Traceback (most recent call last):
  File "/cluster/rs_lab/dbarton/env/lib/python3.8/multiprocessing/process.py", line 315, in _bootstrap
    self.run()
  File "/cluster/rs_lab/dbarton/env/lib/python3.8/multiprocessing/process.py", line 108, in run
    self._target(*self._args, **self._kwargs)
  File "run_pwl.py", line 142, in pwl_solve
    solver.priority_solve(control, output=output)
  File "/cluster/rs_lab/dbarton/usb_twitching/pili/src/analysis/pwlpartition.py", line 823, in priority_solve
    accepted = self.destroy_at(index)
  File "/cluster/rs_lab/dbarton/usb_twitching/pili/src/analysis/pwlpartition.py", line 1036, in destroy_at
    clone.delete_at(index)
  File "/cluster/rs_lab/dbarton/usb_twitching/pili/src/analysis/pwlpartition.py", line 407, in delete_at
    self.update_residuals()
  File "/cluster/rs_lab/dbarton/usb_twitching/pili/src/analysis/pwlpartition.py", line 175, in update_residuals
    self.residual_at(0, self.model.M)
  File "/cluster/rs_lab/dbarton/usb_twitching/pili/src/analysis/pwlpartition.py", line 250, in residual_at
    residual = np.concatenate(distance_list)
  File "<__array_function__ internals>", line 5, in concatenate
ValueError: need at least one array to concatenate
/cluster/rs_lab/dbarton/usb_twitching/pili/support.py:52: RuntimeWarning: invalid value encountered in true_divide
  d_hat = np.divide(d_ba, d)
/cluster/rs_lab/dbarton/usb_twitching/pili/support.py:52: RuntimeWarning: invalid value encountered in true_divide
  d_hat = np.divide(d_ba, d)
Process Process-194:
Traceback (most recent call last):
  File "/cluster/rs_lab/dbarton/env/lib/python3.8/multiprocessing/process.py", line 315, in _bootstrap
    self.run()
  File "/cluster/rs_lab/dbarton/env/lib/python3.8/multiprocessing/process.py", line 108, in run
    self._target(*self._args, **self._kwargs)
  File "run_pwl.py", line 157, in pwl_solve
    'solver_iter' : solver.get_iter_count()
AttributeError: 'Solver' object has no attribute 'get_iter_count'
Process Process-178:
Traceback (most recent call last):
  File "/cluster/rs_lab/dbarton/env/lib/python3.8/multiprocessing/process.py", line 315, in _bootstrap
    self.run()
  File "/cluster/rs_lab/dbarton/env/lib/python3.8/multiprocessing/process.py", line 108, in run
    self._target(*self._args, **self._kwargs)
  File "run_pwl.py", line 157, in pwl_solve
    'solver_iter' : solver.get_iter_count()
AttributeError: 'Solver' object has no attribute 'get_iter_count'
Process Process-198:
Traceback (most recent call last):
  File "/cluster/rs_lab/dbarton/env/lib/python3.8/multiprocessing/process.py", line 315, in _bootstrap
    self.run()
  File "/cluster/rs_lab/dbarton/env/lib/python3.8/multiprocessing/process.py", line 108, in run
    self._target(*self._args, **self._kwargs)
  File "run_pwl.py", line 157, in pwl_solve
    'solver_iter' : solver.get_iter_count()
AttributeError: 'Solver' object has no attribute 'get_iter_count'
Process Process-186:
Traceback (most recent call last):
  File "/cluster/rs_lab/dbarton/env/lib/python3.8/multiprocessing/process.py", line 315, in _bootstrap
    self.run()
  File "/cluster/rs_lab/dbarton/env/lib/python3.8/multiprocessing/process.py", line 108, in run
    self._target(*self._args, **self._kwargs)
  File "run_pwl.py", line 157, in pwl_solve
    'solver_iter' : solver.get_iter_count()
AttributeError: 'Solver' object has no attribute 'get_iter_count'
/cluster/rs_lab/dbarton/usb_twitching/pili/support.py:52: RuntimeWarning: invalid value encountered in true_divide
  d_hat = np.divide(d_ba, d)
/cluster/rs_lab/dbarton/usb_twitching/pili/src/analysis/pwlpartition.py:102: RuntimeWarning: invalid value encountered in true_divide
  u = vector/length[:,np.newaxis]
Process Process-193:
Traceback (most recent call last):
  File "/cluster/rs_lab/dbarton/env/lib/python3.8/multiprocessing/process.py", line 315, in _bootstrap
    self.run()
  File "/cluster/rs_lab/dbarton/env/lib/python3.8/multiprocessing/process.py", line 108, in run
    self._target(*self._args, **self._kwargs)
  File "run_pwl.py", line 142, in pwl_solve
    solver.priority_solve(control, output=output)
  File "/cluster/rs_lab/dbarton/usb_twitching/pili/src/analysis/pwlpartition.py", line 823, in priority_solve
    accepted = self.destroy_at(index)
  File "/cluster/rs_lab/dbarton/usb_twitching/pili/src/analysis/pwlpartition.py", line 1036, in destroy_at
    clone.delete_at(index)
  File "/cluster/rs_lab/dbarton/usb_twitching/pili/src/analysis/pwlpartition.py", line 407, in delete_at
    self.update_residuals()
  File "/cluster/rs_lab/dbarton/usb_twitching/pili/src/analysis/pwlpartition.py", line 175, in update_residuals
    self.residual_at(0, self.model.M)
  File "/cluster/rs_lab/dbarton/usb_twitching/pili/src/analysis/pwlpartition.py", line 250, in residual_at
    residual = np.concatenate(distance_list)
  File "<__array_function__ internals>", line 5, in concatenate
ValueError: need at least one array to concatenate
Process Process-175:
Traceback (most recent call last):
  File "/cluster/rs_lab/dbarton/env/lib/python3.8/multiprocessing/process.py", line 315, in _bootstrap
    self.run()
  File "/cluster/rs_lab/dbarton/env/lib/python3.8/multiprocessing/process.py", line 108, in run
    self._target(*self._args, **self._kwargs)
  File "run_pwl.py", line 157, in pwl_solve
    'solver_iter' : solver.get_iter_count()
AttributeError: 'Solver' object has no attribute 'get_iter_count'
Process Process-199:
Traceback (most recent call last):
  File "/cluster/rs_lab/dbarton/env/lib/python3.8/multiprocessing/process.py", line 315, in _bootstrap
    self.run()
  File "/cluster/rs_lab/dbarton/env/lib/python3.8/multiprocessing/process.py", line 108, in run
    self._target(*self._args, **self._kwargs)
  File "run_pwl.py", line 157, in pwl_solve
    'solver_iter' : solver.get_iter_count()
AttributeError: 'Solver' object has no attribute 'get_iter_count'
Process Process-172:
Traceback (most recent call last):
  File "/cluster/rs_lab/dbarton/env/lib/python3.8/multiprocessing/process.py", line 315, in _bootstrap
    self.run()
  File "/cluster/rs_lab/dbarton/env/lib/python3.8/multiprocessing/process.py", line 108, in run
    self._target(*self._args, **self._kwargs)
  File "run_pwl.py", line 157, in pwl_solve
    'solver_iter' : solver.get_iter_count()
AttributeError: 'Solver' object has no attribute 'get_iter_count'
/cluster/rs_lab/dbarton/usb_twitching/pili/src/analysis/mdl.py:193: RuntimeWarning: invalid value encountered in arccos
  theta = np.arccos(np.sum(norm_dx * norm_dy,axis=1))
Process Process-185:
Traceback (most recent call last):
  File "/cluster/rs_lab/dbarton/env/lib/python3.8/multiprocessing/process.py", line 315, in _bootstrap
    self.run()
  File "/cluster/rs_lab/dbarton/env/lib/python3.8/multiprocessing/process.py", line 108, in run
    self._target(*self._args, **self._kwargs)
  File "run_pwl.py", line 157, in pwl_solve
    'solver_iter' : solver.get_iter_count()
AttributeError: 'Solver' object has no attribute 'get_iter_count'
/cluster/rs_lab/dbarton/usb_twitching/pili/src/analysis/mdl.py:193: RuntimeWarning: invalid value encountered in arccos
  theta = np.arccos(np.sum(norm_dx * norm_dy,axis=1))
Process Process-196:
Traceback (most recent call last):
  File "/cluster/rs_lab/dbarton/env/lib/python3.8/multiprocessing/process.py", line 315, in _bootstrap
    self.run()
  File "/cluster/rs_lab/dbarton/env/lib/python3.8/multiprocessing/process.py", line 108, in run
    self._target(*self._args, **self._kwargs)
  File "run_pwl.py", line 157, in pwl_solve
    'solver_iter' : solver.get_iter_count()
AttributeError: 'Solver' object has no attribute 'get_iter_count'
/cluster/rs_lab/dbarton/usb_twitching/pili/src/analysis/mdl.py:193: RuntimeWarning: invalid value encountered in arccos
  theta = np.arccos(np.sum(norm_dx * norm_dy,axis=1))
Process Process-184:
Traceback (most recent call last):
  File "/cluster/rs_lab/dbarton/env/lib/python3.8/multiprocessing/process.py", line 315, in _bootstrap
    self.run()
  File "/cluster/rs_lab/dbarton/env/lib/python3.8/multiprocessing/process.py", line 108, in run
    self._target(*self._args, **self._kwargs)
  File "run_pwl.py", line 157, in pwl_solve
    'solver_iter' : solver.get_iter_count()
AttributeError: 'Solver' object has no attribute 'get_iter_count'
Process Process-179:
Traceback (most recent call last):
  File "/cluster/rs_lab/dbarton/env/lib/python3.8/multiprocessing/process.py", line 315, in _bootstrap
    self.run()
  File "/cluster/rs_lab/dbarton/env/lib/python3.8/multiprocessing/process.py", line 108, in run
    self._target(*self._args, **self._kwargs)
  File "run_pwl.py", line 157, in pwl_solve
    'solver_iter' : solver.get_iter_count()
AttributeError: 'Solver' object has no attribute 'get_iter_count'
Process Process-187:
Traceback (most recent call last):
  File "/cluster/rs_lab/dbarton/env/lib/python3.8/multiprocessing/process.py", line 315, in _bootstrap
    self.run()
  File "/cluster/rs_lab/dbarton/env/lib/python3.8/multiprocessing/process.py", line 108, in run
    self._target(*self._args, **self._kwargs)
  File "run_pwl.py", line 157, in pwl_solve
    'solver_iter' : solver.get_iter_count()
AttributeError: 'Solver' object has no attribute 'get_iter_count'
Process Process-177:
Traceback (most recent call last):
  File "/cluster/rs_lab/dbarton/env/lib/python3.8/multiprocessing/process.py", line 315, in _bootstrap
    self.run()
  File "/cluster/rs_lab/dbarton/env/lib/python3.8/multiprocessing/process.py", line 108, in run
    self._target(*self._args, **self._kwargs)
  File "run_pwl.py", line 157, in pwl_solve
    'solver_iter' : solver.get_iter_count()
AttributeError: 'Solver' object has no attribute 'get_iter_count'
