  0%|          | 0/1 [00:00<?, ?it/s]  0%|          | 0/1 [00:00<?, ?it/s]  0%|          | 0/1 [00:00<?, ?it/s]  0%|          | 0/1 [00:00<?, ?it/s]  0%|          | 0/1 [00:00<?, ?it/s]  0%|          | 0/1 [00:00<?, ?it/s]100%|██████████| 1/1 [00:00<00:00, 106.95it/s]100%|██████████| 1/1 [00:00<00:00, 94.66it/s]100%|██████████| 1/1 [00:00<00:00, 80.17it/s]  0%|          | 0/1 [00:00<?, ?it/s]100%|██████████| 1/1 [00:00<00:00, 64.47it/s]100%|██████████| 1/1 [00:00<00:00, 77.98it/s]100%|██████████| 1/1 [00:00<00:00, 114.39it/s]100%|██████████| 1/1 [00:00<00:00, 134.38it/s]  0%|          | 0/1 [00:00<?, ?it/s]100%|██████████| 1/1 [00:00<00:00, 112.44it/s]  0%|          | 0/1 [00:00<?, ?it/s]  0%|          | 0/1 [00:00<?, ?it/s]100%|██████████| 1/1 [00:00<00:00, 245.97it/s]100%|██████████| 1/1 [00:00<00:00, 140.69it/s]  0%|          | 0/1 [00:00<?, ?it/s]  0%|          | 0/1 [00:00<?, ?it/s]  0%|          | 0/1 [00:00<?, ?it/s]  0%|          | 0/1 [00:00<?, ?it/s]  0%|          | 0/1 [00:00<?, ?it/s]  0%|          | 0/1 [00:00<?, ?it/s]  0%|          | 0/1 [00:00<?, ?it/s]  0%|          | 0/1 [00:00<?, ?it/s]100%|██████████| 1/1 [00:00<00:00, 183.45it/s]100%|██████████| 1/1 [00:00<00:00, 162.66it/s]100%|██████████| 1/1 [00:00<00:00, 134.12it/s]  0%|          | 0/1 [00:00<?, ?it/s]  0%|          | 0/1 [00:00<?, ?it/s]100%|██████████| 1/1 [00:00<00:00, 106.79it/s]  0%|          | 0/1 [00:00<?, ?it/s]100%|██████████| 1/1 [00:00<00:00, 99.11it/s]  0%|          | 0/1 [00:00<?, ?it/s]100%|██████████| 1/1 [00:00<00:00, 98.71it/s]100%|██████████| 1/1 [00:00<00:00, 71.43it/s]100%|██████████| 1/1 [00:00<00:00, 86.50it/s]100%|██████████| 1/1 [00:00<00:00, 101.62it/s]  0%|          | 0/1 [00:00<?, ?it/s]100%|██████████| 1/1 [00:00<00:00, 89.73it/s]100%|██████████| 1/1 [00:00<00:00, 79.55it/s]100%|██████████| 1/1 [00:00<00:00, 82.11it/s]100%|██████████| 1/1 [00:00<00:00, 216.22it/s]  0%|          | 0/1 [00:00<?, ?it/s]100%|██████████| 1/1 [00:00<00:00, 166.71it/s]  0%|          | 0/1 [00:00<?, ?it/s]  0%|          | 0/1 [00:00<?, ?it/s]  0%|          | 0/1 [00:00<?, ?it/s]  0%|          | 0/1 [00:00<?, ?it/s]100%|██████████| 1/1 [00:00<00:00, 169.80it/s]100%|██████████| 1/1 [00:00<00:00, 126.11it/s]100%|██████████| 1/1 [00:00<00:00, 121.46it/s]100%|██████████| 1/1 [00:00<00:00, 110.33it/s]  0%|          | 0/1 [00:00<?, ?it/s]  0%|          | 0/1 [00:00<?, ?it/s]  0%|          | 0/1 [00:00<?, ?it/s]  0%|          | 0/1 [00:00<?, ?it/s]  0%|          | 0/1 [00:00<?, ?it/s]  0%|          | 0/1 [00:00<?, ?it/s]  0%|          | 0/1 [00:00<?, ?it/s]  0%|          | 0/1 [00:00<?, ?it/s]  0%|          | 0/1 [00:00<?, ?it/s]  0%|          | 0/1 [00:00<?, ?it/s]  0%|          | 0/1 [00:00<?, ?it/s]100%|██████████| 1/1 [00:00<00:00, 193.85it/s]  0%|          | 0/1 [00:00<?, ?it/s]  0%|          | 0/1 [00:00<?, ?it/s]  0%|          | 0/1 [00:00<?, ?it/s]  0%|          | 0/1 [00:00<?, ?it/s]100%|██████████| 1/1 [00:00<00:00, 175.03it/s]100%|██████████| 1/1 [00:00<00:00, 120.08it/s]100%|██████████| 1/1 [00:00<00:00, 102.22it/s]100%|██████████| 1/1 [00:00<00:00, 89.25it/s]100%|██████████| 1/1 [00:00<00:00, 83.66it/s]100%|██████████| 1/1 [00:00<00:00, 75.37it/s]100%|██████████| 1/1 [00:00<00:00, 66.72it/s]100%|██████████| 1/1 [00:00<00:00, 69.70it/s]100%|██████████| 1/1 [00:00<00:00, 68.65it/s]100%|██████████| 1/1 [00:00<00:00, 58.70it/s]100%|██████████| 1/1 [00:00<00:00, 60.15it/s]100%|██████████| 1/1 [00:00<00:00, 59.03it/s]100%|██████████| 1/1 [00:00<00:00, 56.88it/s]100%|██████████| 1/1 [00:00<00:00, 52.48it/s]  0%|          | 0/1 [00:00<?, ?it/s]100%|██████████| 1/1 [00:00<00:00, 173.35it/s]  0%|          | 0/1 [00:00<?, ?it/s]  0%|          | 0/1 [00:00<?, ?it/s]100%|██████████| 1/1 [00:00<00:00, 209.25it/s]  0%|          | 0/1 [00:00<?, ?it/s]100%|██████████| 1/1 [00:00<00:00, 156.07it/s]100%|██████████| 1/1 [00:00<00:00, 209.84it/s]  0%|          | 0/1 [00:00<?, ?it/s]  0%|          | 0/1 [00:00<?, ?it/s]100%|██████████| 1/1 [00:00<00:00, 184.65it/s]100%|██████████| 1/1 [00:00<00:00, 155.75it/s]  0%|          | 0/1 [00:00<?, ?it/s]  0%|          | 0/1 [00:00<?, ?it/s]  0%|          | 0/1 [00:00<?, ?it/s]100%|██████████| 1/1 [00:00<00:00, 148.80it/s]100%|██████████| 1/1 [00:00<00:00, 137.82it/s]100%|██████████| 1/1 [00:00<00:00, 173.11it/s]  0%|          | 0/1 [00:00<?, ?it/s]  0%|          | 0/1 [00:00<?, ?it/s]100%|██████████| 1/1 [00:00<00:00, 140.45it/s]100%|██████████| 1/1 [00:00<00:00, 187.05it/s]  0%|          | 0/1 [00:00<?, ?it/s]100%|██████████| 1/1 [00:00<00:00, 120.77it/s]  0%|          | 0/1 [00:00<?, ?it/s]100%|██████████| 1/1 [00:00<00:00, 206.48it/s]  0%|          | 0/1 [00:00<?, ?it/s]  0%|          | 0/1 [00:00<?, ?it/s]100%|██████████| 1/1 [00:00<00:00, 144.82it/s]100%|██████████| 1/1 [00:00<00:00, 162.90it/s]  0%|          | 0/1 [00:00<?, ?it/s]  0%|          | 0/1 [00:00<?, ?it/s]100%|██████████| 1/1 [00:00<00:00, 143.26it/s]100%|██████████| 1/1 [00:00<00:00, 201.45it/s]  0%|          | 0/1 [00:00<?, ?it/s]  0%|          | 0/1 [00:00<?, ?it/s]100%|██████████| 1/1 [00:00<00:00, 175.27it/s]100%|██████████| 1/1 [00:00<00:00, 187.36it/s]  0%|          | 0/1 [00:00<?, ?it/s]  0%|          | 0/1 [00:00<?, ?it/s]100%|██████████| 1/1 [00:00<00:00, 192.89it/s]100%|██████████| 1/1 [00:00<00:00, 174.14it/s]
  0%|          | 0/1 [00:00<?, ?it/s]100%|██████████| 1/1 [00:00<00:00, 48.29it/s]
  0%|          | 0/1 [00:00<?, ?it/s]100%|██████████| 1/1 [00:00<00:00, 53.72it/s]
  0%|          | 0/1 [00:00<?, ?it/s]100%|██████████| 1/1 [00:00<00:00, 24.02it/s]
  0%|          | 0/1 [00:00<?, ?it/s]100%|██████████| 1/1 [00:00<00:00, 20.83it/s]
  0%|          | 0/1 [00:00<?, ?it/s]100%|██████████| 1/1 [00:00<00:00, 22.24it/s]
  0%|          | 0/1 [00:00<?, ?it/s]100%|██████████| 1/1 [00:00<00:00, 22.66it/s]
Process Process-10:
Traceback (most recent call last):
  File "/homes/dbarton/miniconda3/lib/python3.8/multiprocessing/process.py", line 315, in _bootstrap
    self.run()
  File "/homes/dbarton/miniconda3/lib/python3.8/multiprocessing/process.py", line 108, in run
    self._target(*self._args, **self._kwargs)
  File "run_pwl.py", line 125, in pwl_solve
    solver = annealing.solve_exp(lptr, M, r, default_loss_conf=loss_conf)
  File "/cluster/rs_lab/dbarton/usb_twitching/pili/src/analysis/annealing.py", line 1751, in solve_exp
    solver.remapping()
  File "/cluster/rs_lab/dbarton/usb_twitching/pili/src/analysis/annealing.py", line 1656, in remapping
    queue.append((bysegment[sidx][0], lptr.sidx[i-1]))
IndexError: list index out of range
  0%|          | 0/1 [00:00<?, ?it/s]100%|██████████| 1/1 [00:00<00:00, 65.19it/s]
  0%|          | 0/1 [00:00<?, ?it/s]100%|██████████| 1/1 [00:00<00:00, 20.08it/s]
Process Process-33:
Traceback (most recent call last):
  File "/homes/dbarton/miniconda3/lib/python3.8/multiprocessing/process.py", line 315, in _bootstrap
    self.run()
  File "/homes/dbarton/miniconda3/lib/python3.8/multiprocessing/process.py", line 108, in run
    self._target(*self._args, **self._kwargs)
  File "run_pwl.py", line 125, in pwl_solve
    solver = annealing.solve_exp(lptr, M, r, default_loss_conf=loss_conf)
  File "/cluster/rs_lab/dbarton/usb_twitching/pili/src/analysis/annealing.py", line 1751, in solve_exp
    solver.remapping()
  File "/cluster/rs_lab/dbarton/usb_twitching/pili/src/analysis/annealing.py", line 1656, in remapping
    queue.append((bysegment[sidx][0], lptr.sidx[i-1]))
IndexError: list index out of range
  0%|          | 0/1 [00:00<?, ?it/s]100%|██████████| 1/1 [00:00<00:00, 36.00it/s]
  0%|          | 0/1 [00:00<?, ?it/s]100%|██████████| 1/1 [00:00<00:00, 39.84it/s]
  0%|          | 0/1 [00:00<?, ?it/s]100%|██████████| 1/1 [00:00<00:00, 24.65it/s]
/cluster/rs_lab/dbarton/usb_twitching/pili/src/analysis/annealing.py:1359: RuntimeWarning: overflow encountered in exp
  s = np.exp(-(score_prime - score)/T)
  0%|          | 0/1 [00:00<?, ?it/s]100%|██████████| 1/1 [00:00<00:00, 19.90it/s]
Process Process-15:
Traceback (most recent call last):
  File "/homes/dbarton/miniconda3/lib/python3.8/multiprocessing/process.py", line 315, in _bootstrap
    self.run()
  File "/homes/dbarton/miniconda3/lib/python3.8/multiprocessing/process.py", line 108, in run
    self._target(*self._args, **self._kwargs)
  File "run_pwl.py", line 125, in pwl_solve
    solver = annealing.solve_exp(lptr, M, r, default_loss_conf=loss_conf)
  File "/cluster/rs_lab/dbarton/usb_twitching/pili/src/analysis/annealing.py", line 1751, in solve_exp
    solver.remapping()
  File "/cluster/rs_lab/dbarton/usb_twitching/pili/src/analysis/annealing.py", line 1656, in remapping
    queue.append((bysegment[sidx][0], lptr.sidx[i-1]))
IndexError: list index out of range
  0%|          | 0/1 [00:00<?, ?it/s]100%|██████████| 1/1 [00:00<00:00, 29.32it/s]
Process Process-40:
Traceback (most recent call last):
  File "/homes/dbarton/miniconda3/lib/python3.8/multiprocessing/process.py", line 315, in _bootstrap
    self.run()
  File "/homes/dbarton/miniconda3/lib/python3.8/multiprocessing/process.py", line 108, in run
    self._target(*self._args, **self._kwargs)
  File "run_pwl.py", line 125, in pwl_solve
    solver = annealing.solve_exp(lptr, M, r, default_loss_conf=loss_conf)
  File "/cluster/rs_lab/dbarton/usb_twitching/pili/src/analysis/annealing.py", line 1751, in solve_exp
    solver.remapping()
  File "/cluster/rs_lab/dbarton/usb_twitching/pili/src/analysis/annealing.py", line 1656, in remapping
    queue.append((bysegment[sidx][0], lptr.sidx[i-1]))
IndexError: list index out of range
  0%|          | 0/1 [00:00<?, ?it/s]100%|██████████| 1/1 [00:00<00:00, 32.50it/s]
/cluster/rs_lab/dbarton/usb_twitching/pili/support.py:52: RuntimeWarning: invalid value encountered in true_divide
  d_hat = np.divide(d_ba, d)
  0%|          | 0/1 [00:00<?, ?it/s]100%|██████████| 1/1 [00:00<00:00, 72.46it/s]
  0%|          | 0/1 [00:00<?, ?it/s]100%|██████████| 1/1 [00:00<00:00, 31.29it/s]
  0%|          | 0/1 [00:00<?, ?it/s]100%|██████████| 1/1 [00:00<00:00, 23.88it/s]
/cluster/rs_lab/dbarton/usb_twitching/pili/support.py:52: RuntimeWarning: invalid value encountered in true_divide
  d_hat = np.divide(d_ba, d)
Process Process-51:
Traceback (most recent call last):
  File "/homes/dbarton/miniconda3/lib/python3.8/multiprocessing/process.py", line 315, in _bootstrap
    self.run()
  File "/homes/dbarton/miniconda3/lib/python3.8/multiprocessing/process.py", line 108, in run
    self._target(*self._args, **self._kwargs)
  File "run_pwl.py", line 125, in pwl_solve
    solver = annealing.solve_exp(lptr, M, r, default_loss_conf=loss_conf)
  File "/cluster/rs_lab/dbarton/usb_twitching/pili/src/analysis/annealing.py", line 1751, in solve_exp
    solver.remapping()
  File "/cluster/rs_lab/dbarton/usb_twitching/pili/src/analysis/annealing.py", line 1656, in remapping
    queue.append((bysegment[sidx][0], lptr.sidx[i-1]))
IndexError: list index out of range
  0%|          | 0/1 [00:00<?, ?it/s]100%|██████████| 1/1 [00:00<00:00, 33.79it/s]
/cluster/rs_lab/dbarton/usb_twitching/pili/support.py:52: RuntimeWarning: invalid value encountered in true_divide
  d_hat = np.divide(d_ba, d)
  0%|          | 0/1 [00:00<?, ?it/s]100%|██████████| 1/1 [00:00<00:00, 25.85it/s]
/cluster/rs_lab/dbarton/usb_twitching/pili/support.py:52: RuntimeWarning: invalid value encountered in true_divide
  d_hat = np.divide(d_ba, d)
Process Process-5:
Traceback (most recent call last):
  File "/homes/dbarton/miniconda3/lib/python3.8/multiprocessing/process.py", line 315, in _bootstrap
    self.run()
  File "/homes/dbarton/miniconda3/lib/python3.8/multiprocessing/process.py", line 108, in run
    self._target(*self._args, **self._kwargs)
  File "run_pwl.py", line 125, in pwl_solve
    solver = annealing.solve_exp(lptr, M, r, default_loss_conf=loss_conf)
  File "/cluster/rs_lab/dbarton/usb_twitching/pili/src/analysis/annealing.py", line 1751, in solve_exp
    solver.remapping()
  File "/cluster/rs_lab/dbarton/usb_twitching/pili/src/analysis/annealing.py", line 1656, in remapping
    queue.append((bysegment[sidx][0], lptr.sidx[i-1]))
IndexError: list index out of range
  0%|          | 0/1 [00:00<?, ?it/s]100%|██████████| 1/1 [00:00<00:00, 31.32it/s]
/cluster/rs_lab/dbarton/usb_twitching/pili/support.py:52: RuntimeWarning: invalid value encountered in true_divide
  d_hat = np.divide(d_ba, d)
Process Process-67:
Traceback (most recent call last):
  File "/homes/dbarton/miniconda3/lib/python3.8/multiprocessing/process.py", line 315, in _bootstrap
    self.run()
  File "/homes/dbarton/miniconda3/lib/python3.8/multiprocessing/process.py", line 108, in run
    self._target(*self._args, **self._kwargs)
  File "run_pwl.py", line 125, in pwl_solve
    solver = annealing.solve_exp(lptr, M, r, default_loss_conf=loss_conf)
  File "/cluster/rs_lab/dbarton/usb_twitching/pili/src/analysis/annealing.py", line 1751, in solve_exp
    solver.remapping()
  File "/cluster/rs_lab/dbarton/usb_twitching/pili/src/analysis/annealing.py", line 1656, in remapping
    queue.append((bysegment[sidx][0], lptr.sidx[i-1]))
IndexError: list index out of range
  0%|          | 0/1 [00:00<?, ?it/s]100%|██████████| 1/1 [00:00<00:00, 29.15it/s]
Process Process-63:
Traceback (most recent call last):
  File "/homes/dbarton/miniconda3/lib/python3.8/multiprocessing/process.py", line 315, in _bootstrap
    self.run()
  File "/homes/dbarton/miniconda3/lib/python3.8/multiprocessing/process.py", line 108, in run
    self._target(*self._args, **self._kwargs)
  File "run_pwl.py", line 125, in pwl_solve
    solver = annealing.solve_exp(lptr, M, r, default_loss_conf=loss_conf)
  File "/cluster/rs_lab/dbarton/usb_twitching/pili/src/analysis/annealing.py", line 1751, in solve_exp
    solver.remapping()
  File "/cluster/rs_lab/dbarton/usb_twitching/pili/src/analysis/annealing.py", line 1656, in remapping
    queue.append((bysegment[sidx][0], lptr.sidx[i-1]))
IndexError: list index out of range
  0%|          | 0/1 [00:00<?, ?it/s]100%|██████████| 1/1 [00:00<00:00, 16.90it/s]
Process Process-18:
Traceback (most recent call last):
  File "/homes/dbarton/miniconda3/lib/python3.8/multiprocessing/process.py", line 315, in _bootstrap
    self.run()
  File "/homes/dbarton/miniconda3/lib/python3.8/multiprocessing/process.py", line 108, in run
    self._target(*self._args, **self._kwargs)
  File "run_pwl.py", line 125, in pwl_solve
    solver = annealing.solve_exp(lptr, M, r, default_loss_conf=loss_conf)
  File "/cluster/rs_lab/dbarton/usb_twitching/pili/src/analysis/annealing.py", line 1751, in solve_exp
    solver.remapping()
  File "/cluster/rs_lab/dbarton/usb_twitching/pili/src/analysis/annealing.py", line 1656, in remapping
    queue.append((bysegment[sidx][0], lptr.sidx[i-1]))
IndexError: list index out of range
  0%|          | 0/1 [00:00<?, ?it/s]100%|██████████| 1/1 [00:00<00:00, 37.94it/s]
/cluster/rs_lab/dbarton/usb_twitching/pili/support.py:52: RuntimeWarning: invalid value encountered in true_divide
  d_hat = np.divide(d_ba, d)
/cluster/rs_lab/dbarton/usb_twitching/pili/src/analysis/annealing.py:1359: RuntimeWarning: overflow encountered in exp
  s = np.exp(-(score_prime - score)/T)
Process Process-19:
Traceback (most recent call last):
  File "/homes/dbarton/miniconda3/lib/python3.8/multiprocessing/process.py", line 315, in _bootstrap
    self.run()
  File "/homes/dbarton/miniconda3/lib/python3.8/multiprocessing/process.py", line 108, in run
    self._target(*self._args, **self._kwargs)
  File "run_pwl.py", line 125, in pwl_solve
    solver = annealing.solve_exp(lptr, M, r, default_loss_conf=loss_conf)
  File "/cluster/rs_lab/dbarton/usb_twitching/pili/src/analysis/annealing.py", line 1751, in solve_exp
    solver.remapping()
  File "/cluster/rs_lab/dbarton/usb_twitching/pili/src/analysis/annealing.py", line 1656, in remapping
    queue.append((bysegment[sidx][0], lptr.sidx[i-1]))
IndexError: list index out of range
  0%|          | 0/1 [00:00<?, ?it/s]100%|██████████| 1/1 [00:00<00:00, 58.12it/s]
  0%|          | 0/1 [00:00<?, ?it/s]100%|██████████| 1/1 [00:00<00:00, 33.30it/s]
  0%|          | 0/1 [00:00<?, ?it/s]100%|██████████| 1/1 [00:00<00:00, 23.00it/s]
  0%|          | 0/1 [00:00<?, ?it/s]100%|██████████| 1/1 [00:00<00:00, 20.31it/s]
Process Process-74:
Traceback (most recent call last):
  File "/homes/dbarton/miniconda3/lib/python3.8/multiprocessing/process.py", line 315, in _bootstrap
    self.run()
  File "/homes/dbarton/miniconda3/lib/python3.8/multiprocessing/process.py", line 108, in run
    self._target(*self._args, **self._kwargs)
  File "run_pwl.py", line 125, in pwl_solve
    solver = annealing.solve_exp(lptr, M, r, default_loss_conf=loss_conf)
  File "/cluster/rs_lab/dbarton/usb_twitching/pili/src/analysis/annealing.py", line 1751, in solve_exp
    solver.remapping()
  File "/cluster/rs_lab/dbarton/usb_twitching/pili/src/analysis/annealing.py", line 1656, in remapping
    queue.append((bysegment[sidx][0], lptr.sidx[i-1]))
IndexError: list index out of range
  0%|          | 0/1 [00:00<?, ?it/s]100%|██████████| 1/1 [00:00<00:00, 26.56it/s]
Process Process-53:
Traceback (most recent call last):
  File "/homes/dbarton/miniconda3/lib/python3.8/multiprocessing/process.py", line 315, in _bootstrap
    self.run()
  File "/homes/dbarton/miniconda3/lib/python3.8/multiprocessing/process.py", line 108, in run
    self._target(*self._args, **self._kwargs)
  File "run_pwl.py", line 125, in pwl_solve
    solver = annealing.solve_exp(lptr, M, r, default_loss_conf=loss_conf)
  File "/cluster/rs_lab/dbarton/usb_twitching/pili/src/analysis/annealing.py", line 1751, in solve_exp
    solver.remapping()
  File "/cluster/rs_lab/dbarton/usb_twitching/pili/src/analysis/annealing.py", line 1656, in remapping
    queue.append((bysegment[sidx][0], lptr.sidx[i-1]))
IndexError: list index out of range
  0%|          | 0/1 [00:00<?, ?it/s]100%|██████████| 1/1 [00:00<00:00, 41.83it/s]
  0%|          | 0/1 [00:00<?, ?it/s]100%|██████████| 1/1 [00:00<00:00, 37.84it/s]
Process Process-71:
Traceback (most recent call last):
  File "/homes/dbarton/miniconda3/lib/python3.8/multiprocessing/process.py", line 315, in _bootstrap
    self.run()
  File "/homes/dbarton/miniconda3/lib/python3.8/multiprocessing/process.py", line 108, in run
    self._target(*self._args, **self._kwargs)
  File "run_pwl.py", line 125, in pwl_solve
    solver = annealing.solve_exp(lptr, M, r, default_loss_conf=loss_conf)
  File "/cluster/rs_lab/dbarton/usb_twitching/pili/src/analysis/annealing.py", line 1751, in solve_exp
    solver.remapping()
  File "/cluster/rs_lab/dbarton/usb_twitching/pili/src/analysis/annealing.py", line 1656, in remapping
    queue.append((bysegment[sidx][0], lptr.sidx[i-1]))
IndexError: list index out of range
  0%|          | 0/1 [00:00<?, ?it/s]100%|██████████| 1/1 [00:00<00:00, 65.18it/s]
  0%|          | 0/1 [00:00<?, ?it/s]100%|██████████| 1/1 [00:00<00:00, 34.10it/s]
Process Process-27:
Traceback (most recent call last):
  File "/homes/dbarton/miniconda3/lib/python3.8/multiprocessing/process.py", line 315, in _bootstrap
    self.run()
  File "/homes/dbarton/miniconda3/lib/python3.8/multiprocessing/process.py", line 108, in run
    self._target(*self._args, **self._kwargs)
  File "run_pwl.py", line 125, in pwl_solve
    solver = annealing.solve_exp(lptr, M, r, default_loss_conf=loss_conf)
  File "/cluster/rs_lab/dbarton/usb_twitching/pili/src/analysis/annealing.py", line 1751, in solve_exp
    solver.remapping()
  File "/cluster/rs_lab/dbarton/usb_twitching/pili/src/analysis/annealing.py", line 1656, in remapping
    queue.append((bysegment[sidx][0], lptr.sidx[i-1]))
IndexError: list index out of range
  0%|          | 0/1 [00:00<?, ?it/s]100%|██████████| 1/1 [00:00<00:00, 20.54it/s]
  0%|          | 0/1 [00:00<?, ?it/s]100%|██████████| 1/1 [00:00<00:00, 31.52it/s]
  0%|          | 0/1 [00:00<?, ?it/s]100%|██████████| 1/1 [00:00<00:00, 19.95it/s]
Process Process-9:
Traceback (most recent call last):
  File "/homes/dbarton/miniconda3/lib/python3.8/multiprocessing/process.py", line 315, in _bootstrap
    self.run()
  File "/homes/dbarton/miniconda3/lib/python3.8/multiprocessing/process.py", line 108, in run
    self._target(*self._args, **self._kwargs)
  File "run_pwl.py", line 125, in pwl_solve
    solver = annealing.solve_exp(lptr, M, r, default_loss_conf=loss_conf)
  File "/cluster/rs_lab/dbarton/usb_twitching/pili/src/analysis/annealing.py", line 1751, in solve_exp
    solver.remapping()
  File "/cluster/rs_lab/dbarton/usb_twitching/pili/src/analysis/annealing.py", line 1656, in remapping
    queue.append((bysegment[sidx][0], lptr.sidx[i-1]))
IndexError: list index out of range
  0%|          | 0/1 [00:00<?, ?it/s]100%|██████████| 1/1 [00:00<00:00, 21.97it/s]
  0%|          | 0/1 [00:00<?, ?it/s]100%|██████████| 1/1 [00:00<00:00, 19.67it/s]
Process Process-80:
Traceback (most recent call last):
  File "/homes/dbarton/miniconda3/lib/python3.8/multiprocessing/process.py", line 315, in _bootstrap
    self.run()
  File "/homes/dbarton/miniconda3/lib/python3.8/multiprocessing/process.py", line 108, in run
    self._target(*self._args, **self._kwargs)
  File "run_pwl.py", line 125, in pwl_solve
    solver = annealing.solve_exp(lptr, M, r, default_loss_conf=loss_conf)
  File "/cluster/rs_lab/dbarton/usb_twitching/pili/src/analysis/annealing.py", line 1751, in solve_exp
    solver.remapping()
  File "/cluster/rs_lab/dbarton/usb_twitching/pili/src/analysis/annealing.py", line 1656, in remapping
    queue.append((bysegment[sidx][0], lptr.sidx[i-1]))
IndexError: list index out of range
  0%|          | 0/1 [00:00<?, ?it/s]100%|██████████| 1/1 [00:00<00:00, 40.33it/s]
  0%|          | 0/1 [00:00<?, ?it/s]100%|██████████| 1/1 [00:00<00:00, 28.15it/s]
  0%|          | 0/1 [00:00<?, ?it/s]100%|██████████| 1/1 [00:00<00:00, 20.47it/s]
Process Process-20:
Traceback (most recent call last):
  File "/homes/dbarton/miniconda3/lib/python3.8/multiprocessing/process.py", line 315, in _bootstrap
    self.run()
  File "/homes/dbarton/miniconda3/lib/python3.8/multiprocessing/process.py", line 108, in run
    self._target(*self._args, **self._kwargs)
  File "run_pwl.py", line 125, in pwl_solve
    solver = annealing.solve_exp(lptr, M, r, default_loss_conf=loss_conf)
  File "/cluster/rs_lab/dbarton/usb_twitching/pili/src/analysis/annealing.py", line 1751, in solve_exp
    solver.remapping()
  File "/cluster/rs_lab/dbarton/usb_twitching/pili/src/analysis/annealing.py", line 1656, in remapping
    queue.append((bysegment[sidx][0], lptr.sidx[i-1]))
IndexError: list index out of range
  0%|          | 0/1 [00:00<?, ?it/s]100%|██████████| 1/1 [00:00<00:00, 25.71it/s]
/cluster/rs_lab/dbarton/usb_twitching/pili/support.py:52: RuntimeWarning: invalid value encountered in true_divide
  d_hat = np.divide(d_ba, d)
  0%|          | 0/1 [00:00<?, ?it/s]100%|██████████| 1/1 [00:00<00:00, 70.17it/s]
  0%|          | 0/1 [00:00<?, ?it/s]100%|██████████| 1/1 [00:00<00:00, 20.03it/s]
  0%|          | 0/1 [00:00<?, ?it/s]100%|██████████| 1/1 [00:00<00:00, 20.66it/s]
  0%|          | 0/1 [00:00<?, ?it/s]100%|██████████| 1/1 [00:00<00:00, 35.67it/s]
  0%|          | 0/1 [00:00<?, ?it/s]100%|██████████| 1/1 [00:00<00:00, 27.77it/s]
  0%|          | 0/1 [00:00<?, ?it/s]100%|██████████| 1/1 [00:00<00:00, 31.11it/s]
  0%|          | 0/1 [00:00<?, ?it/s]100%|██████████| 1/1 [00:00<00:00, 28.55it/s]
  0%|          | 0/1 [00:00<?, ?it/s]100%|██████████| 1/1 [00:00<00:00, 24.66it/s]
  0%|          | 0/1 [00:00<?, ?it/s]100%|██████████| 1/1 [00:00<00:00, 36.89it/s]
  0%|          | 0/1 [00:00<?, ?it/s]100%|██████████| 1/1 [00:00<00:00, 19.39it/s]
Process Process-21:
Traceback (most recent call last):
  File "/homes/dbarton/miniconda3/lib/python3.8/multiprocessing/process.py", line 315, in _bootstrap
    self.run()
  File "/homes/dbarton/miniconda3/lib/python3.8/multiprocessing/process.py", line 108, in run
    self._target(*self._args, **self._kwargs)
  File "run_pwl.py", line 125, in pwl_solve
    solver = annealing.solve_exp(lptr, M, r, default_loss_conf=loss_conf)
  File "/cluster/rs_lab/dbarton/usb_twitching/pili/src/analysis/annealing.py", line 1751, in solve_exp
    solver.remapping()
  File "/cluster/rs_lab/dbarton/usb_twitching/pili/src/analysis/annealing.py", line 1656, in remapping
    queue.append((bysegment[sidx][0], lptr.sidx[i-1]))
IndexError: list index out of range
  0%|          | 0/1 [00:00<?, ?it/s]100%|██████████| 1/1 [00:00<00:00, 22.24it/s]
Process Process-45:
Traceback (most recent call last):
  File "/homes/dbarton/miniconda3/lib/python3.8/multiprocessing/process.py", line 315, in _bootstrap
    self.run()
  File "/homes/dbarton/miniconda3/lib/python3.8/multiprocessing/process.py", line 108, in run
    self._target(*self._args, **self._kwargs)
  File "run_pwl.py", line 125, in pwl_solve
    solver = annealing.solve_exp(lptr, M, r, default_loss_conf=loss_conf)
  File "/cluster/rs_lab/dbarton/usb_twitching/pili/src/analysis/annealing.py", line 1751, in solve_exp
    solver.remapping()
  File "/cluster/rs_lab/dbarton/usb_twitching/pili/src/analysis/annealing.py", line 1656, in remapping
    queue.append((bysegment[sidx][0], lptr.sidx[i-1]))
IndexError: list index out of range
  0%|          | 0/1 [00:00<?, ?it/s]100%|██████████| 1/1 [00:00<00:00, 54.16it/s]
/cluster/rs_lab/dbarton/usb_twitching/pili/support.py:52: RuntimeWarning: invalid value encountered in true_divide
  d_hat = np.divide(d_ba, d)
Process Process-50:
Traceback (most recent call last):
  File "/homes/dbarton/miniconda3/lib/python3.8/multiprocessing/process.py", line 315, in _bootstrap
    self.run()
  File "/homes/dbarton/miniconda3/lib/python3.8/multiprocessing/process.py", line 108, in run
    self._target(*self._args, **self._kwargs)
  File "run_pwl.py", line 125, in pwl_solve
    solver = annealing.solve_exp(lptr, M, r, default_loss_conf=loss_conf)
  File "/cluster/rs_lab/dbarton/usb_twitching/pili/src/analysis/annealing.py", line 1751, in solve_exp
    solver.remapping()
  File "/cluster/rs_lab/dbarton/usb_twitching/pili/src/analysis/annealing.py", line 1656, in remapping
    queue.append((bysegment[sidx][0], lptr.sidx[i-1]))
IndexError: list index out of range
  0%|          | 0/1 [00:00<?, ?it/s]100%|██████████| 1/1 [00:00<00:00, 30.81it/s]
  0%|          | 0/1 [00:00<?, ?it/s]100%|██████████| 1/1 [00:00<00:00, 29.31it/s]
Process Process-25:
Traceback (most recent call last):
  File "/homes/dbarton/miniconda3/lib/python3.8/multiprocessing/process.py", line 315, in _bootstrap
    self.run()
  File "/homes/dbarton/miniconda3/lib/python3.8/multiprocessing/process.py", line 108, in run
    self._target(*self._args, **self._kwargs)
  File "run_pwl.py", line 125, in pwl_solve
    solver = annealing.solve_exp(lptr, M, r, default_loss_conf=loss_conf)
  File "/cluster/rs_lab/dbarton/usb_twitching/pili/src/analysis/annealing.py", line 1751, in solve_exp
    solver.remapping()
  File "/cluster/rs_lab/dbarton/usb_twitching/pili/src/analysis/annealing.py", line 1656, in remapping
    queue.append((bysegment[sidx][0], lptr.sidx[i-1]))
IndexError: list index out of range
  0%|          | 0/1 [00:00<?, ?it/s]100%|██████████| 1/1 [00:00<00:00, 35.21it/s]
  0%|          | 0/1 [00:00<?, ?it/s]100%|██████████| 1/1 [00:00<00:00, 20.43it/s]
  0%|          | 0/1 [00:00<?, ?it/s]100%|██████████| 1/1 [00:00<00:00, 31.68it/s]
  0%|          | 0/1 [00:00<?, ?it/s]100%|██████████| 1/1 [00:00<00:00, 29.95it/s]
  0%|          | 0/1 [00:00<?, ?it/s]100%|██████████| 1/1 [00:00<00:00, 58.37it/s]
  0%|          | 0/1 [00:00<?, ?it/s]100%|██████████| 1/1 [00:00<00:00, 19.96it/s]
  0%|          | 0/1 [00:00<?, ?it/s]100%|██████████| 1/1 [00:00<00:00, 30.90it/s]
/cluster/rs_lab/dbarton/usb_twitching/pili/support.py:52: RuntimeWarning: invalid value encountered in true_divide
  d_hat = np.divide(d_ba, d)
  0%|          | 0/1 [00:00<?, ?it/s]100%|██████████| 1/1 [00:00<00:00, 49.80it/s]
/cluster/rs_lab/dbarton/usb_twitching/pili/support.py:52: RuntimeWarning: invalid value encountered in true_divide
  d_hat = np.divide(d_ba, d)
  0%|          | 0/1 [00:00<?, ?it/s]100%|██████████| 1/1 [00:00<00:00, 23.87it/s]
/cluster/rs_lab/dbarton/usb_twitching/pili/support.py:52: RuntimeWarning: invalid value encountered in true_divide
  d_hat = np.divide(d_ba, d)
Process Process-79:
Traceback (most recent call last):
  File "/homes/dbarton/miniconda3/lib/python3.8/multiprocessing/process.py", line 315, in _bootstrap
    self.run()
  File "/homes/dbarton/miniconda3/lib/python3.8/multiprocessing/process.py", line 108, in run
    self._target(*self._args, **self._kwargs)
  File "run_pwl.py", line 125, in pwl_solve
    solver = annealing.solve_exp(lptr, M, r, default_loss_conf=loss_conf)
  File "/cluster/rs_lab/dbarton/usb_twitching/pili/src/analysis/annealing.py", line 1751, in solve_exp
    solver.remapping()
  File "/cluster/rs_lab/dbarton/usb_twitching/pili/src/analysis/annealing.py", line 1656, in remapping
    queue.append((bysegment[sidx][0], lptr.sidx[i-1]))
IndexError: list index out of range
  0%|          | 0/1 [00:00<?, ?it/s]100%|██████████| 1/1 [00:00<00:00, 36.39it/s]
Process Process-59:
Traceback (most recent call last):
  File "/homes/dbarton/miniconda3/lib/python3.8/multiprocessing/process.py", line 315, in _bootstrap
    self.run()
  File "/homes/dbarton/miniconda3/lib/python3.8/multiprocessing/process.py", line 108, in run
    self._target(*self._args, **self._kwargs)
  File "run_pwl.py", line 125, in pwl_solve
    solver = annealing.solve_exp(lptr, M, r, default_loss_conf=loss_conf)
  File "/cluster/rs_lab/dbarton/usb_twitching/pili/src/analysis/annealing.py", line 1751, in solve_exp
    solver.remapping()
  File "/cluster/rs_lab/dbarton/usb_twitching/pili/src/analysis/annealing.py", line 1656, in remapping
    queue.append((bysegment[sidx][0], lptr.sidx[i-1]))
IndexError: list index out of range
  0%|          | 0/1 [00:00<?, ?it/s]100%|██████████| 1/1 [00:00<00:00, 21.63it/s]
  0%|          | 0/1 [00:00<?, ?it/s]100%|██████████| 1/1 [00:00<00:00, 20.15it/s]
  0%|          | 0/1 [00:00<?, ?it/s]100%|██████████| 1/1 [00:00<00:00, 21.58it/s]
  0%|          | 0/1 [00:00<?, ?it/s]100%|██████████| 1/1 [00:00<00:00, 22.61it/s]
Process Process-72:
Traceback (most recent call last):
  File "/homes/dbarton/miniconda3/lib/python3.8/multiprocessing/process.py", line 315, in _bootstrap
    self.run()
  File "/homes/dbarton/miniconda3/lib/python3.8/multiprocessing/process.py", line 108, in run
    self._target(*self._args, **self._kwargs)
  File "run_pwl.py", line 125, in pwl_solve
    solver = annealing.solve_exp(lptr, M, r, default_loss_conf=loss_conf)
  File "/cluster/rs_lab/dbarton/usb_twitching/pili/src/analysis/annealing.py", line 1751, in solve_exp
    solver.remapping()
  File "/cluster/rs_lab/dbarton/usb_twitching/pili/src/analysis/annealing.py", line 1656, in remapping
    queue.append((bysegment[sidx][0], lptr.sidx[i-1]))
IndexError: list index out of range
  0%|          | 0/1 [00:00<?, ?it/s]100%|██████████| 1/1 [00:00<00:00, 21.21it/s]
/cluster/rs_lab/dbarton/usb_twitching/pili/support.py:52: RuntimeWarning: invalid value encountered in true_divide
  d_hat = np.divide(d_ba, d)
  0%|          | 0/1 [00:00<?, ?it/s]100%|██████████| 1/1 [00:00<00:00, 28.68it/s]
  0%|          | 0/1 [00:00<?, ?it/s]100%|██████████| 1/1 [00:00<00:00, 54.08it/s]
  0%|          | 0/1 [00:00<?, ?it/s]100%|██████████| 1/1 [00:00<00:00, 90.52it/s]
Process Process-68:
Traceback (most recent call last):
  File "/homes/dbarton/miniconda3/lib/python3.8/multiprocessing/process.py", line 315, in _bootstrap
    self.run()
  File "/homes/dbarton/miniconda3/lib/python3.8/multiprocessing/process.py", line 108, in run
    self._target(*self._args, **self._kwargs)
  File "run_pwl.py", line 125, in pwl_solve
    solver = annealing.solve_exp(lptr, M, r, default_loss_conf=loss_conf)
  File "/cluster/rs_lab/dbarton/usb_twitching/pili/src/analysis/annealing.py", line 1751, in solve_exp
    solver.remapping()
  File "/cluster/rs_lab/dbarton/usb_twitching/pili/src/analysis/annealing.py", line 1656, in remapping
    queue.append((bysegment[sidx][0], lptr.sidx[i-1]))
IndexError: list index out of range
  0%|          | 0/1 [00:00<?, ?it/s]100%|██████████| 1/1 [00:00<00:00, 31.72it/s]
  0%|          | 0/1 [00:00<?, ?it/s]100%|██████████| 1/1 [00:00<00:00, 42.71it/s]
  0%|          | 0/1 [00:00<?, ?it/s]100%|██████████| 1/1 [00:00<00:00, 19.92it/s]
  0%|          | 0/1 [00:00<?, ?it/s]100%|██████████| 1/1 [00:00<00:00, 162.43it/s]
  0%|          | 0/1 [00:00<?, ?it/s]100%|██████████| 1/1 [00:00<00:00, 49.28it/s]
Process Process-110:
Traceback (most recent call last):
  File "/homes/dbarton/miniconda3/lib/python3.8/multiprocessing/process.py", line 315, in _bootstrap
    self.run()
  File "/homes/dbarton/miniconda3/lib/python3.8/multiprocessing/process.py", line 108, in run
    self._target(*self._args, **self._kwargs)
  File "run_pwl.py", line 125, in pwl_solve
    solver = annealing.solve_exp(lptr, M, r, default_loss_conf=loss_conf)
  File "/cluster/rs_lab/dbarton/usb_twitching/pili/src/analysis/annealing.py", line 1751, in solve_exp
    solver.remapping()
  File "/cluster/rs_lab/dbarton/usb_twitching/pili/src/analysis/annealing.py", line 1656, in remapping
    queue.append((bysegment[sidx][0], lptr.sidx[i-1]))
IndexError: list index out of range
  0%|          | 0/1 [00:00<?, ?it/s]100%|██████████| 1/1 [00:00<00:00, 37.26it/s]
Process Process-82:
Traceback (most recent call last):
  File "/homes/dbarton/miniconda3/lib/python3.8/multiprocessing/process.py", line 315, in _bootstrap
    self.run()
  File "/homes/dbarton/miniconda3/lib/python3.8/multiprocessing/process.py", line 108, in run
    self._target(*self._args, **self._kwargs)
  File "run_pwl.py", line 125, in pwl_solve
    solver = annealing.solve_exp(lptr, M, r, default_loss_conf=loss_conf)
  File "/cluster/rs_lab/dbarton/usb_twitching/pili/src/analysis/annealing.py", line 1751, in solve_exp
    solver.remapping()
  File "/cluster/rs_lab/dbarton/usb_twitching/pili/src/analysis/annealing.py", line 1656, in remapping
    queue.append((bysegment[sidx][0], lptr.sidx[i-1]))
IndexError: list index out of range
  0%|          | 0/1 [00:00<?, ?it/s]100%|██████████| 1/1 [00:00<00:00, 52.98it/s]
/cluster/rs_lab/dbarton/usb_twitching/pili/support.py:52: RuntimeWarning: invalid value encountered in true_divide
  d_hat = np.divide(d_ba, d)
Process Process-73:
Traceback (most recent call last):
  File "/homes/dbarton/miniconda3/lib/python3.8/multiprocessing/process.py", line 315, in _bootstrap
    self.run()
  File "/homes/dbarton/miniconda3/lib/python3.8/multiprocessing/process.py", line 108, in run
    self._target(*self._args, **self._kwargs)
  File "run_pwl.py", line 125, in pwl_solve
    solver = annealing.solve_exp(lptr, M, r, default_loss_conf=loss_conf)
  File "/cluster/rs_lab/dbarton/usb_twitching/pili/src/analysis/annealing.py", line 1751, in solve_exp
    solver.remapping()
  File "/cluster/rs_lab/dbarton/usb_twitching/pili/src/analysis/annealing.py", line 1656, in remapping
    queue.append((bysegment[sidx][0], lptr.sidx[i-1]))
IndexError: list index out of range
  0%|          | 0/1 [00:00<?, ?it/s]100%|██████████| 1/1 [00:00<00:00, 69.71it/s]
  0%|          | 0/1 [00:00<?, ?it/s]100%|██████████| 1/1 [00:00<00:00, 33.62it/s]
/cluster/rs_lab/dbarton/usb_twitching/pili/support.py:52: RuntimeWarning: invalid value encountered in true_divide
  d_hat = np.divide(d_ba, d)
  0%|          | 0/1 [00:00<?, ?it/s]100%|██████████| 1/1 [00:00<00:00, 19.74it/s]
  0%|          | 0/1 [00:00<?, ?it/s]100%|██████████| 1/1 [00:00<00:00, 44.14it/s]
  0%|          | 0/1 [00:00<?, ?it/s]100%|██████████| 1/1 [00:00<00:00, 20.12it/s]
/cluster/rs_lab/dbarton/usb_twitching/pili/support.py:52: RuntimeWarning: invalid value encountered in true_divide
  d_hat = np.divide(d_ba, d)
  0%|          | 0/1 [00:00<?, ?it/s]100%|██████████| 1/1 [00:00<00:00, 63.85it/s]
  0%|          | 0/1 [00:00<?, ?it/s]100%|██████████| 1/1 [00:00<00:00, 20.01it/s]
  0%|          | 0/1 [00:00<?, ?it/s]100%|██████████| 1/1 [00:00<00:00, 22.90it/s]
Process Process-105:
Traceback (most recent call last):
  File "/homes/dbarton/miniconda3/lib/python3.8/multiprocessing/process.py", line 315, in _bootstrap
    self.run()
  File "/homes/dbarton/miniconda3/lib/python3.8/multiprocessing/process.py", line 108, in run
    self._target(*self._args, **self._kwargs)
  File "run_pwl.py", line 125, in pwl_solve
    solver = annealing.solve_exp(lptr, M, r, default_loss_conf=loss_conf)
  File "/cluster/rs_lab/dbarton/usb_twitching/pili/src/analysis/annealing.py", line 1751, in solve_exp
    solver.remapping()
  File "/cluster/rs_lab/dbarton/usb_twitching/pili/src/analysis/annealing.py", line 1656, in remapping
    queue.append((bysegment[sidx][0], lptr.sidx[i-1]))
IndexError: list index out of range
  0%|          | 0/1 [00:00<?, ?it/s]100%|██████████| 1/1 [00:00<00:00, 37.99it/s]
Process Process-112:
Traceback (most recent call last):
  File "/homes/dbarton/miniconda3/lib/python3.8/multiprocessing/process.py", line 315, in _bootstrap
    self.run()
  File "/homes/dbarton/miniconda3/lib/python3.8/multiprocessing/process.py", line 108, in run
    self._target(*self._args, **self._kwargs)
  File "run_pwl.py", line 125, in pwl_solve
    solver = annealing.solve_exp(lptr, M, r, default_loss_conf=loss_conf)
  File "/cluster/rs_lab/dbarton/usb_twitching/pili/src/analysis/annealing.py", line 1751, in solve_exp
    solver.remapping()
  File "/cluster/rs_lab/dbarton/usb_twitching/pili/src/analysis/annealing.py", line 1656, in remapping
    queue.append((bysegment[sidx][0], lptr.sidx[i-1]))
IndexError: list index out of range
  0%|          | 0/1 [00:00<?, ?it/s]100%|██████████| 1/1 [00:00<00:00, 31.70it/s]
Process Process-31:
Traceback (most recent call last):
  File "/homes/dbarton/miniconda3/lib/python3.8/multiprocessing/process.py", line 315, in _bootstrap
    self.run()
  File "/homes/dbarton/miniconda3/lib/python3.8/multiprocessing/process.py", line 108, in run
    self._target(*self._args, **self._kwargs)
  File "run_pwl.py", line 125, in pwl_solve
    solver = annealing.solve_exp(lptr, M, r, default_loss_conf=loss_conf)
  File "/cluster/rs_lab/dbarton/usb_twitching/pili/src/analysis/annealing.py", line 1751, in solve_exp
    solver.remapping()
  File "/cluster/rs_lab/dbarton/usb_twitching/pili/src/analysis/annealing.py", line 1656, in remapping
    queue.append((bysegment[sidx][0], lptr.sidx[i-1]))
IndexError: list index out of range
  0%|          | 0/1 [00:00<?, ?it/s]100%|██████████| 1/1 [00:00<00:00, 19.76it/s]
Process Process-13:
Traceback (most recent call last):
  File "/homes/dbarton/miniconda3/lib/python3.8/multiprocessing/process.py", line 315, in _bootstrap
    self.run()
  File "/homes/dbarton/miniconda3/lib/python3.8/multiprocessing/process.py", line 108, in run
    self._target(*self._args, **self._kwargs)
  File "run_pwl.py", line 125, in pwl_solve
    solver = annealing.solve_exp(lptr, M, r, default_loss_conf=loss_conf)
  File "/cluster/rs_lab/dbarton/usb_twitching/pili/src/analysis/annealing.py", line 1751, in solve_exp
    solver.remapping()
  File "/cluster/rs_lab/dbarton/usb_twitching/pili/src/analysis/annealing.py", line 1656, in remapping
    queue.append((bysegment[sidx][0], lptr.sidx[i-1]))
IndexError: list index out of range
  0%|          | 0/1 [00:00<?, ?it/s]100%|██████████| 1/1 [00:00<00:00, 23.30it/s]
Process Process-4:
Traceback (most recent call last):
  File "/homes/dbarton/miniconda3/lib/python3.8/multiprocessing/process.py", line 315, in _bootstrap
    self.run()
  File "/homes/dbarton/miniconda3/lib/python3.8/multiprocessing/process.py", line 108, in run
    self._target(*self._args, **self._kwargs)
  File "run_pwl.py", line 125, in pwl_solve
    solver = annealing.solve_exp(lptr, M, r, default_loss_conf=loss_conf)
  File "/cluster/rs_lab/dbarton/usb_twitching/pili/src/analysis/annealing.py", line 1751, in solve_exp
    solver.remapping()
  File "/cluster/rs_lab/dbarton/usb_twitching/pili/src/analysis/annealing.py", line 1656, in remapping
    queue.append((bysegment[sidx][0], lptr.sidx[i-1]))
IndexError: list index out of range
  0%|          | 0/1 [00:00<?, ?it/s]100%|██████████| 1/1 [00:00<00:00, 21.86it/s]
  0%|          | 0/1 [00:00<?, ?it/s]100%|██████████| 1/1 [00:00<00:00, 27.71it/s]
/cluster/rs_lab/dbarton/usb_twitching/pili/support.py:52: RuntimeWarning: invalid value encountered in true_divide
  d_hat = np.divide(d_ba, d)
Process Process-118:
Traceback (most recent call last):
  File "/homes/dbarton/miniconda3/lib/python3.8/multiprocessing/process.py", line 315, in _bootstrap
    self.run()
  File "/homes/dbarton/miniconda3/lib/python3.8/multiprocessing/process.py", line 108, in run
    self._target(*self._args, **self._kwargs)
  File "run_pwl.py", line 125, in pwl_solve
    solver = annealing.solve_exp(lptr, M, r, default_loss_conf=loss_conf)
  File "/cluster/rs_lab/dbarton/usb_twitching/pili/src/analysis/annealing.py", line 1751, in solve_exp
    solver.remapping()
  File "/cluster/rs_lab/dbarton/usb_twitching/pili/src/analysis/annealing.py", line 1656, in remapping
    queue.append((bysegment[sidx][0], lptr.sidx[i-1]))
IndexError: list index out of range
  0%|          | 0/1 [00:00<?, ?it/s]100%|██████████| 1/1 [00:00<00:00, 45.66it/s]
  0%|          | 0/1 [00:00<?, ?it/s]100%|██████████| 1/1 [00:00<00:00, 19.87it/s]
/cluster/rs_lab/dbarton/usb_twitching/pili/support.py:52: RuntimeWarning: invalid value encountered in true_divide
  d_hat = np.divide(d_ba, d)
Process Process-41:
Traceback (most recent call last):
  File "/homes/dbarton/miniconda3/lib/python3.8/multiprocessing/process.py", line 315, in _bootstrap
    self.run()
  File "/homes/dbarton/miniconda3/lib/python3.8/multiprocessing/process.py", line 108, in run
    self._target(*self._args, **self._kwargs)
  File "run_pwl.py", line 125, in pwl_solve
    solver = annealing.solve_exp(lptr, M, r, default_loss_conf=loss_conf)
  File "/cluster/rs_lab/dbarton/usb_twitching/pili/src/analysis/annealing.py", line 1751, in solve_exp
    solver.remapping()
  File "/cluster/rs_lab/dbarton/usb_twitching/pili/src/analysis/annealing.py", line 1656, in remapping
    queue.append((bysegment[sidx][0], lptr.sidx[i-1]))
IndexError: list index out of range
  0%|          | 0/1 [00:00<?, ?it/s]100%|██████████| 1/1 [00:00<00:00, 19.79it/s]
Process Process-121:
Traceback (most recent call last):
  File "/homes/dbarton/miniconda3/lib/python3.8/multiprocessing/process.py", line 315, in _bootstrap
    self.run()
  File "/homes/dbarton/miniconda3/lib/python3.8/multiprocessing/process.py", line 108, in run
    self._target(*self._args, **self._kwargs)
  File "run_pwl.py", line 125, in pwl_solve
    solver = annealing.solve_exp(lptr, M, r, default_loss_conf=loss_conf)
  File "/cluster/rs_lab/dbarton/usb_twitching/pili/src/analysis/annealing.py", line 1751, in solve_exp
    solver.remapping()
  File "/cluster/rs_lab/dbarton/usb_twitching/pili/src/analysis/annealing.py", line 1656, in remapping
    queue.append((bysegment[sidx][0], lptr.sidx[i-1]))
IndexError: list index out of range
  0%|          | 0/1 [00:00<?, ?it/s]100%|██████████| 1/1 [00:00<00:00, 21.64it/s]
/cluster/rs_lab/dbarton/usb_twitching/pili/support.py:52: RuntimeWarning: invalid value encountered in true_divide
  d_hat = np.divide(d_ba, d)
  0%|          | 0/1 [00:00<?, ?it/s]100%|██████████| 1/1 [00:00<00:00, 30.50it/s]
Process Process-148:
Traceback (most recent call last):
  File "/homes/dbarton/miniconda3/lib/python3.8/multiprocessing/process.py", line 315, in _bootstrap
    self.run()
  File "/homes/dbarton/miniconda3/lib/python3.8/multiprocessing/process.py", line 108, in run
    self._target(*self._args, **self._kwargs)
  File "run_pwl.py", line 125, in pwl_solve
    solver = annealing.solve_exp(lptr, M, r, default_loss_conf=loss_conf)
  File "/cluster/rs_lab/dbarton/usb_twitching/pili/src/analysis/annealing.py", line 1751, in solve_exp
    solver.remapping()
  File "/cluster/rs_lab/dbarton/usb_twitching/pili/src/analysis/annealing.py", line 1656, in remapping
    queue.append((bysegment[sidx][0], lptr.sidx[i-1]))
IndexError: list index out of range
  0%|          | 0/1 [00:00<?, ?it/s]100%|██████████| 1/1 [00:00<00:00, 19.68it/s]
Process Process-131:
Traceback (most recent call last):
  File "/homes/dbarton/miniconda3/lib/python3.8/multiprocessing/process.py", line 315, in _bootstrap
    self.run()
  File "/homes/dbarton/miniconda3/lib/python3.8/multiprocessing/process.py", line 108, in run
    self._target(*self._args, **self._kwargs)
  File "run_pwl.py", line 125, in pwl_solve
    solver = annealing.solve_exp(lptr, M, r, default_loss_conf=loss_conf)
  File "/cluster/rs_lab/dbarton/usb_twitching/pili/src/analysis/annealing.py", line 1751, in solve_exp
    solver.remapping()
  File "/cluster/rs_lab/dbarton/usb_twitching/pili/src/analysis/annealing.py", line 1656, in remapping
    queue.append((bysegment[sidx][0], lptr.sidx[i-1]))
IndexError: list index out of range
  0%|          | 0/1 [00:00<?, ?it/s]100%|██████████| 1/1 [00:00<00:00, 30.32it/s]
Process Process-137:
Traceback (most recent call last):
  File "/homes/dbarton/miniconda3/lib/python3.8/multiprocessing/process.py", line 315, in _bootstrap
    self.run()
  File "/homes/dbarton/miniconda3/lib/python3.8/multiprocessing/process.py", line 108, in run
    self._target(*self._args, **self._kwargs)
  File "run_pwl.py", line 125, in pwl_solve
    solver = annealing.solve_exp(lptr, M, r, default_loss_conf=loss_conf)
  File "/cluster/rs_lab/dbarton/usb_twitching/pili/src/analysis/annealing.py", line 1751, in solve_exp
    solver.remapping()
  File "/cluster/rs_lab/dbarton/usb_twitching/pili/src/analysis/annealing.py", line 1656, in remapping
    queue.append((bysegment[sidx][0], lptr.sidx[i-1]))
IndexError: list index out of range
  0%|          | 0/1 [00:00<?, ?it/s]100%|██████████| 1/1 [00:00<00:00, 29.19it/s]
Process Process-116:
Traceback (most recent call last):
  File "/homes/dbarton/miniconda3/lib/python3.8/multiprocessing/process.py", line 315, in _bootstrap
    self.run()
  File "/homes/dbarton/miniconda3/lib/python3.8/multiprocessing/process.py", line 108, in run
    self._target(*self._args, **self._kwargs)
  File "run_pwl.py", line 125, in pwl_solve
    solver = annealing.solve_exp(lptr, M, r, default_loss_conf=loss_conf)
  File "/cluster/rs_lab/dbarton/usb_twitching/pili/src/analysis/annealing.py", line 1751, in solve_exp
    solver.remapping()
  File "/cluster/rs_lab/dbarton/usb_twitching/pili/src/analysis/annealing.py", line 1656, in remapping
    queue.append((bysegment[sidx][0], lptr.sidx[i-1]))
IndexError: list index out of range
  0%|          | 0/1 [00:00<?, ?it/s]100%|██████████| 1/1 [00:00<00:00, 17.96it/s]
/cluster/rs_lab/dbarton/usb_twitching/pili/support.py:52: RuntimeWarning: invalid value encountered in true_divide
  d_hat = np.divide(d_ba, d)
/cluster/rs_lab/dbarton/usb_twitching/pili/src/analysis/annealing.py:1359: RuntimeWarning: overflow encountered in exp
  s = np.exp(-(score_prime - score)/T)
Process Process-7:
Traceback (most recent call last):
  File "/homes/dbarton/miniconda3/lib/python3.8/multiprocessing/process.py", line 315, in _bootstrap
    self.run()
  File "/homes/dbarton/miniconda3/lib/python3.8/multiprocessing/process.py", line 108, in run
    self._target(*self._args, **self._kwargs)
  File "run_pwl.py", line 125, in pwl_solve
    solver = annealing.solve_exp(lptr, M, r, default_loss_conf=loss_conf)
  File "/cluster/rs_lab/dbarton/usb_twitching/pili/src/analysis/annealing.py", line 1751, in solve_exp
    solver.remapping()
  File "/cluster/rs_lab/dbarton/usb_twitching/pili/src/analysis/annealing.py", line 1656, in remapping
    queue.append((bysegment[sidx][0], lptr.sidx[i-1]))
IndexError: list index out of range
  0%|          | 0/1 [00:00<?, ?it/s]100%|██████████| 1/1 [00:00<00:00, 34.23it/s]
  0%|          | 0/1 [00:00<?, ?it/s]100%|██████████| 1/1 [00:00<00:00, 58.05it/s]
  0%|          | 0/1 [00:00<?, ?it/s]100%|██████████| 1/1 [00:00<00:00, 26.94it/s]
  0%|          | 0/1 [00:00<?, ?it/s]100%|██████████| 1/1 [00:00<00:00, 29.42it/s]
  0%|          | 0/1 [00:00<?, ?it/s]100%|██████████| 1/1 [00:00<00:00, 45.47it/s]
/cluster/rs_lab/dbarton/usb_twitching/pili/support.py:52: RuntimeWarning: invalid value encountered in true_divide
  d_hat = np.divide(d_ba, d)
Process Process-47:
Traceback (most recent call last):
  File "/homes/dbarton/miniconda3/lib/python3.8/multiprocessing/process.py", line 315, in _bootstrap
    self.run()
  File "/homes/dbarton/miniconda3/lib/python3.8/multiprocessing/process.py", line 108, in run
    self._target(*self._args, **self._kwargs)
  File "run_pwl.py", line 125, in pwl_solve
    solver = annealing.solve_exp(lptr, M, r, default_loss_conf=loss_conf)
  File "/cluster/rs_lab/dbarton/usb_twitching/pili/src/analysis/annealing.py", line 1751, in solve_exp
    solver.remapping()
  File "/cluster/rs_lab/dbarton/usb_twitching/pili/src/analysis/annealing.py", line 1656, in remapping
    queue.append((bysegment[sidx][0], lptr.sidx[i-1]))
IndexError: list index out of range
  0%|          | 0/1 [00:00<?, ?it/s]100%|██████████| 1/1 [00:00<00:00, 49.75it/s]
Process Process-14:
Traceback (most recent call last):
  File "/homes/dbarton/miniconda3/lib/python3.8/multiprocessing/process.py", line 315, in _bootstrap
    self.run()
  File "/homes/dbarton/miniconda3/lib/python3.8/multiprocessing/process.py", line 108, in run
    self._target(*self._args, **self._kwargs)
  File "run_pwl.py", line 125, in pwl_solve
    solver = annealing.solve_exp(lptr, M, r, default_loss_conf=loss_conf)
  File "/cluster/rs_lab/dbarton/usb_twitching/pili/src/analysis/annealing.py", line 1751, in solve_exp
    solver.remapping()
  File "/cluster/rs_lab/dbarton/usb_twitching/pili/src/analysis/annealing.py", line 1656, in remapping
    queue.append((bysegment[sidx][0], lptr.sidx[i-1]))
IndexError: list index out of range
  0%|          | 0/1 [00:00<?, ?it/s]100%|██████████| 1/1 [00:00<00:00, 20.04it/s]
/cluster/rs_lab/dbarton/usb_twitching/pili/src/analysis/annealing.py:1359: RuntimeWarning: overflow encountered in exp
  s = np.exp(-(score_prime - score)/T)
Process Process-58:
Traceback (most recent call last):
  File "/homes/dbarton/miniconda3/lib/python3.8/multiprocessing/process.py", line 315, in _bootstrap
    self.run()
  File "/homes/dbarton/miniconda3/lib/python3.8/multiprocessing/process.py", line 108, in run
    self._target(*self._args, **self._kwargs)
  File "run_pwl.py", line 125, in pwl_solve
    solver = annealing.solve_exp(lptr, M, r, default_loss_conf=loss_conf)
  File "/cluster/rs_lab/dbarton/usb_twitching/pili/src/analysis/annealing.py", line 1751, in solve_exp
    solver.remapping()
  File "/cluster/rs_lab/dbarton/usb_twitching/pili/src/analysis/annealing.py", line 1656, in remapping
    queue.append((bysegment[sidx][0], lptr.sidx[i-1]))
IndexError: list index out of range
  0%|          | 0/1 [00:00<?, ?it/s]100%|██████████| 1/1 [00:00<00:00, 28.93it/s]
  0%|          | 0/1 [00:00<?, ?it/s]100%|██████████| 1/1 [00:00<00:00, 22.52it/s]
  0%|          | 0/1 [00:00<?, ?it/s]100%|██████████| 1/1 [00:00<00:00, 44.62it/s]
Process Process-159:
Traceback (most recent call last):
  File "/homes/dbarton/miniconda3/lib/python3.8/multiprocessing/process.py", line 315, in _bootstrap
    self.run()
  File "/homes/dbarton/miniconda3/lib/python3.8/multiprocessing/process.py", line 108, in run
    self._target(*self._args, **self._kwargs)
  File "run_pwl.py", line 125, in pwl_solve
    solver = annealing.solve_exp(lptr, M, r, default_loss_conf=loss_conf)
  File "/cluster/rs_lab/dbarton/usb_twitching/pili/src/analysis/annealing.py", line 1751, in solve_exp
    solver.remapping()
  File "/cluster/rs_lab/dbarton/usb_twitching/pili/src/analysis/annealing.py", line 1656, in remapping
    queue.append((bysegment[sidx][0], lptr.sidx[i-1]))
IndexError: list index out of range
  0%|          | 0/1 [00:00<?, ?it/s]100%|██████████| 1/1 [00:00<00:00, 21.12it/s]
Process Process-150:
Traceback (most recent call last):
  File "/homes/dbarton/miniconda3/lib/python3.8/multiprocessing/process.py", line 315, in _bootstrap
    self.run()
  File "/homes/dbarton/miniconda3/lib/python3.8/multiprocessing/process.py", line 108, in run
    self._target(*self._args, **self._kwargs)
  File "run_pwl.py", line 125, in pwl_solve
    solver = annealing.solve_exp(lptr, M, r, default_loss_conf=loss_conf)
  File "/cluster/rs_lab/dbarton/usb_twitching/pili/src/analysis/annealing.py", line 1751, in solve_exp
    solver.remapping()
  File "/cluster/rs_lab/dbarton/usb_twitching/pili/src/analysis/annealing.py", line 1656, in remapping
    queue.append((bysegment[sidx][0], lptr.sidx[i-1]))
IndexError: list index out of range
  0%|          | 0/1 [00:00<?, ?it/s]100%|██████████| 1/1 [00:00<00:00, 37.53it/s]
/cluster/rs_lab/dbarton/usb_twitching/pili/support.py:52: RuntimeWarning: invalid value encountered in true_divide
  d_hat = np.divide(d_ba, d)
  0%|          | 0/1 [00:00<?, ?it/s]100%|██████████| 1/1 [00:00<00:00, 56.12it/s]
  0%|          | 0/1 [00:00<?, ?it/s]100%|██████████| 1/1 [00:00<00:00, 33.01it/s]
  0%|          | 0/1 [00:00<?, ?it/s]100%|██████████| 1/1 [00:00<00:00, 21.36it/s]
Process Process-167:
Traceback (most recent call last):
  File "/homes/dbarton/miniconda3/lib/python3.8/multiprocessing/process.py", line 315, in _bootstrap
    self.run()
  File "/homes/dbarton/miniconda3/lib/python3.8/multiprocessing/process.py", line 108, in run
    self._target(*self._args, **self._kwargs)
  File "run_pwl.py", line 125, in pwl_solve
    solver = annealing.solve_exp(lptr, M, r, default_loss_conf=loss_conf)
  File "/cluster/rs_lab/dbarton/usb_twitching/pili/src/analysis/annealing.py", line 1751, in solve_exp
    solver.remapping()
  File "/cluster/rs_lab/dbarton/usb_twitching/pili/src/analysis/annealing.py", line 1656, in remapping
    queue.append((bysegment[sidx][0], lptr.sidx[i-1]))
IndexError: list index out of range
  0%|          | 0/1 [00:00<?, ?it/s]100%|██████████| 1/1 [00:00<00:00, 34.60it/s]
Process Process-141:
Traceback (most recent call last):
  File "/homes/dbarton/miniconda3/lib/python3.8/multiprocessing/process.py", line 315, in _bootstrap
    self.run()
  File "/homes/dbarton/miniconda3/lib/python3.8/multiprocessing/process.py", line 108, in run
    self._target(*self._args, **self._kwargs)
  File "run_pwl.py", line 125, in pwl_solve
    solver = annealing.solve_exp(lptr, M, r, default_loss_conf=loss_conf)
  File "/cluster/rs_lab/dbarton/usb_twitching/pili/src/analysis/annealing.py", line 1751, in solve_exp
    solver.remapping()
  File "/cluster/rs_lab/dbarton/usb_twitching/pili/src/analysis/annealing.py", line 1656, in remapping
    queue.append((bysegment[sidx][0], lptr.sidx[i-1]))
IndexError: list index out of range
  0%|          | 0/1 [00:00<?, ?it/s]100%|██████████| 1/1 [00:00<00:00, 18.88it/s]
Process Process-152:
Traceback (most recent call last):
  File "/homes/dbarton/miniconda3/lib/python3.8/multiprocessing/process.py", line 315, in _bootstrap
    self.run()
  File "/homes/dbarton/miniconda3/lib/python3.8/multiprocessing/process.py", line 108, in run
    self._target(*self._args, **self._kwargs)
  File "run_pwl.py", line 125, in pwl_solve
    solver = annealing.solve_exp(lptr, M, r, default_loss_conf=loss_conf)
  File "/cluster/rs_lab/dbarton/usb_twitching/pili/src/analysis/annealing.py", line 1751, in solve_exp
    solver.remapping()
  File "/cluster/rs_lab/dbarton/usb_twitching/pili/src/analysis/annealing.py", line 1656, in remapping
    queue.append((bysegment[sidx][0], lptr.sidx[i-1]))
IndexError: list index out of range
  0%|          | 0/1 [00:00<?, ?it/s]100%|██████████| 1/1 [00:00<00:00, 19.11it/s]
Process Process-124:
Traceback (most recent call last):
  File "/homes/dbarton/miniconda3/lib/python3.8/multiprocessing/process.py", line 315, in _bootstrap
    self.run()
  File "/homes/dbarton/miniconda3/lib/python3.8/multiprocessing/process.py", line 108, in run
    self._target(*self._args, **self._kwargs)
  File "run_pwl.py", line 125, in pwl_solve
    solver = annealing.solve_exp(lptr, M, r, default_loss_conf=loss_conf)
  File "/cluster/rs_lab/dbarton/usb_twitching/pili/src/analysis/annealing.py", line 1751, in solve_exp
    solver.remapping()
  File "/cluster/rs_lab/dbarton/usb_twitching/pili/src/analysis/annealing.py", line 1656, in remapping
    queue.append((bysegment[sidx][0], lptr.sidx[i-1]))
IndexError: list index out of range
  0%|          | 0/1 [00:00<?, ?it/s]100%|██████████| 1/1 [00:00<00:00, 19.47it/s]
  0%|          | 0/1 [00:00<?, ?it/s]100%|██████████| 1/1 [00:00<00:00, 45.75it/s]
/cluster/rs_lab/dbarton/usb_twitching/pili/src/analysis/annealing.py:1359: RuntimeWarning: overflow encountered in exp
  s = np.exp(-(score_prime - score)/T)
Process Process-3:
Traceback (most recent call last):
  File "/homes/dbarton/miniconda3/lib/python3.8/multiprocessing/process.py", line 315, in _bootstrap
    self.run()
  File "/homes/dbarton/miniconda3/lib/python3.8/multiprocessing/process.py", line 108, in run
    self._target(*self._args, **self._kwargs)
  File "run_pwl.py", line 125, in pwl_solve
    solver = annealing.solve_exp(lptr, M, r, default_loss_conf=loss_conf)
  File "/cluster/rs_lab/dbarton/usb_twitching/pili/src/analysis/annealing.py", line 1751, in solve_exp
    solver.remapping()
  File "/cluster/rs_lab/dbarton/usb_twitching/pili/src/analysis/annealing.py", line 1656, in remapping
    queue.append((bysegment[sidx][0], lptr.sidx[i-1]))
IndexError: list index out of range
  0%|          | 0/1 [00:00<?, ?it/s]100%|██████████| 1/1 [00:00<00:00, 23.18it/s]
  0%|          | 0/1 [00:00<?, ?it/s]100%|██████████| 1/1 [00:00<00:00, 41.23it/s]
/cluster/rs_lab/dbarton/usb_twitching/pili/support.py:52: RuntimeWarning: invalid value encountered in true_divide
  d_hat = np.divide(d_ba, d)
/cluster/rs_lab/dbarton/usb_twitching/pili/src/analysis/annealing.py:1359: RuntimeWarning: overflow encountered in exp
  s = np.exp(-(score_prime - score)/T)
Process Process-6:
Traceback (most recent call last):
  File "/homes/dbarton/miniconda3/lib/python3.8/multiprocessing/process.py", line 315, in _bootstrap
    self.run()
  File "/homes/dbarton/miniconda3/lib/python3.8/multiprocessing/process.py", line 108, in run
    self._target(*self._args, **self._kwargs)
  File "run_pwl.py", line 125, in pwl_solve
    solver = annealing.solve_exp(lptr, M, r, default_loss_conf=loss_conf)
  File "/cluster/rs_lab/dbarton/usb_twitching/pili/src/analysis/annealing.py", line 1751, in solve_exp
    solver.remapping()
  File "/cluster/rs_lab/dbarton/usb_twitching/pili/src/analysis/annealing.py", line 1656, in remapping
    queue.append((bysegment[sidx][0], lptr.sidx[i-1]))
IndexError: list index out of range
  0%|          | 0/1 [00:00<?, ?it/s]100%|██████████| 1/1 [00:00<00:00, 27.08it/s]
Process Process-139:
Traceback (most recent call last):
  File "/homes/dbarton/miniconda3/lib/python3.8/multiprocessing/process.py", line 315, in _bootstrap
    self.run()
  File "/homes/dbarton/miniconda3/lib/python3.8/multiprocessing/process.py", line 108, in run
    self._target(*self._args, **self._kwargs)
  File "run_pwl.py", line 125, in pwl_solve
    solver = annealing.solve_exp(lptr, M, r, default_loss_conf=loss_conf)
  File "/cluster/rs_lab/dbarton/usb_twitching/pili/src/analysis/annealing.py", line 1751, in solve_exp
    solver.remapping()
  File "/cluster/rs_lab/dbarton/usb_twitching/pili/src/analysis/annealing.py", line 1656, in remapping
    queue.append((bysegment[sidx][0], lptr.sidx[i-1]))
IndexError: list index out of range
  0%|          | 0/1 [00:00<?, ?it/s]100%|██████████| 1/1 [00:00<00:00, 29.40it/s]
Process Process-101:
Traceback (most recent call last):
  File "/homes/dbarton/miniconda3/lib/python3.8/multiprocessing/process.py", line 315, in _bootstrap
    self.run()
  File "/homes/dbarton/miniconda3/lib/python3.8/multiprocessing/process.py", line 108, in run
    self._target(*self._args, **self._kwargs)
  File "run_pwl.py", line 125, in pwl_solve
    solver = annealing.solve_exp(lptr, M, r, default_loss_conf=loss_conf)
  File "/cluster/rs_lab/dbarton/usb_twitching/pili/src/analysis/annealing.py", line 1751, in solve_exp
    solver.remapping()
  File "/cluster/rs_lab/dbarton/usb_twitching/pili/src/analysis/annealing.py", line 1656, in remapping
    queue.append((bysegment[sidx][0], lptr.sidx[i-1]))
IndexError: list index out of range
  0%|          | 0/1 [00:00<?, ?it/s]100%|██████████| 1/1 [00:00<00:00, 30.51it/s]
  0%|          | 0/1 [00:00<?, ?it/s]100%|██████████| 1/1 [00:00<00:00, 19.10it/s]
Process Process-120:
Traceback (most recent call last):
  File "/homes/dbarton/miniconda3/lib/python3.8/multiprocessing/process.py", line 315, in _bootstrap
    self.run()
  File "/homes/dbarton/miniconda3/lib/python3.8/multiprocessing/process.py", line 108, in run
    self._target(*self._args, **self._kwargs)
  File "run_pwl.py", line 125, in pwl_solve
    solver = annealing.solve_exp(lptr, M, r, default_loss_conf=loss_conf)
  File "/cluster/rs_lab/dbarton/usb_twitching/pili/src/analysis/annealing.py", line 1751, in solve_exp
    solver.remapping()
  File "/cluster/rs_lab/dbarton/usb_twitching/pili/src/analysis/annealing.py", line 1656, in remapping
    queue.append((bysegment[sidx][0], lptr.sidx[i-1]))
IndexError: list index out of range
  0%|          | 0/1 [00:00<?, ?it/s]100%|██████████| 1/1 [00:00<00:00, 94.41it/s]
  0%|          | 0/1 [00:00<?, ?it/s]100%|██████████| 1/1 [00:00<00:00, 59.01it/s]
Process Process-75:
Traceback (most recent call last):
  File "/homes/dbarton/miniconda3/lib/python3.8/multiprocessing/process.py", line 315, in _bootstrap
    self.run()
  File "/homes/dbarton/miniconda3/lib/python3.8/multiprocessing/process.py", line 108, in run
    self._target(*self._args, **self._kwargs)
  File "run_pwl.py", line 125, in pwl_solve
    solver = annealing.solve_exp(lptr, M, r, default_loss_conf=loss_conf)
  File "/cluster/rs_lab/dbarton/usb_twitching/pili/src/analysis/annealing.py", line 1751, in solve_exp
    solver.remapping()
  File "/cluster/rs_lab/dbarton/usb_twitching/pili/src/analysis/annealing.py", line 1656, in remapping
    queue.append((bysegment[sidx][0], lptr.sidx[i-1]))
IndexError: list index out of range
  0%|          | 0/1 [00:00<?, ?it/s]100%|██████████| 1/1 [00:00<00:00, 41.45it/s]
Process Process-28:
Traceback (most recent call last):
  File "/homes/dbarton/miniconda3/lib/python3.8/multiprocessing/process.py", line 315, in _bootstrap
    self.run()
  File "/homes/dbarton/miniconda3/lib/python3.8/multiprocessing/process.py", line 108, in run
    self._target(*self._args, **self._kwargs)
  File "run_pwl.py", line 125, in pwl_solve
    solver = annealing.solve_exp(lptr, M, r, default_loss_conf=loss_conf)
  File "/cluster/rs_lab/dbarton/usb_twitching/pili/src/analysis/annealing.py", line 1751, in solve_exp
    solver.remapping()
  File "/cluster/rs_lab/dbarton/usb_twitching/pili/src/analysis/annealing.py", line 1656, in remapping
    queue.append((bysegment[sidx][0], lptr.sidx[i-1]))
IndexError: list index out of range
  0%|          | 0/1 [00:00<?, ?it/s]100%|██████████| 1/1 [00:00<00:00, 66.95it/s]
Process Process-176:
Traceback (most recent call last):
  File "/homes/dbarton/miniconda3/lib/python3.8/multiprocessing/process.py", line 315, in _bootstrap
    self.run()
  File "/homes/dbarton/miniconda3/lib/python3.8/multiprocessing/process.py", line 108, in run
    self._target(*self._args, **self._kwargs)
  File "run_pwl.py", line 125, in pwl_solve
    solver = annealing.solve_exp(lptr, M, r, default_loss_conf=loss_conf)
  File "/cluster/rs_lab/dbarton/usb_twitching/pili/src/analysis/annealing.py", line 1751, in solve_exp
    solver.remapping()
  File "/cluster/rs_lab/dbarton/usb_twitching/pili/src/analysis/annealing.py", line 1656, in remapping
    queue.append((bysegment[sidx][0], lptr.sidx[i-1]))
IndexError: list index out of range
  0%|          | 0/1 [00:00<?, ?it/s]100%|██████████| 1/1 [00:00<00:00, 16.76it/s]
Process Process-123:
Traceback (most recent call last):
  File "/homes/dbarton/miniconda3/lib/python3.8/multiprocessing/process.py", line 315, in _bootstrap
    self.run()
  File "/homes/dbarton/miniconda3/lib/python3.8/multiprocessing/process.py", line 108, in run
    self._target(*self._args, **self._kwargs)
  File "run_pwl.py", line 125, in pwl_solve
    solver = annealing.solve_exp(lptr, M, r, default_loss_conf=loss_conf)
  File "/cluster/rs_lab/dbarton/usb_twitching/pili/src/analysis/annealing.py", line 1751, in solve_exp
    solver.remapping()
  File "/cluster/rs_lab/dbarton/usb_twitching/pili/src/analysis/annealing.py", line 1656, in remapping
    queue.append((bysegment[sidx][0], lptr.sidx[i-1]))
IndexError: list index out of range
  0%|          | 0/1 [00:00<?, ?it/s]100%|██████████| 1/1 [00:00<00:00, 18.75it/s]
  0%|          | 0/1 [00:00<?, ?it/s]100%|██████████| 1/1 [00:00<00:00, 35.45it/s]
Process Process-65:
Traceback (most recent call last):
  File "/homes/dbarton/miniconda3/lib/python3.8/multiprocessing/process.py", line 315, in _bootstrap
    self.run()
  File "/homes/dbarton/miniconda3/lib/python3.8/multiprocessing/process.py", line 108, in run
    self._target(*self._args, **self._kwargs)
  File "run_pwl.py", line 125, in pwl_solve
    solver = annealing.solve_exp(lptr, M, r, default_loss_conf=loss_conf)
  File "/cluster/rs_lab/dbarton/usb_twitching/pili/src/analysis/annealing.py", line 1751, in solve_exp
    solver.remapping()
  File "/cluster/rs_lab/dbarton/usb_twitching/pili/src/analysis/annealing.py", line 1656, in remapping
    queue.append((bysegment[sidx][0], lptr.sidx[i-1]))
IndexError: list index out of range


/cluster/rs_lab/dbarton/usb_twitching/pili/support.py:52: RuntimeWarning: invalid value encountered in true_divide
  d_hat = np.divide(d_ba, d)
Process Process-164:
Traceback (most recent call last):
  File "/homes/dbarton/miniconda3/lib/python3.8/multiprocessing/process.py", line 315, in _bootstrap
    self.run()
  File "/homes/dbarton/miniconda3/lib/python3.8/multiprocessing/process.py", line 108, in run
    self._target(*self._args, **self._kwargs)
  File "run_pwl.py", line 125, in pwl_solve
    solver = annealing.solve_exp(lptr, M, r, default_loss_conf=loss_conf)
  File "/cluster/rs_lab/dbarton/usb_twitching/pili/src/analysis/annealing.py", line 1751, in solve_exp
    solver.remapping()
  File "/cluster/rs_lab/dbarton/usb_twitching/pili/src/analysis/annealing.py", line 1656, in remapping
    queue.append((bysegment[sidx][0], lptr.sidx[i-1]))
IndexError: list index out of range


/cluster/rs_lab/dbarton/usb_twitching/pili/support.py:52: RuntimeWarning: invalid value encountered in true_divide
  d_hat = np.divide(d_ba, d)
/cluster/rs_lab/dbarton/usb_twitching/pili/src/analysis/annealing.py:1359: RuntimeWarning: overflow encountered in exp
  s = np.exp(-(score_prime - score)/T)
Process Process-182:
Traceback (most recent call last):
  File "/homes/dbarton/miniconda3/lib/python3.8/multiprocessing/process.py", line 315, in _bootstrap
    self.run()
  File "/homes/dbarton/miniconda3/lib/python3.8/multiprocessing/process.py", line 108, in run
    self._target(*self._args, **self._kwargs)
  File "run_pwl.py", line 125, in pwl_solve
    solver = annealing.solve_exp(lptr, M, r, default_loss_conf=loss_conf)
  File "/cluster/rs_lab/dbarton/usb_twitching/pili/src/analysis/annealing.py", line 1751, in solve_exp
    solver.remapping()
  File "/cluster/rs_lab/dbarton/usb_twitching/pili/src/analysis/annealing.py", line 1656, in remapping
    queue.append((bysegment[sidx][0], lptr.sidx[i-1]))
IndexError: list index out of range










/cluster/rs_lab/dbarton/usb_twitching/pili/support.py:52: RuntimeWarning: invalid value encountered in true_divide
  d_hat = np.divide(d_ba, d)
Process Process-136:
Traceback (most recent call last):
  File "/homes/dbarton/miniconda3/lib/python3.8/multiprocessing/process.py", line 315, in _bootstrap
    self.run()
  File "/homes/dbarton/miniconda3/lib/python3.8/multiprocessing/process.py", line 108, in run
    self._target(*self._args, **self._kwargs)
  File "run_pwl.py", line 125, in pwl_solve
    solver = annealing.solve_exp(lptr, M, r, default_loss_conf=loss_conf)
  File "/cluster/rs_lab/dbarton/usb_twitching/pili/src/analysis/annealing.py", line 1751, in solve_exp
    solver.remapping()
  File "/cluster/rs_lab/dbarton/usb_twitching/pili/src/analysis/annealing.py", line 1656, in remapping
    queue.append((bysegment[sidx][0], lptr.sidx[i-1]))
IndexError: list index out of range

Process Process-134:
Traceback (most recent call last):
  File "/homes/dbarton/miniconda3/lib/python3.8/multiprocessing/process.py", line 315, in _bootstrap
    self.run()
  File "/homes/dbarton/miniconda3/lib/python3.8/multiprocessing/process.py", line 108, in run
    self._target(*self._args, **self._kwargs)
  File "run_pwl.py", line 125, in pwl_solve
    solver = annealing.solve_exp(lptr, M, r, default_loss_conf=loss_conf)
  File "/cluster/rs_lab/dbarton/usb_twitching/pili/src/analysis/annealing.py", line 1751, in solve_exp
    solver.remapping()
  File "/cluster/rs_lab/dbarton/usb_twitching/pili/src/analysis/annealing.py", line 1656, in remapping
    queue.append((bysegment[sidx][0], lptr.sidx[i-1]))
IndexError: list index out of range



Process Process-174:
Traceback (most recent call last):
  File "/homes/dbarton/miniconda3/lib/python3.8/multiprocessing/process.py", line 315, in _bootstrap
    self.run()
  File "/homes/dbarton/miniconda3/lib/python3.8/multiprocessing/process.py", line 108, in run
    self._target(*self._args, **self._kwargs)
  File "run_pwl.py", line 125, in pwl_solve
    solver = annealing.solve_exp(lptr, M, r, default_loss_conf=loss_conf)
  File "/cluster/rs_lab/dbarton/usb_twitching/pili/src/analysis/annealing.py", line 1751, in solve_exp
    solver.remapping()
  File "/cluster/rs_lab/dbarton/usb_twitching/pili/src/analysis/annealing.py", line 1656, in remapping
    queue.append((bysegment[sidx][0], lptr.sidx[i-1]))
IndexError: list index out of range



Process Process-189:
Traceback (most recent call last):
  File "/homes/dbarton/miniconda3/lib/python3.8/multiprocessing/process.py", line 315, in _bootstrap
    self.run()
  File "/homes/dbarton/miniconda3/lib/python3.8/multiprocessing/process.py", line 108, in run
    self._target(*self._args, **self._kwargs)
  File "run_pwl.py", line 125, in pwl_solve
    solver = annealing.solve_exp(lptr, M, r, default_loss_conf=loss_conf)
  File "/cluster/rs_lab/dbarton/usb_twitching/pili/src/analysis/annealing.py", line 1751, in solve_exp
    solver.remapping()
  File "/cluster/rs_lab/dbarton/usb_twitching/pili/src/analysis/annealing.py", line 1656, in remapping
    queue.append((bysegment[sidx][0], lptr.sidx[i-1]))
IndexError: list index out of range

/cluster/rs_lab/dbarton/usb_twitching/pili/support.py:52: RuntimeWarning: invalid value encountered in true_divide
  d_hat = np.divide(d_ba, d)
Process Process-153:
Traceback (most recent call last):
  File "/homes/dbarton/miniconda3/lib/python3.8/multiprocessing/process.py", line 315, in _bootstrap
    self.run()
  File "/homes/dbarton/miniconda3/lib/python3.8/multiprocessing/process.py", line 108, in run
    self._target(*self._args, **self._kwargs)
  File "run_pwl.py", line 125, in pwl_solve
    solver = annealing.solve_exp(lptr, M, r, default_loss_conf=loss_conf)
  File "/cluster/rs_lab/dbarton/usb_twitching/pili/src/analysis/annealing.py", line 1751, in solve_exp
    solver.remapping()
  File "/cluster/rs_lab/dbarton/usb_twitching/pili/src/analysis/annealing.py", line 1656, in remapping
    queue.append((bysegment[sidx][0], lptr.sidx[i-1]))
IndexError: list index out of range



/cluster/rs_lab/dbarton/usb_twitching/pili/src/analysis/annealing.py:1359: RuntimeWarning: overflow encountered in exp
  s = np.exp(-(score_prime - score)/T)
Process Process-114:
Traceback (most recent call last):
  File "/homes/dbarton/miniconda3/lib/python3.8/multiprocessing/process.py", line 315, in _bootstrap
    self.run()
  File "/homes/dbarton/miniconda3/lib/python3.8/multiprocessing/process.py", line 108, in run
    self._target(*self._args, **self._kwargs)
  File "run_pwl.py", line 125, in pwl_solve
    solver = annealing.solve_exp(lptr, M, r, default_loss_conf=loss_conf)
  File "/cluster/rs_lab/dbarton/usb_twitching/pili/src/analysis/annealing.py", line 1751, in solve_exp
    solver.remapping()
  File "/cluster/rs_lab/dbarton/usb_twitching/pili/src/analysis/annealing.py", line 1656, in remapping
    queue.append((bysegment[sidx][0], lptr.sidx[i-1]))
IndexError: list index out of range

Process Process-16:
Traceback (most recent call last):
  File "/homes/dbarton/miniconda3/lib/python3.8/multiprocessing/process.py", line 315, in _bootstrap
    self.run()
  File "/homes/dbarton/miniconda3/lib/python3.8/multiprocessing/process.py", line 108, in run
    self._target(*self._args, **self._kwargs)
  File "run_pwl.py", line 125, in pwl_solve
    solver = annealing.solve_exp(lptr, M, r, default_loss_conf=loss_conf)
  File "/cluster/rs_lab/dbarton/usb_twitching/pili/src/analysis/annealing.py", line 1751, in solve_exp
    solver.remapping()
  File "/cluster/rs_lab/dbarton/usb_twitching/pili/src/analysis/annealing.py", line 1656, in remapping
    queue.append((bysegment[sidx][0], lptr.sidx[i-1]))
IndexError: list index out of range

/cluster/rs_lab/dbarton/usb_twitching/pili/support.py:52: RuntimeWarning: invalid value encountered in true_divide
  d_hat = np.divide(d_ba, d)
Process Process-161:
Traceback (most recent call last):
  File "/homes/dbarton/miniconda3/lib/python3.8/multiprocessing/process.py", line 315, in _bootstrap
    self.run()
  File "/homes/dbarton/miniconda3/lib/python3.8/multiprocessing/process.py", line 108, in run
    self._target(*self._args, **self._kwargs)
  File "run_pwl.py", line 125, in pwl_solve
    solver = annealing.solve_exp(lptr, M, r, default_loss_conf=loss_conf)
  File "/cluster/rs_lab/dbarton/usb_twitching/pili/src/analysis/annealing.py", line 1751, in solve_exp
    solver.remapping()
  File "/cluster/rs_lab/dbarton/usb_twitching/pili/src/analysis/annealing.py", line 1656, in remapping
    queue.append((bysegment[sidx][0], lptr.sidx[i-1]))
IndexError: list index out of range


/cluster/rs_lab/dbarton/usb_twitching/pili/src/analysis/annealing.py:1359: RuntimeWarning: overflow encountered in exp
  s = np.exp(-(score_prime - score)/T)
Process Process-183:
Traceback (most recent call last):
  File "/homes/dbarton/miniconda3/lib/python3.8/multiprocessing/process.py", line 315, in _bootstrap
    self.run()
  File "/homes/dbarton/miniconda3/lib/python3.8/multiprocessing/process.py", line 108, in run
    self._target(*self._args, **self._kwargs)
  File "run_pwl.py", line 125, in pwl_solve
    solver = annealing.solve_exp(lptr, M, r, default_loss_conf=loss_conf)
  File "/cluster/rs_lab/dbarton/usb_twitching/pili/src/analysis/annealing.py", line 1751, in solve_exp
    solver.remapping()
  File "/cluster/rs_lab/dbarton/usb_twitching/pili/src/analysis/annealing.py", line 1656, in remapping
    queue.append((bysegment[sidx][0], lptr.sidx[i-1]))
IndexError: list index out of range

Process Process-195:
Traceback (most recent call last):
  File "/homes/dbarton/miniconda3/lib/python3.8/multiprocessing/process.py", line 315, in _bootstrap
    self.run()
  File "/homes/dbarton/miniconda3/lib/python3.8/multiprocessing/process.py", line 108, in run
    self._target(*self._args, **self._kwargs)
  File "run_pwl.py", line 125, in pwl_solve
    solver = annealing.solve_exp(lptr, M, r, default_loss_conf=loss_conf)
  File "/cluster/rs_lab/dbarton/usb_twitching/pili/src/analysis/annealing.py", line 1751, in solve_exp
    solver.remapping()
  File "/cluster/rs_lab/dbarton/usb_twitching/pili/src/analysis/annealing.py", line 1656, in remapping
    queue.append((bysegment[sidx][0], lptr.sidx[i-1]))
IndexError: list index out of range

/cluster/rs_lab/dbarton/usb_twitching/pili/support.py:52: RuntimeWarning: invalid value encountered in true_divide
  d_hat = np.divide(d_ba, d)
Process Process-1:
Traceback (most recent call last):
  File "/homes/dbarton/miniconda3/lib/python3.8/multiprocessing/process.py", line 315, in _bootstrap
    self.run()
  File "/homes/dbarton/miniconda3/lib/python3.8/multiprocessing/process.py", line 108, in run
    self._target(*self._args, **self._kwargs)
  File "run_pwl.py", line 125, in pwl_solve
    solver = annealing.solve_exp(lptr, M, r, default_loss_conf=loss_conf)
  File "/cluster/rs_lab/dbarton/usb_twitching/pili/src/analysis/annealing.py", line 1751, in solve_exp
    solver.remapping()
  File "/cluster/rs_lab/dbarton/usb_twitching/pili/src/analysis/annealing.py", line 1656, in remapping
    queue.append((bysegment[sidx][0], lptr.sidx[i-1]))
IndexError: list index out of range

Process Process-162:
Traceback (most recent call last):
  File "/homes/dbarton/miniconda3/lib/python3.8/multiprocessing/process.py", line 315, in _bootstrap
    self.run()
  File "/homes/dbarton/miniconda3/lib/python3.8/multiprocessing/process.py", line 108, in run
    self._target(*self._args, **self._kwargs)
  File "run_pwl.py", line 125, in pwl_solve
    solver = annealing.solve_exp(lptr, M, r, default_loss_conf=loss_conf)
  File "/cluster/rs_lab/dbarton/usb_twitching/pili/src/analysis/annealing.py", line 1751, in solve_exp
    solver.remapping()
  File "/cluster/rs_lab/dbarton/usb_twitching/pili/src/analysis/annealing.py", line 1656, in remapping
    queue.append((bysegment[sidx][0], lptr.sidx[i-1]))
IndexError: list index out of range

Process Process-178:
Traceback (most recent call last):
  File "/homes/dbarton/miniconda3/lib/python3.8/multiprocessing/process.py", line 315, in _bootstrap
    self.run()
  File "/homes/dbarton/miniconda3/lib/python3.8/multiprocessing/process.py", line 108, in run
    self._target(*self._args, **self._kwargs)
  File "run_pwl.py", line 125, in pwl_solve
    solver = annealing.solve_exp(lptr, M, r, default_loss_conf=loss_conf)
  File "/cluster/rs_lab/dbarton/usb_twitching/pili/src/analysis/annealing.py", line 1751, in solve_exp
    solver.remapping()
  File "/cluster/rs_lab/dbarton/usb_twitching/pili/src/analysis/annealing.py", line 1656, in remapping
    queue.append((bysegment[sidx][0], lptr.sidx[i-1]))
IndexError: list index out of range

Process Process-142:
Traceback (most recent call last):
  File "/homes/dbarton/miniconda3/lib/python3.8/multiprocessing/process.py", line 315, in _bootstrap
    self.run()
  File "/homes/dbarton/miniconda3/lib/python3.8/multiprocessing/process.py", line 108, in run
    self._target(*self._args, **self._kwargs)
  File "run_pwl.py", line 125, in pwl_solve
    solver = annealing.solve_exp(lptr, M, r, default_loss_conf=loss_conf)
  File "/cluster/rs_lab/dbarton/usb_twitching/pili/src/analysis/annealing.py", line 1751, in solve_exp
    solver.remapping()
  File "/cluster/rs_lab/dbarton/usb_twitching/pili/src/analysis/annealing.py", line 1656, in remapping
    queue.append((bysegment[sidx][0], lptr.sidx[i-1]))
IndexError: list index out of range

/cluster/rs_lab/dbarton/usb_twitching/pili/support.py:52: RuntimeWarning: invalid value encountered in true_divide
  d_hat = np.divide(d_ba, d)
/cluster/rs_lab/dbarton/usb_twitching/pili/src/analysis/annealing.py:1359: RuntimeWarning: overflow encountered in exp
  s = np.exp(-(score_prime - score)/T)
Process Process-156:
Traceback (most recent call last):
  File "/homes/dbarton/miniconda3/lib/python3.8/multiprocessing/process.py", line 315, in _bootstrap
    self.run()
  File "/homes/dbarton/miniconda3/lib/python3.8/multiprocessing/process.py", line 108, in run
    self._target(*self._args, **self._kwargs)
  File "run_pwl.py", line 125, in pwl_solve
    solver = annealing.solve_exp(lptr, M, r, default_loss_conf=loss_conf)
  File "/cluster/rs_lab/dbarton/usb_twitching/pili/src/analysis/annealing.py", line 1751, in solve_exp
    solver.remapping()
  File "/cluster/rs_lab/dbarton/usb_twitching/pili/src/analysis/annealing.py", line 1656, in remapping
    queue.append((bysegment[sidx][0], lptr.sidx[i-1]))
IndexError: list index out of range

/cluster/rs_lab/dbarton/usb_twitching/pili/support.py:52: RuntimeWarning: invalid value encountered in true_divide
  d_hat = np.divide(d_ba, d)
Process Process-197:
Traceback (most recent call last):
  File "/homes/dbarton/miniconda3/lib/python3.8/multiprocessing/process.py", line 315, in _bootstrap
    self.run()
  File "/homes/dbarton/miniconda3/lib/python3.8/multiprocessing/process.py", line 108, in run
    self._target(*self._args, **self._kwargs)
  File "run_pwl.py", line 125, in pwl_solve
    solver = annealing.solve_exp(lptr, M, r, default_loss_conf=loss_conf)
  File "/cluster/rs_lab/dbarton/usb_twitching/pili/src/analysis/annealing.py", line 1751, in solve_exp
    solver.remapping()
  File "/cluster/rs_lab/dbarton/usb_twitching/pili/src/analysis/annealing.py", line 1656, in remapping
    queue.append((bysegment[sidx][0], lptr.sidx[i-1]))
IndexError: list index out of range

Process Process-166:
Traceback (most recent call last):
  File "/homes/dbarton/miniconda3/lib/python3.8/multiprocessing/process.py", line 315, in _bootstrap
    self.run()
  File "/homes/dbarton/miniconda3/lib/python3.8/multiprocessing/process.py", line 108, in run
    self._target(*self._args, **self._kwargs)
  File "run_pwl.py", line 125, in pwl_solve
    solver = annealing.solve_exp(lptr, M, r, default_loss_conf=loss_conf)
  File "/cluster/rs_lab/dbarton/usb_twitching/pili/src/analysis/annealing.py", line 1751, in solve_exp
    solver.remapping()
  File "/cluster/rs_lab/dbarton/usb_twitching/pili/src/analysis/annealing.py", line 1656, in remapping
    queue.append((bysegment[sidx][0], lptr.sidx[i-1]))
IndexError: list index out of range

Process Process-103:
Traceback (most recent call last):
  File "/homes/dbarton/miniconda3/lib/python3.8/multiprocessing/process.py", line 315, in _bootstrap
    self.run()
  File "/homes/dbarton/miniconda3/lib/python3.8/multiprocessing/process.py", line 108, in run
    self._target(*self._args, **self._kwargs)
  File "run_pwl.py", line 125, in pwl_solve
    solver = annealing.solve_exp(lptr, M, r, default_loss_conf=loss_conf)
  File "/cluster/rs_lab/dbarton/usb_twitching/pili/src/analysis/annealing.py", line 1751, in solve_exp
    solver.remapping()
  File "/cluster/rs_lab/dbarton/usb_twitching/pili/src/analysis/annealing.py", line 1656, in remapping
    queue.append((bysegment[sidx][0], lptr.sidx[i-1]))
IndexError: list index out of range

/cluster/rs_lab/dbarton/usb_twitching/pili/support.py:52: RuntimeWarning: invalid value encountered in true_divide
  d_hat = np.divide(d_ba, d)

Process Process-185:
Traceback (most recent call last):
  File "/homes/dbarton/miniconda3/lib/python3.8/multiprocessing/process.py", line 315, in _bootstrap
    self.run()
  File "/homes/dbarton/miniconda3/lib/python3.8/multiprocessing/process.py", line 108, in run
    self._target(*self._args, **self._kwargs)
  File "run_pwl.py", line 125, in pwl_solve
    solver = annealing.solve_exp(lptr, M, r, default_loss_conf=loss_conf)
  File "/cluster/rs_lab/dbarton/usb_twitching/pili/src/analysis/annealing.py", line 1751, in solve_exp
    solver.remapping()
  File "/cluster/rs_lab/dbarton/usb_twitching/pili/src/analysis/annealing.py", line 1656, in remapping
    queue.append((bysegment[sidx][0], lptr.sidx[i-1]))
IndexError: list index out of range



Process Process-126:
Traceback (most recent call last):
  File "/homes/dbarton/miniconda3/lib/python3.8/multiprocessing/process.py", line 315, in _bootstrap
    self.run()
  File "/homes/dbarton/miniconda3/lib/python3.8/multiprocessing/process.py", line 108, in run
    self._target(*self._args, **self._kwargs)
  File "run_pwl.py", line 125, in pwl_solve
    solver = annealing.solve_exp(lptr, M, r, default_loss_conf=loss_conf)
  File "/cluster/rs_lab/dbarton/usb_twitching/pili/src/analysis/annealing.py", line 1751, in solve_exp
    solver.remapping()
  File "/cluster/rs_lab/dbarton/usb_twitching/pili/src/analysis/annealing.py", line 1656, in remapping
    queue.append((bysegment[sidx][0], lptr.sidx[i-1]))
IndexError: list index out of range

Process Process-127:
Traceback (most recent call last):
  File "/homes/dbarton/miniconda3/lib/python3.8/multiprocessing/process.py", line 315, in _bootstrap
    self.run()
  File "/homes/dbarton/miniconda3/lib/python3.8/multiprocessing/process.py", line 108, in run
    self._target(*self._args, **self._kwargs)
  File "run_pwl.py", line 125, in pwl_solve
    solver = annealing.solve_exp(lptr, M, r, default_loss_conf=loss_conf)
  File "/cluster/rs_lab/dbarton/usb_twitching/pili/src/analysis/annealing.py", line 1751, in solve_exp
    solver.remapping()
  File "/cluster/rs_lab/dbarton/usb_twitching/pili/src/analysis/annealing.py", line 1656, in remapping
    queue.append((bysegment[sidx][0], lptr.sidx[i-1]))
IndexError: list index out of range

/cluster/rs_lab/dbarton/usb_twitching/pili/support.py:52: RuntimeWarning: invalid value encountered in true_divide
  d_hat = np.divide(d_ba, d)
Process Process-191:
Traceback (most recent call last):
  File "/homes/dbarton/miniconda3/lib/python3.8/multiprocessing/process.py", line 315, in _bootstrap
    self.run()
  File "/homes/dbarton/miniconda3/lib/python3.8/multiprocessing/process.py", line 108, in run
    self._target(*self._args, **self._kwargs)
  File "run_pwl.py", line 125, in pwl_solve
    solver = annealing.solve_exp(lptr, M, r, default_loss_conf=loss_conf)
  File "/cluster/rs_lab/dbarton/usb_twitching/pili/src/analysis/annealing.py", line 1751, in solve_exp
    solver.remapping()
  File "/cluster/rs_lab/dbarton/usb_twitching/pili/src/analysis/annealing.py", line 1656, in remapping
    queue.append((bysegment[sidx][0], lptr.sidx[i-1]))
IndexError: list index out of range

/cluster/rs_lab/dbarton/usb_twitching/pili/support.py:52: RuntimeWarning: invalid value encountered in true_divide
  d_hat = np.divide(d_ba, d)


Process Process-115:
Traceback (most recent call last):
  File "/homes/dbarton/miniconda3/lib/python3.8/multiprocessing/process.py", line 315, in _bootstrap
    self.run()
  File "/homes/dbarton/miniconda3/lib/python3.8/multiprocessing/process.py", line 108, in run
    self._target(*self._args, **self._kwargs)
  File "run_pwl.py", line 125, in pwl_solve
    solver = annealing.solve_exp(lptr, M, r, default_loss_conf=loss_conf)
  File "/cluster/rs_lab/dbarton/usb_twitching/pili/src/analysis/annealing.py", line 1751, in solve_exp
    solver.remapping()
  File "/cluster/rs_lab/dbarton/usb_twitching/pili/src/analysis/annealing.py", line 1656, in remapping
    queue.append((bysegment[sidx][0], lptr.sidx[i-1]))
IndexError: list index out of range

Process Process-186:
Traceback (most recent call last):
  File "/homes/dbarton/miniconda3/lib/python3.8/multiprocessing/process.py", line 315, in _bootstrap
    self.run()
  File "/homes/dbarton/miniconda3/lib/python3.8/multiprocessing/process.py", line 108, in run
    self._target(*self._args, **self._kwargs)
  File "run_pwl.py", line 125, in pwl_solve
    solver = annealing.solve_exp(lptr, M, r, default_loss_conf=loss_conf)
  File "/cluster/rs_lab/dbarton/usb_twitching/pili/src/analysis/annealing.py", line 1751, in solve_exp
    solver.remapping()
  File "/cluster/rs_lab/dbarton/usb_twitching/pili/src/analysis/annealing.py", line 1656, in remapping
    queue.append((bysegment[sidx][0], lptr.sidx[i-1]))
IndexError: list index out of range

/cluster/rs_lab/dbarton/usb_twitching/pili/support.py:52: RuntimeWarning: invalid value encountered in true_divide
  d_hat = np.divide(d_ba, d)
Process Process-193:
Traceback (most recent call last):
  File "/homes/dbarton/miniconda3/lib/python3.8/multiprocessing/process.py", line 315, in _bootstrap
    self.run()
  File "/homes/dbarton/miniconda3/lib/python3.8/multiprocessing/process.py", line 108, in run
    self._target(*self._args, **self._kwargs)
  File "run_pwl.py", line 125, in pwl_solve
    solver = annealing.solve_exp(lptr, M, r, default_loss_conf=loss_conf)
  File "/cluster/rs_lab/dbarton/usb_twitching/pili/src/analysis/annealing.py", line 1751, in solve_exp
    solver.remapping()
  File "/cluster/rs_lab/dbarton/usb_twitching/pili/src/analysis/annealing.py", line 1656, in remapping
    queue.append((bysegment[sidx][0], lptr.sidx[i-1]))
IndexError: list index out of range

/cluster/rs_lab/dbarton/usb_twitching/pili/src/analysis/annealing.py:1359: RuntimeWarning: overflow encountered in exp
  s = np.exp(-(score_prime - score)/T)
Process Process-145:
Traceback (most recent call last):
  File "/homes/dbarton/miniconda3/lib/python3.8/multiprocessing/process.py", line 315, in _bootstrap
    self.run()
  File "/homes/dbarton/miniconda3/lib/python3.8/multiprocessing/process.py", line 108, in run
    self._target(*self._args, **self._kwargs)
  File "run_pwl.py", line 125, in pwl_solve
    solver = annealing.solve_exp(lptr, M, r, default_loss_conf=loss_conf)
  File "/cluster/rs_lab/dbarton/usb_twitching/pili/src/analysis/annealing.py", line 1751, in solve_exp
    solver.remapping()
  File "/cluster/rs_lab/dbarton/usb_twitching/pili/src/analysis/annealing.py", line 1656, in remapping
    queue.append((bysegment[sidx][0], lptr.sidx[i-1]))
IndexError: list index out of range

Process Process-135:
Traceback (most recent call last):
  File "/homes/dbarton/miniconda3/lib/python3.8/multiprocessing/process.py", line 315, in _bootstrap
    self.run()
  File "/homes/dbarton/miniconda3/lib/python3.8/multiprocessing/process.py", line 108, in run
    self._target(*self._args, **self._kwargs)
  File "run_pwl.py", line 125, in pwl_solve
    solver = annealing.solve_exp(lptr, M, r, default_loss_conf=loss_conf)
  File "/cluster/rs_lab/dbarton/usb_twitching/pili/src/analysis/annealing.py", line 1751, in solve_exp
    solver.remapping()
  File "/cluster/rs_lab/dbarton/usb_twitching/pili/src/analysis/annealing.py", line 1656, in remapping
    queue.append((bysegment[sidx][0], lptr.sidx[i-1]))
IndexError: list index out of range


Process Process-173:
Traceback (most recent call last):
  File "/homes/dbarton/miniconda3/lib/python3.8/multiprocessing/process.py", line 315, in _bootstrap
    self.run()
  File "/homes/dbarton/miniconda3/lib/python3.8/multiprocessing/process.py", line 108, in run
    self._target(*self._args, **self._kwargs)
  File "run_pwl.py", line 125, in pwl_solve
    solver = annealing.solve_exp(lptr, M, r, default_loss_conf=loss_conf)
  File "/cluster/rs_lab/dbarton/usb_twitching/pili/src/analysis/annealing.py", line 1751, in solve_exp
    solver.remapping()
  File "/cluster/rs_lab/dbarton/usb_twitching/pili/src/analysis/annealing.py", line 1656, in remapping
    queue.append((bysegment[sidx][0], lptr.sidx[i-1]))
IndexError: list index out of range

Process Process-175:
Traceback (most recent call last):
  File "/homes/dbarton/miniconda3/lib/python3.8/multiprocessing/process.py", line 315, in _bootstrap
    self.run()
  File "/homes/dbarton/miniconda3/lib/python3.8/multiprocessing/process.py", line 108, in run
    self._target(*self._args, **self._kwargs)
  File "run_pwl.py", line 125, in pwl_solve
    solver = annealing.solve_exp(lptr, M, r, default_loss_conf=loss_conf)
  File "/cluster/rs_lab/dbarton/usb_twitching/pili/src/analysis/annealing.py", line 1751, in solve_exp
    solver.remapping()
  File "/cluster/rs_lab/dbarton/usb_twitching/pili/src/analysis/annealing.py", line 1656, in remapping
    queue.append((bysegment[sidx][0], lptr.sidx[i-1]))
IndexError: list index out of range

/cluster/rs_lab/dbarton/usb_twitching/pili/support.py:52: RuntimeWarning: invalid value encountered in true_divide
  d_hat = np.divide(d_ba, d)
/cluster/rs_lab/dbarton/usb_twitching/pili/src/analysis/annealing.py:1359: RuntimeWarning: overflow encountered in exp
  s = np.exp(-(score_prime - score)/T)
Process Process-198:
Traceback (most recent call last):
  File "/homes/dbarton/miniconda3/lib/python3.8/multiprocessing/process.py", line 315, in _bootstrap
    self.run()
  File "/homes/dbarton/miniconda3/lib/python3.8/multiprocessing/process.py", line 108, in run
    self._target(*self._args, **self._kwargs)
  File "run_pwl.py", line 125, in pwl_solve
    solver = annealing.solve_exp(lptr, M, r, default_loss_conf=loss_conf)
  File "/cluster/rs_lab/dbarton/usb_twitching/pili/src/analysis/annealing.py", line 1751, in solve_exp
    solver.remapping()
  File "/cluster/rs_lab/dbarton/usb_twitching/pili/src/analysis/annealing.py", line 1656, in remapping
    queue.append((bysegment[sidx][0], lptr.sidx[i-1]))
IndexError: list index out of range

/cluster/rs_lab/dbarton/usb_twitching/pili/support.py:52: RuntimeWarning: invalid value encountered in true_divide
  d_hat = np.divide(d_ba, d)
Process Process-180:
Traceback (most recent call last):
  File "/homes/dbarton/miniconda3/lib/python3.8/multiprocessing/process.py", line 315, in _bootstrap
    self.run()
  File "/homes/dbarton/miniconda3/lib/python3.8/multiprocessing/process.py", line 108, in run
    self._target(*self._args, **self._kwargs)
  File "run_pwl.py", line 125, in pwl_solve
    solver = annealing.solve_exp(lptr, M, r, default_loss_conf=loss_conf)
  File "/cluster/rs_lab/dbarton/usb_twitching/pili/src/analysis/annealing.py", line 1751, in solve_exp
    solver.remapping()
  File "/cluster/rs_lab/dbarton/usb_twitching/pili/src/analysis/annealing.py", line 1656, in remapping
    queue.append((bysegment[sidx][0], lptr.sidx[i-1]))
IndexError: list index out of range

Process Process-179:
Traceback (most recent call last):
  File "/homes/dbarton/miniconda3/lib/python3.8/multiprocessing/process.py", line 315, in _bootstrap
    self.run()
  File "/homes/dbarton/miniconda3/lib/python3.8/multiprocessing/process.py", line 108, in run
    self._target(*self._args, **self._kwargs)
  File "run_pwl.py", line 125, in pwl_solve
    solver = annealing.solve_exp(lptr, M, r, default_loss_conf=loss_conf)
  File "/cluster/rs_lab/dbarton/usb_twitching/pili/src/analysis/annealing.py", line 1751, in solve_exp
    solver.remapping()
  File "/cluster/rs_lab/dbarton/usb_twitching/pili/src/analysis/annealing.py", line 1656, in remapping
    queue.append((bysegment[sidx][0], lptr.sidx[i-1]))
IndexError: list index out of range

/cluster/rs_lab/dbarton/usb_twitching/pili/support.py:52: RuntimeWarning: invalid value encountered in true_divide
  d_hat = np.divide(d_ba, d)
Process Process-187:
Traceback (most recent call last):
  File "/homes/dbarton/miniconda3/lib/python3.8/multiprocessing/process.py", line 315, in _bootstrap
    self.run()
  File "/homes/dbarton/miniconda3/lib/python3.8/multiprocessing/process.py", line 108, in run
    self._target(*self._args, **self._kwargs)
  File "run_pwl.py", line 125, in pwl_solve
    solver = annealing.solve_exp(lptr, M, r, default_loss_conf=loss_conf)
  File "/cluster/rs_lab/dbarton/usb_twitching/pili/src/analysis/annealing.py", line 1751, in solve_exp
    solver.remapping()
  File "/cluster/rs_lab/dbarton/usb_twitching/pili/src/analysis/annealing.py", line 1656, in remapping
    queue.append((bysegment[sidx][0], lptr.sidx[i-1]))
IndexError: list index out of range

Process Process-196:
Traceback (most recent call last):
  File "/homes/dbarton/miniconda3/lib/python3.8/multiprocessing/process.py", line 315, in _bootstrap
    self.run()
  File "/homes/dbarton/miniconda3/lib/python3.8/multiprocessing/process.py", line 108, in run
    self._target(*self._args, **self._kwargs)
  File "run_pwl.py", line 125, in pwl_solve
    solver = annealing.solve_exp(lptr, M, r, default_loss_conf=loss_conf)
  File "/cluster/rs_lab/dbarton/usb_twitching/pili/src/analysis/annealing.py", line 1751, in solve_exp
    solver.remapping()
  File "/cluster/rs_lab/dbarton/usb_twitching/pili/src/analysis/annealing.py", line 1656, in remapping
    queue.append((bysegment[sidx][0], lptr.sidx[i-1]))
IndexError: list index out of range

Process Process-184:
Traceback (most recent call last):
  File "/homes/dbarton/miniconda3/lib/python3.8/multiprocessing/process.py", line 315, in _bootstrap
    self.run()
  File "/homes/dbarton/miniconda3/lib/python3.8/multiprocessing/process.py", line 108, in run
    self._target(*self._args, **self._kwargs)
  File "run_pwl.py", line 125, in pwl_solve
    solver = annealing.solve_exp(lptr, M, r, default_loss_conf=loss_conf)
  File "/cluster/rs_lab/dbarton/usb_twitching/pili/src/analysis/annealing.py", line 1751, in solve_exp
    solver.remapping()
  File "/cluster/rs_lab/dbarton/usb_twitching/pili/src/analysis/annealing.py", line 1656, in remapping
    queue.append((bysegment[sidx][0], lptr.sidx[i-1]))
IndexError: list index out of range
